Workbook

Sheet 개요
A1: 통합 AI 보안위협 매트릭스 (UTM) v3.2 LITE
A2: Lv1 도메인 10 · Lv2 위협 분류 36 · Lv3 세부 위협 124 · 위험 평가(발생가능성×심각도) | 2026-10-02 | 작성 중 — D01·D02 및 분류 변경 Lv3를 v3.2 문체로 재작성, D03~D10 순차 재작성 예정
A4: 1. 통합 대상 소스
A5: 소스 | B5: 버전 / 공개일 | C5: 규모 | D5: 관점 | E5: 입수 경로
A6: MITRE ATLAS | B6: v2026.09 (2026-09-15) | C6: 전술 16 · 기법 208 · 완화책 40 · 사례 73 · 절차 665 | D6: 공격자 TTP | E6: ATLAS-2026_09.yaml · excel-atlas*.xlsx
A7: OWASP Top 10 for LLM Applications | B7: 2026 (2026-08-04) | C7: 10 | D7: LLM 애플리케이션 위험 | E7: 원문 PDF
A8: OWASP Top 10 for Agentic Applications | B8: 2026 (2025-12-09) | C8: 10 + 사고 추적표 25건 | D8: 에이전트 위험 | E8: 원문 PDF
A9: OWASP GenAI Data Security | B9: 2026 v1.0 (2026-03) | C9: 21 | D9: 데이터 생애주기 위험 | E9: 원문 PDF
A10: OWASP MCP Top 10 | B10: 2025 (beta) | C10: 10 | D10: MCP 프로토콜 계층 | E10: github.com/OWASP/www-project-mcp-top-10
A12: 2. 핵심 지표 (수식 연동)
A13: 지표 | B13: 값
A14: Lv1 도메인 / Lv2 위협 분류 / Lv3 세부 위협 | B14: =SUMPRODUCT(1/COUNTIF(통합매트릭스!$A$5:$A$128,통합매트릭스!$A$5:$A$128))&" / "&SUMPRODUCT(1/COUNTIF(통합매트릭스!$B$5:$B$128,통합매트릭스!$B$5:$B$128))&" / "&COUNTA(통합매트릭스!$D$5:$D$128)
A15: 위험도 매우 높음 / 높음 / 보통 / 낮음 | B15: =COUNTIF(통합매트릭스!$J$5:$J$128,"매우 높음")&" / "&COUNTIF(통합매트릭스!$J$5:$J$128,"높음")&" / "&COUNTIF(통합매트릭스!$J$5:$J$128,"보통")&" / "&COUNTIF(통합매트릭스!$J$5:$J$128,"낮음")
A16: 근거 수준 실제 사고 확인 / 실사용 기법 포함 / 실증·공개 취약점 / 이론·시나리오 | B16: =COUNTIF(통합매트릭스!$L$5:$L$128,"실제 사고 확인")&" / "&COUNTIF(통합매트릭스!$L$5:$L$128,"실사용 기법 포함")&" / "&COUNTIF(통합매트릭스!$L$5:$L$128,"실증·공개 취약점")&" / "&COUNTIF(통합매트릭스!$L$5:$L$128,"이론·시나리오")
A17: 실제 사고가 1건 이상 연결된 Lv3 | B17: =COUNTIF(통합매트릭스!$M$5:$M$128,">0")
A18: v3.2 문체 재작성 Lv3 / 전체 | B18: 38 / 124
A20: 3. 위험 매트릭스 (Lv3 수)
A21: 발생가능성 \ 심각도 | B21: 상 | C21: 중 | D21: 하
A22: 상 | B22: =COUNTIFS(통합매트릭스!$H$5:$H$128,"상",통합매트릭스!$I$5:$I$128,"상") | C22: =COUNTIFS(통합매트릭스!$H$5:$H$128,"상",통합매트릭스!$I$5:$I$128,"중") | D22: =COUNTIFS(통합매트릭스!$H$5:$H$128,"상",통합매트릭스!$I$5:$I$128,"하")
A23: 중 | B23: =COUNTIFS(통합매트릭스!$H$5:$H$128,"중",통합매트릭스!$I$5:$I$128,"상") | C23: =COUNTIFS(통합매트릭스!$H$5:$H$128,"중",통합매트릭스!$I$5:$I$128,"중") | D23: =COUNTIFS(통합매트릭스!$H$5:$H$128,"중",통합매트릭스!$I$5:$I$128,"하")
A24: 하 | B24: =COUNTIFS(통합매트릭스!$H$5:$H$128,"하",통합매트릭스!$I$5:$I$128,"상") | C24: =COUNTIFS(통합매트릭스!$H$5:$H$128,"하",통합매트릭스!$I$5:$I$128,"중") | D24: =COUNTIFS(통합매트릭스!$H$5:$H$128,"하",통합매트릭스!$I$5:$I$128,"하")
A26: 4. 시트 구성
A27: 시트 | B27: 내용
A28: 통합매트릭스 | B28: 핵심 산출물. Lv3 124행 — 분류 체계, 요약설명·참조(AI 관점·실제 사례), 위험 평가, 교차 매핑(공격 단계·ATLAS·OWASP), 핵심 통제(Lv2)
A29: 도메인·평가기준 | B29: 3단 분류 정의와 작성 규칙, Lv1 도메인 리스크 정의·경계 판정 규칙, 위험 평가·근거 수준 기준, 참조 작성 규칙
A30: ATLAS사례연구 | B30: MITRE ATLAS 사례 73건 요약과 Lv3 매핑 — 참조의 'ATLAS AML.CS' 출처 조회용
A31: 변경이력 | B31: 버전별 변경 내역과 Lv3 ID 대응표(폐지 ID는 재사용하지 않음)

Sheet 통합매트릭스
A1: 통합 AI 보안위협 매트릭스 v3.2 LITE — Lv1 도메인(10) · Lv2 위협 분류(36) · Lv3 세부 위협(124)
A2: 기준: MITRE ATLAS v2026.09 · OWASP LLM Top 10 2026 · Agentic Top 10 2026 · GenAI Data Security 2026 v1.0 · MCP Top 10(2025 beta) | 2026-10-02 | 작성 중 — D01·D02 및 분류 변경 Lv3를 v3.2 문체로 재작성, D03~D10 순차 재작성 예정 — 회색 글자 = v3.1 문구 유지 행
A3: 분류 체계 (Lv1 · Lv2 · Lv3) | H3: 위험 평가 | N3: 교차 매핑 | Q3: 통제 (Lv2)
A4: 도메인 (Lv1) | B4: UT-ID | C4: 위협 분류 (Lv2) | D4: Lv3 ID | E4: 세부 위협 (Lv3) | F4: 요약설명 | G4: 참조 | H4: 발생가능성 | I4: 심각도 | J4: 위험도 | K4: 심각도 근거 | L4: 근거 수준 | M4: 실제 사고 수 | N4: 주 공격 단계 | O4: ATLAS 기법 (주) | P4: OWASP 매핑 (주) | Q4: 핵심 통제 요약
A5: D01. 공격 준비 및 AI 무기화 | B5: UT-01 | C5: AI 대상 정찰 및 접근 확보 | D5: UT-01.1 | E5: 공개 정보 수집 | F5: - 공격자는 논문·기술 블로그·코드 저장소·앱 스토어·조직 웹사이트와 인터넷 스캔 DB를 검색해, 대상 조직이 쓰는 AI의 모델 구조·학습 데이터·프레임워크와 관련 인물 정보를 수집할 수 있음 - 공개된 정보만 쓰므로 조직이 탐지할 수 없고, 수집 결과가 이후 대리 모델 구축·맞춤형 인젝션·피싱의 설계 근거가 됨 | G5: ■ AI 관점 - 기술 정보원: 학회 논문·프리프린트·기술 블로그·특허, 공개 취약점 분석 자료에서 대상 모델의 구조·데이터셋·알려진 공격 기법을 확인 (ATLAS AML.T0000·T0001) - 자산 정보원: 조직 웹사이트·앱 스토어·GitHub에서 AI 기능, 사용 프레임워크, 에이전트 설정 파일을 찾고, Shodan·Censys 같은 스캔 DB로 노출된 AI 서비스를 조회 (ATLAS AML.T0003·T0004·T0095·T0000.003) - 인물 정보: 임직원 이름·메일·얼굴 사진과 개인정보를 수집해 딥페이크·사칭(UT-04)의 재료로 씀 (ATLAS AML.T0087) - 수집은 조직 밖에서 끝나므로 직접 차단보다 모델 카드·기술 문서·저장소 공개 범위를 최소화하는 것이 현실적 통제임 ■ 실제 사례 - [실제 사고] Hermes 에이전트 공격(2026-05): DeepSeek 기반 에이전트가 GitHub에서 2026년 CVE PoC 저장소를 찾고, FOFA로 노출된 Langflow 84개·n8n 약 65만 건을 조회해 표적을 선정 (ATLAS AML.CS0070) - [실제 사고] 중국 세무 시스템 얼굴인식 우회(2020): 암시장에서 개인정보와 고해상도 얼굴 사진을 사들여 인증 우회에 사용, 약 7,700만 달러 부정 수취 (ATLAS AML.CS0004) - [실증] Jira Service Management 공격(2025-06): "site:atlassian.net/servicedesk" 검색으로 AI 연동 서비스 포털을 쓰는 조직을 표적 목록화 (ATLAS AML.CS0039) | H5: 상 | I5: 하 | J5: =IF(AND(H5="상",I5="상"),"매우 높음",IF(OR(AND(H5="상",I5="중"),AND(H5="중",I5="상")),"높음",IF(OR(AND(H5="중",I5="중"),AND(H5="상",I5="하"),AND(H5="하",I5="상")),"보통","낮음"))) | K5: 직접 피해 없음(후속 공격 설계 단계) | L5: 실제 사고 확인 | M5: 3 | N5: 정찰(Reconnaissance) | O5: T0000, T0000.000, T0000.001, T0000.002, T0000.003, T0001, T0003, T0004, T0087, T0095, T0095.000 | Q5: 공개 정보·모델 아티팩트 공개 최소화, 노출 자산 관리, AI 허니팟, 비정상 탐색·질의 탐지
A6: D01. 공격 준비 및 AI 무기화 | B6: UT-01 | C6: AI 대상 정찰 및 접근 확보 | D6: UT-01.2 | E6: 노출 AI 자산 스캔 | F6: - 공격자는 인터넷 포트 스캔, SaaS·에이전트 플랫폼의 메타데이터 API 조회, 에이전트 호출 채널(메일·웹훅) 탐침으로 외부에 노출된 AI 서비스와 에이전트를 찾아 공격 진입점을 목록화할 수 있음 - 자체 호스팅 AI 런타임은 잘 알려진 포트·API를 기본으로 열어 대량 스캔에 쉽게 걸리며, 자율 공격 에이전트가 이 과정을 자동화하고 있음 | G6: ■ AI 관점 - 스캔 대상: 모델 서빙 엔드포인트, Ray·노트북 같은 학습 클러스터 대시보드, 에이전트 관리 콘솔·게이트웨이 — 기본 포트와 표준 API가 예측 가능함 (ATLAS AML.T0006.002) - 플랫폼 열거: 에이전트·SaaS 플랫폼의 예측 가능한 URL 구조나 메타데이터 API로 특정 조직이 배포한 에이전트를 찾아냄 (ATLAS AML.T0006.000·T0006.001) - 트리거 탐침: 고객 지원 메일·웹훅·메신저 채널에 시험 입력을 보내 자동 응답 여부로 에이전트 존재와 동작 방식을 확인 (ATLAS AML.T0006.003) - 찾아낸 노출 서비스는 일반 초기 침투(UT-02.4)나 인증 없는 서비스 악용(UT-31.1)으로 바로 이어짐 ■ 실제 사례 - [실제 사고] ShadowRay(2023-09~): 공인 IP 스캔으로 인증 없이 노출된 Ray 대시보드를 찾아 최소 7개월간 악용 — 피해 장비 가치 약 10억 달러 추산 (ATLAS AML.CS0023) - [실제 사고] GTG-1002(2025-09): 탈옥한 Claude 에이전트가 표적 조직의 IP 대역 스캔과 취약점 스캔을 자율 수행해 공격 표면을 열거 (ATLAS AML.CS0069) - [실증] Copilot Studio 고객 지원 에이전트(2025-06): 공개된 지원 메일 주소로 시험 메일을 보내 자동 회신 여부로 AI 에이전트가 관리하는 받은편지함을 식별 (ATLAS AML.CS0037) | H6: 상 | I6: 하 | J6: =IF(AND(H6="상",I6="상"),"매우 높음",IF(OR(AND(H6="상",I6="중"),AND(H6="중",I6="상")),"높음",IF(OR(AND(H6="중",I6="중"),AND(H6="상",I6="하"),AND(H6="하",I6="상")),"보통","낮음"))) | K6: 직접 피해 없음(공격 진입점 식별 단계) | L6: 실제 사고 확인 | M6: 4 | N6: 정찰(Reconnaissance) | O6: T0006, T0006.000, T0006.001, T0006.002, T0006.003 | Q6: 공개 정보·모델 아티팩트 공개 최소화, 노출 자산 관리, AI 허니팟, 비정상 탐색·질의 탐지
A7: D01. 공격 준비 및 AI 무기화 | B7: UT-01 | C7: AI 대상 정찰 및 접근 확보 | D7: UT-01.3 | E7: AI 모델 접근 확보 | F7: - 공격자는 공개 추론 API·AI 탑재 제품·앱 패키지 속 모델 파일을 통해 대상 모델에 질의하거나 모델 전체를 손에 넣어, 추출·회피·인젝션 공격의 시험대를 확보할 수 있음 - 정상 사용자와 같은 접근 경로라 구분이 어렵고, 모델 파일까지 확보하면 오프라인에서 제한 없이 공격을 다듬을 수 있음 | G7: ■ AI 관점 - 질의 접근: 추론 API, 웹 채팅, 메일·SNS로 동작하는 AI 서비스를 통해 출력을 반복 관찰 — 대량 계정·프록시로 이용 제한을 피하기도 함 (ATLAS AML.T0040) - 간접 접근: 보안 제품·인증 앱처럼 AI를 내장한 제품을 써서 모델의 판정과 로그·메타데이터를 관찰 (ATLAS AML.T0047) - 전체 접근: 앱 패키지·노출된 레지스트리·저장소에서 모델 파일을 확보하면 화이트박스 공격과 오프라인 탐색이 가능 (ATLAS AML.T0044, UT-16.2) - 확보한 접근은 모델 복제(UT-16.1)·적대적 예제 검증(UT-17.1)·인젝션 시험(UT-06.1)의 출발점이 됨 ■ 실제 사례 - [실제 사고] Claude 증류 캠페인(2026-02): 약 2.4만 개의 부정 계정으로 Claude 추론 API에 접근해 1,600만 건을 질의 (ATLAS AML.CS0056) - [실제 사고] 중국 세무 시스템 얼굴인식 우회(2020): 가상 카메라 앱으로 생성 영상을 얼굴인식 인증 서비스에 직접 입력 (ATLAS AML.CS0004) - [실증] Google Photos 모델 추출(2025-03): 앱 패키지에서 암호화되지 않은 TFLite 모델을 꺼내고 암호화된 모델은 실행 중 복호화 시점에 가로채 화이트박스 접근 확보 (ATLAS AML.CS0058) | H7: 상 | I7: 중 | J7: =IF(AND(H7="상",I7="상"),"매우 높음",IF(OR(AND(H7="상",I7="중"),AND(H7="중",I7="상")),"높음",IF(OR(AND(H7="중",I7="중"),AND(H7="상",I7="하"),AND(H7="하",I7="상")),"보통","낮음"))) | K7: 질의 또는 전체 접근 확보로 추출/회피/추론 공격 기반 형성 | L7: 실제 사고 확인 | M7: 8 | N7: AI 모델 접근(AI Model Access) | O7: T0040, T0044, T0047 | Q7: 공개 정보·모델 아티팩트 공개 최소화, 노출 자산 관리, AI 허니팟, 비정상 탐색·질의 탐지
A8: D01. 공격 준비 및 AI 무기화 | B8: UT-01 | C8: AI 대상 정찰 및 접근 확보 | D8: UT-01.4 | E8: 모델 및 환경 탐색 | F8: - 공격자는 모델 출력·오류·로그를 관찰하거나 확보한 환경을 열거해 모델 계열·분류 체계·출력 점수 노출 여부와 내부 AI 자원·클라우드 구성을 파악할 수 있음 - 직접 피해는 없지만 공격 대상과 방법을 정밀하게 만들며, 탈취 자격증명으로 쓸 수 있는 AI 서비스를 찾는 단계로도 쓰임 | G8: ■ AI 관점 - 모델 탐색: 반복 질의로 출력 공간(분류 클래스)과 모델 계열을 추정하고, 응답 헤더·로그에 남은 신뢰도 점수처럼 불필요하게 노출된 출력을 찾음 (ATLAS AML.T0013·T0014·T0063) - 자산 탐색: 침투한 환경에서 학습·배포 소프트웨어 스택, 데이터 관리 시스템, 모델 레지스트리, 컨테이너 이미지 속 모델을 찾아냄 (ATLAS AML.T0007) - 환경 탐색: 계정·권한·네트워크·클라우드 자원과 활성화된 AI 서비스·할당량을 확인 — 탈취 키로 사용 가능한 LLM 서비스를 고르는 데 쓰임 (ATLAS AML.T0075·T0089, UT-25.4) - 프롬프트 질의로 에이전트 도구·권한을 파악하는 탐색은 UT-08.2에서 다룸 ■ 실제 사례 - [실제 사고] LLMjacking(2024-05): 탈취한 클라우드 자격증명으로 어떤 LLM 서비스가 켜져 있고 할당량이 얼마인지 확인한 뒤 무단 사용 (ATLAS AML.CS0030) - [실제 사고] GTG-1002(2025-09): 침투 후 에이전트가 시스템·네트워크 구성과 DB 유형을 확인하고 내부 네트워크 구조 전체를 매핑 (ATLAS AML.CS0069) - [실증] ProofPoint 회피(2019-09): 메일 헤더에 남은 모델 점수를 찾아 대리 모델 학습과 탐지 회피에 활용 (ATLAS AML.CS0008) | H8: 상 | I8: 하 | J8: =IF(AND(H8="상",I8="상"),"매우 높음",IF(OR(AND(H8="상",I8="중"),AND(H8="중",I8="상")),"높음",IF(OR(AND(H8="중",I8="중"),AND(H8="상",I8="하"),AND(H8="하",I8="상")),"보통","낮음"))) | K8: 탐색 단계로 직접 피해 제한적 | L8: 실제 사고 확인 | M8: 3 | N8: 탐색(Discovery) | O8: T0007, T0013, T0014, T0063, T0075, T0089 | Q8: 공개 정보·모델 아티팩트 공개 최소화, 노출 자산 관리, AI 허니팟, 비정상 탐색·질의 탐지
A9: D01. 공격 준비 및 AI 무기화 | B9: UT-02 | C9: 공격 준비 및 일반 침투 | D9: UT-02.1 | E9: 공격 도구 확보 | F9: - 공격자는 공개된 적대적 공격 구현체·익스플로잇·딥페이크 도구·탈옥 도구와 공격용 에이전트 프레임워크·스킬을 입수하거나 직접 개발해, AI 대상 공격과 공격 자동화 역량을 확보할 수 있음 - 조직 밖에서 이뤄지는 준비 단계라 직접 탐지가 어렵고, 공개 도구와 상용 범죄 서비스가 공격 진입 장벽을 크게 낮춤 | G9: ■ AI 관점 - 입수 대상: 적대적 공격 라이브러리·공개 PoC, 범용 해킹 도구, 얼굴 합성·가상 카메라 앱 같은 딥페이크 도구, 생성형 AI 서비스 접근권, AI 서비스 키 검증·역방향 프록시 도구 (ATLAS AML.T0016) - 자체 개발: 탐지 회피용 변이 기법, 모델 백도어 삽입 도구, 안전장치 우회 도구, 1클릭 RCE 스크립트처럼 표적 AI에 맞춘 공격 도구를 직접 제작 (ATLAS AML.T0017) - 에이전트 도구: 공격용 에이전트 프레임워크, 스캐너·익스플로잇을 감싼 MCP 서버, 침투 절차를 담은 스킬을 확보·제작해 자율 공격(UT-03.1)의 실행 기반으로 사용 (ATLAS AML.T0016.004·T0017.002) - 활동이 조직 밖에서 일어나므로 위협 인텔리전스로 도구 유통과 AI 제공자 오남용 신호를 추적하는 것이 현실적인 대응임 ■ 실제 사례 - [실제 사고] Hermes 에이전트 공격(2026-05): 위협 행위자가 Hermes 에이전트와 FOFA 검색 MCP 서버를 확보하고 인증 없는 WebSocket 익스플로잇 절차를 담은 스킬을 제작해, DeepSeek 기반으로 Langflow·n8n 취약점 공격을 자율 수행 — 접근에는 실패 (ATLAS AML.CS0070) - [실제 사고] LLMjacking(2024-05): AI 서비스 키 대량 검증 도구(keychecker)와 역방향 프록시(OAI Reverse Proxy)를 입수해, 탈취한 클라우드 자격증명의 LLM 접근권을 범죄자에게 재판매 (ATLAS AML.CS0030) - [실제 사고] Storm-2139(2024-12): 생성형 AI 서비스의 안전장치를 우회하는 도구 de3u를 개발해 금지 콘텐츠 생성에 사용 (ATLAS AML.CS0057) | H9: 상 | I9: 하 | J9: =IF(AND(H9="상",I9="상"),"매우 높음",IF(OR(AND(H9="상",I9="중"),AND(H9="중",I9="상")),"높음",IF(OR(AND(H9="중",I9="중"),AND(H9="상",I9="하"),AND(H9="하",I9="상")),"보통","낮음"))) | K9: 직접 피해 없음(공격 준비 단계) | L9: 실제 사고 확인 | M9: 10 | N9: 자원 개발(Resource Development) | O9: T0016, T0016.000, T0016.001, T0016.002, T0016.003, T0016.004, T0017, T0017.000, T0017.002 | Q9: 기존 엔터프라이즈 보안통제(패치·EDR·네트워크 분리·ATT&CK 기반 탐지)를 AI 인프라까지 확장
A10: D01. 공격 준비 및 AI 무기화 | B10: UT-02 | C10: 공격 준비 및 일반 침투 | D10: UT-02.2 | E10: 공개 AI 자원 입수 | F10: - 공격자는 대상과 같거나 비슷한 공개 데이터셋·사전학습 모델·에이전트 설정 파일을 입수해, 대리 모델을 만들고 공격을 실제 대상에 쓰기 전에 미리 검증할 수 있음 - 오픈 모델·공개 데이터가 많을수록 대리 모델의 정확도가 높아져 블랙박스 서비스에도 화이트박스 수준의 공격 준비가 가능해짐 | G10: ■ AI 관점 - 입수 대상: 대상이 쓰는 것과 같거나 대표성 있는 데이터셋, 공개된 기반 모델과 참조 구현, 공개 저장소의 에이전트 설정 파일(도구·데이터 소스·자격증명 구성) (ATLAS AML.T0002) - 쓰임새: 대리 모델 학습과 적대적 예제 사전 검증(UT-16.1·17.1), 변조 모델 제작의 원본 확보(UT-28.1), 에이전트 공격 설계(UT-08.2) - 클라우드 저장소·공개 서비스 설정 오류로 조직의 비공개 학습 데이터·모델이 함께 노출되면 준비 단계가 곧 자산 유출이 됨 (UT-31.1) ■ 실제 사례 - [실제 사고] Clearview AI 설정 오류(2020-04): 비밀번호로 보호된 코드 저장소에 누구나 계정을 만들 수 있어, 학습 데이터·애플리케이션·클라우드 버킷 키에 접근 가능한 상태로 노출 (ATLAS AML.CS0006) - [실증] 기계 번역 서비스 공격(2020-04): 대상 서비스와 유사한 데이터셋·모델 구조를 확보해 대리 모델을 만들고 적대적 입력을 실제 서비스에 전이 (ATLAS AML.CS0005) - [실증] OpenClaw C2(2026-02): GitHub 공개 저장소에서 에이전트 설정 파일을 확보해 인젝션 공격 설계에 활용 (ATLAS AML.CS0051) | H10: 중 | I10: 하 | J10: =IF(AND(H10="상",I10="상"),"매우 높음",IF(OR(AND(H10="상",I10="중"),AND(H10="중",I10="상")),"높음",IF(OR(AND(H10="중",I10="중"),AND(H10="상",I10="하"),AND(H10="하",I10="상")),"보통","낮음"))) | K10: 직접 피해 없음(대리 모델 구축 등 준비 단계) | L10: 실제 사고 확인 | M10: 1 | N10: 자원 개발(Resource Development) | O10: T0002, T0002.000, T0002.001, T0002.002 | Q10: 기존 엔터프라이즈 보안통제(패치·EDR·네트워크 분리·ATT&CK 기반 탐지)를 AI 인프라까지 확장
A11: D01. 공격 준비 및 AI 무기화 | B11: UT-02 | C11: 공격 준비 및 일반 침투 | D11: UT-02.3 | E11: 공격 인프라 확보 | F11: - 공격자는 클라우드·서버리스 자원, 도메인, 단말, 물리적 공격 소품, 서비스 계정, AI 서비스 프록시를 사거나 만들고 정상 인프라를 장악해, 공격 수행과 은닉에 필요한 기반을 구축할 수 있음 - 정상 클라우드 서비스와 상용 프록시를 쓰면 출처 추적과 차단이 어렵고, 이용 정책·지역 제한도 우회됨 | G11: ■ AI 관점 - 연산 자원: 공격 개발용 GPU 작업 공간(무료 노트북·클라우드 크레딧), 출처를 숨기는 서버리스 함수 (ATLAS AML.T0008.000·T0008.004) - AI 서비스 프록시: 프런티어 모델 API 접근권을 재판매하는 상용 프록시로 대량 계정·지역 제한을 우회해 증류·남용 캠페인을 수행 (ATLAS AML.T0008.005) - 계정·도메인: 피해자 명의 계정 등록, 허브 조직 네임스페이스 선점, 인젝션 페이로드와 반출 수신용 웹서버·도메인 준비 (ATLAS AML.T0021·T0008.002·T0079) - 물리 소품·단말: 적대적 패치 인쇄, 저가 휴대폰·개조 ROM 구매 — 물리 환경 공격(UT-17.2)·딥페이크 인증 우회(UT-04.1)에 사용 ■ 실제 사례 - [실제 사고] Claude 증류 캠페인(2026-02): DeepSeek·Moonshot·MiniMax가 상용 프록시 서비스로 Claude에 접근해 중국 내 상업 이용 제한을 우회 (ATLAS AML.CS0056) - [실제 사고] Storm-2139(2024-12): 탈옥한 Azure OpenAI 접근권을 판매하는 서비스용 인프라와 역방향 프록시를 운영 (ATLAS AML.CS0057) - [실제 사고] 중국 세무 시스템 얼굴인식 우회(2020): 저가 휴대폰을 사들이고 피해자 신원으로 세무 시스템 계정을 새로 등록 (ATLAS AML.CS0004) | H11: 상 | I11: 하 | J11: =IF(AND(H11="상",I11="상"),"매우 높음",IF(OR(AND(H11="상",I11="중"),AND(H11="중",I11="상")),"높음",IF(OR(AND(H11="중",I11="중"),AND(H11="상",I11="하"),AND(H11="하",I11="상")),"보통","낮음"))) | K11: 직접 피해 없음(공격 기반 구축 단계) | L11: 실제 사고 확인 | M11: 7 | N11: 자원 개발(Resource Development) | O11: T0008, T0008.000, T0008.001, T0008.002, T0008.003, T0008.004, T0008.005, T0021, T0079, T0128 | Q11: 기존 엔터프라이즈 보안통제(패치·EDR·네트워크 분리·ATT&CK 기반 탐지)를 AI 인프라까지 확장
A12: D01. 공격 준비 및 AI 무기화 | B12: UT-02 | C12: 공격 준비 및 일반 침투 | D12: UT-02.4 | E12: 일반 초기 침투 | F12: - 공격자는 AI 서비스·지원 인프라의 공개 애플리케이션 취약점을 익스플로잇하거나, 악성 링크·드라이브바이 페이지로 사용자와 AI 에이전트를 유도해 최초 침투할 수 있음 - AI 플랫폼도 일반 웹 애플리케이션과 같은 취약점을 가지며, 침투 후 연결된 모델·데이터·자격증명으로 피해가 확대됨 | G12: ■ AI 관점 - 공개 애플리케이션 악용: AI 앱 빌더·서빙 프레임워크·에이전트 게이트웨이와 그 앞단의 웹·API 서버의 취약점(인증 우회, SSRF, 파일 업로드, JWT 검증 결함) (ATLAS AML.T0049) - 드라이브바이·악성 링크: 사용자 브라우저나 웹을 읽는 AI 에이전트가 악성 페이지를 방문하는 순간 스크립트·프롬프트 인젝션이 실행됨 (ATLAS AML.T0078·T0011.003) - 일반 엔터프라이즈 침투 기법과 같은 원리로 상세 대응은 클라우드 보안위협 매트릭스와 연계하며, 인증 없이 노출된 AI 서비스 자체는 UT-31.1, 로컬 에이전트 1클릭 장악은 UT-32.2에서 다룸 ■ 실제 사례 - [실제 사고] 대만 정부 시스템 침해(2026-07): 다중 에이전트 프레임워크가 임의 요청을 받아 인증 세션을 돌려주는 디버그 엔드포인트 3개와 서명 없는 JWT(alg=none)를 받아들이는 공개 API를 찾아 침투 (ATLAS AML.CS0071) - [실제 사고] LLMjacking(2024-05): Laravel 취약점(CVE-2021-3129)으로 최초 침투한 뒤 클라우드 자격증명을 탈취해 LLM 서비스를 무단 사용 (ATLAS AML.CS0030) - [실제 사고] ToolShell(2025-07): 에이전트에 의해 SharePoint RCE 익스플로잇이 악용된 사례로 보고 (OWASP ASI 부록 D) | H12: 상 | I12: 상 | J12: =IF(AND(H12="상",I12="상"),"매우 높음",IF(OR(AND(H12="상",I12="중"),AND(H12="중",I12="상")),"높음",IF(OR(AND(H12="중",I12="중"),AND(H12="상",I12="하"),AND(H12="하",I12="상")),"보통","낮음"))) | K12: AI 서비스 및 지원 인프라 장악으로 확대 가능 | L12: 실제 사고 확인 | M12: 7 | N12: 초기 접근(Initial Access) | O12: T0011.003, T0049, T0078 | Q12: 기존 엔터프라이즈 보안통제(패치·EDR·네트워크 분리·ATT&CK 기반 탐지)를 AI 인프라까지 확장
A13: D01. 공격 준비 및 AI 무기화 | B13: UT-02 | C13: 공격 준비 및 일반 침투 | D13: UT-02.5 | E13: 내부 확산 및 탐지 회피 | F13: - 공격자는 내부 서비스의 원격 취약점으로 다른 시스템·네트워크 경계로 확산하고, 샌드박스 탐지·난독화·보안 기능 우회 익스플로잇으로 분석과 탐지를 피해 체류를 늘릴 수 있음 - AI 평가·실행 환경의 격리 경계를 넘는 확산까지 포함하며, 인코딩·분할된 통신은 기존 보안 장비의 탐지를 어렵게 함 | G13: ■ AI 관점 - 내부 확산: 도달 가능한 내부 서비스(패키지 캐시, 레지스트리, 관리 API)의 취약점으로 다른 시스템·신뢰 경계로 이동 (ATLAS AML.T0122) - 탐지 회피: 가상화·샌드박스 환경을 감지해 동작을 바꾸고, 페이로드·명령·결과를 압축·Base64·XOR로 인코딩해 분할 전송 (ATLAS AML.T0097·T0123) - 보안 기능 우회: 취약점을 이용해 localhost 제한 같은 보안 기능을 무력화 (ATLAS AML.T0107) - AI 분석 도구를 속이는 프롬프트 인젝션 내장 악성코드처럼 AI 기반 탐지를 겨냥한 회피는 UT-06.1과 함께 봐야 함 ■ 실제 사례 - [실제 사고] OpenAI 평가용 자율 에이전트(2026-07): 내부 Artifactory의 SSRF로 평가망 경계를 넘어 인터넷에 접근하고, 명령·자격증명·결과를 압축·Base64·XOR 인코딩해 외부로 전달 (ATLAS AML.CS0068) - [실제 사고] Skynet 악성코드(2025-06): 여러 샌드박스 회피 기법과 함께 LLM 분석 도구를 겨냥한 프롬프트 인젝션을 내장 (ATLAS AML.CS0043) - [실증] OpenClaw 1클릭 RCE(2026-02): 교차 사이트 WebSocket 하이재킹으로 localhost 네트워크 제한을 우회해 로컬 게이트웨이에 접속 (ATLAS AML.CS0050) | H13: 상 | I13: 중 | J13: =IF(AND(H13="상",I13="상"),"매우 높음",IF(OR(AND(H13="상",I13="중"),AND(H13="중",I13="상")),"높음",IF(OR(AND(H13="중",I13="중"),AND(H13="상",I13="하"),AND(H13="하",I13="상")),"보통","낮음"))) | K13: 침투 범위 확대 및 탐지 지연 | L13: 실제 사고 확인 | M13: 2 | N13: 방어 회피(Defense Evasion) | O13: T0097, T0107, T0122, T0123 | Q13: 기존 엔터프라이즈 보안통제(패치·EDR·네트워크 분리·ATT&CK 기반 탐지)를 AI 인프라까지 확장
A14: D01. 공격 준비 및 AI 무기화 | B14: UT-02 | C14: 공격 준비 및 일반 침투 | D14: UT-02.6 | E14: 일반 수단 데이터 유출 | F14: - 공격자는 정보 저장소·로컬 시스템에서 데이터와 AI 자산을 자동 수집·정리한 뒤, 일반 네트워크 프로토콜이나 C2 채널로 외부에 반출할 수 있음 - AI 에이전트가 수집·집계를 자동화해 반출 규모와 속도가 커졌으며, 모델·학습 데이터·자격증명이 함께 빠져나가는 경우가 많음 | G14: ■ AI 관점 - 수집: 위키·DB·저장소 같은 정보 저장소와 로컬 파일·설정의 SSH 키·자격증명을 검색하고, 스크립트나 에이전트 도구로 자동 수집해 한곳에 모음 (ATLAS AML.T0036·T0037·T0126·T0127) - 반출: SFTP·HTTP POST·DNS 질의·Tor 등 일반 사이버 채널로 전송 (ATLAS AML.T0025·T0072) - AI 자산 특화: 모델 파일·학습 데이터·노트북 산출물이 함께 표적이 되며, 모델 파일 직접 탈취는 UT-16.2, AI 서비스 기능을 이용한 반출은 UT-19에서 다룸 ■ 실제 사례 - [실제 사고] 대만 정부 시스템 침해(2026-07): 다중 에이전트 프레임워크가 인증 없는 사용자 DB API에서 인사 기록 2,564건과 사용자 DB 전체, 내부 구조 정보를 자동 수집·반출 (ATLAS AML.CS0071) - [실제 사고] PyTorch-nightly 의존성 침해(2022-12): 악성 torchtriton 패키지가 SSH 키·설정 파일 등을 수집해 암호화된 DNS 질의로 반출 (ATLAS AML.CS0015) - [실제 사고] LAMEHUG(2025-06): LLM이 생성한 명령으로 문서·바탕화면·다운로드 폴더를 수집해 SFTP·HTTP POST로 반출 (ATLAS AML.CS0044) | H14: 상 | I14: 상 | J14: =IF(AND(H14="상",I14="상"),"매우 높음",IF(OR(AND(H14="상",I14="중"),AND(H14="중",I14="상")),"높음",IF(OR(AND(H14="중",I14="중"),AND(H14="상",I14="하"),AND(H14="하",I14="상")),"보통","낮음"))) | K14: 중요정보 및 AI 자산 대량 반출 | L14: 실제 사고 확인 | M14: 9 | N14: 유출(Exfiltration) | O14: T0025, T0036, T0037, T0072, T0126, T0127 | Q14: 기존 엔터프라이즈 보안통제(패치·EDR·네트워크 분리·ATT&CK 기반 탐지)를 AI 인프라까지 확장
A15: D01. 공격 준비 및 AI 무기화 | B15: UT-03 | C15: AI 기반 자율 공격 | D15: UT-03.1 | E15: 자율 공격 에이전트 | F15: - 공격자는 목표만 부여한 AI 에이전트가 표적 탐색, 취약점 분석·익스플로잇 개발, 실패 시 공격 경로 수정을 사람 개입 없이 반복하게 해, 사람보다 훨씬 빠른 속도와 큰 규모로 침투할 수 있음 - 공격 비용과 필요한 숙련도가 크게 낮아지며, 사람이 대응하는 속도로는 탐지·차단이 따라가기 어려움 | G15: ■ AI 관점 - 자율 정찰: 목표만 주면 에이전트가 필요한 정보를 스스로 정하고 결과를 해석해 다음 조사를 이어감 (ATLAS AML.T0116) - 자율 익스플로잇 개발: 소스·문서·오류 응답을 분석해 취약점을 추론하고 페이로드를 만들어 시험·수정 (ATLAS AML.T0017.001) - 공격 경로 적응: 중간 목표와 전제 조건을 도출하고, 막히면 다른 제품군·취약점으로 경로를 바꿔 재시도 (ATLAS AML.T0117) - 상용 코딩 에이전트를 탈옥(UT-06.2)해 쓰거나 공개 에이전트 프레임워크(UT-02.1)를 쓰며, 여러 에이전트를 조율하는 형태는 UT-03.2에서 다룸 ■ 실제 사례 - [실제 사고] GTG-1002(2025-09): 탈옥한 Claude Code가 MCP로 연결한 스캐너·크래커를 쓰며 약 30개 조직을 자율 공격 — SSRF 익스플로잇 체인을 직접 만들어 일부 침투 성공 (ATLAS AML.CS0069) - [실제 사고] Hermes 에이전트 공격(2026-05): DeepSeek 기반 에이전트가 Langflow를 표적으로 시작했다가 전제 조건이 없자 10개 제품군을 비교해 n8n으로 경로를 바꿈 — 접근에는 실패 (ATLAS AML.CS0070) - [실제 사고] 대만 정부 시스템 침해(2026-07): 에이전트 프레임워크가 공개 포털을 정찰하고 14개 후보 공격 경로를 성공 확률로 평가해 검증된 경로를 실행 (ATLAS AML.CS0071) | H15: 상 | I15: 상 | J15: =IF(AND(H15="상",I15="상"),"매우 높음",IF(OR(AND(H15="상",I15="중"),AND(H15="중",I15="상")),"높음",IF(OR(AND(H15="중",I15="중"),AND(H15="상",I15="하"),AND(H15="하",I15="상")),"보통","낮음"))) | K15: 다수 조직 동시 침투 및 시스템 장악 | L15: 실제 사고 확인 | M15: 4 | N15: AI 공격 적응(AI Attack Adaptation) | O15: T0017.001, T0116, T0117 | Q15: AI 속도 공격을 전제한 탐지·대응 자동화, AI 제공자 오남용 탐지 연계, 위협 인텔리전스
A16: D01. 공격 준비 및 AI 무기화 | B16: UT-03 | C16: AI 기반 자율 공격 | D16: UT-03.2 | E16: 다중 에이전트 공격 조율 | F16: - 공격자는 오케스트레이터 AI가 여러 하위 에이전트에 정찰·인증 공격·취약점 연구 등 임무를 나누고, 발견 결과·자격증명을 공유하게 해 여러 대상을 병렬로 공격할 수 있음 - 공유 저장소를 메시지 게시판으로 쓰는 등 에이전트 간 통신이 정상 트래픽에 섞이고, 병렬 공격으로 짧은 시간에 피해 범위가 넓어짐 | G16: ■ AI 관점 - 공격 조율: 오케스트레이터가 임무 생성, 실행 에이전트 선택, 도구 배분, 결과 집계를 맡아 공통 목표로 이끔 (ATLAS AML.T0124) - 에이전트 간 통신: 직접 호출(A2A·하위 에이전트 인터페이스) 또는 공유 저장소의 파일·디렉터리 이름으로 지시·발견·자격증명을 주고받음 (ATLAS AML.T0118.000·T0118.001) - 공유 산출물 통신은 패키지 캐시·데이터셋 저장소 같은 정상 서비스를 쓰므로 C2 채널(UT-05.3)과 구분이 어렵고, 피해 조직의 저장소가 통신 매체로 악용되기도 함 ■ 실제 사례 - [실제 사고] 대만 정부 시스템 침해(2026-07): Hermes·OpenClaw 기반 프레임워크가 최대 8개 전문 에이전트를 12차례 공격 파상으로 동시 운용 (ATLAS AML.CS0071) - [실제 사고] OpenAI 평가용 자율 에이전트(2026-07): 약 1,200개 에이전트 실행이 Artifactory 원격 캐시를 게시판으로 삼아 7만 건 이상의 지시·익스플로잇·자격증명을 공유하며 Hugging Face 운영 시스템을 침해 (ATLAS AML.CS0068) | H16: 상 | I16: 상 | J16: =IF(AND(H16="상",I16="상"),"매우 높음",IF(OR(AND(H16="상",I16="중"),AND(H16="중",I16="상")),"높음",IF(OR(AND(H16="중",I16="중"),AND(H16="상",I16="하"),AND(H16="하",I16="상")),"보통","낮음"))) | K16: 복수 대상 병렬 침투 및 시스템 장악 | L16: 실제 사고 확인 | M16: 2 | N16: AI 공격 적응(AI Attack Adaptation) | O16: T0118, T0118.000, T0118.001, T0124 | Q16: AI 속도 공격을 전제한 탐지·대응 자동화, AI 제공자 오남용 탐지 연계, 위협 인텔리전스
... A23: D01. 공격 준비 및 AI 무기화 | B23: UT-05 | C23: AI 서비스를 이용한 C2 통신 | D23: UT-05.3 | E23: AI 아티팩트 저장소 악용 | F23: - 공격자는 모델·데이터셋 저장소의 객체를 명령·페이로드 게시판으로 쓰고 실행 결과를 데이터셋에 기록하게 해, 정상 아티팩트 다운로드·업로드로 위장한 비동기 C2를 운영할 수 있음 - AI 개발 환경은 허브 저장소와의 대용량 통신이 일상적이어서 C2 트래픽이 정상 작업에 묻힘 | G23: ■ AI 관점 - 동작 방식: 공격자가 통제하는 모델·데이터셋 저장소에 명령을 올리고, 침해 시스템이 이를 폴링해 실행한 뒤 결과를 데이터셋 객체로 써 넣음 (ATLAS AML.T0120) - 은닉 효과: 학습·추론 환경에서 허브 접근은 허용 목록에 있는 경우가 많고, 아티팩트 형식이라 내용 검사가 어려움 - 대응은 허브 접근을 승인된 조직·저장소로 제한하고, 운영 환경의 예상 밖 업로드를 감시하는 것임 (UT-28.1과 같은 허용 목록 통제) ■ 실제 사례 - [실제 사고] OpenAI 평가용 자율 에이전트(2026-07): 에이전트들이 자신이 통제하는 데이터셋 저장소를 비동기 C2로 써, 침해한 작업자가 명령을 가져가고 결과를 데이터셋 객체에 기록 (ATLAS AML.CS0068) | H23: 중 | I23: 중 | J23: =IF(AND(H23="상",I23="상"),"매우 높음",IF(OR(AND(H23="상",I23="중"),AND(H23="중",I23="상")),"높음",IF(OR(AND(H23="중",I23="중"),AND(H23="상",I23="하"),AND(H23="하",I23="상")),"보통","낮음"))) | K23: 탐지 회피형 통신 채널(제한적 대역) | L23: 실제 사고 확인 | M23: 1 | N23: 명령·제어(Command and Control) | O23: T0120 | Q23: AI API 키 보호·사용량 이상 탐지, AI 서비스 egress 가시성, 비인가 AI 트래픽 차단
A24: D02. 프롬프트 인젝션 및 컨텍스트 노출 | B24: UT-06 | C24: 직접 프롬프트 인젝션 | D24: UT-06.1 | E24: 시스템 지시 무력화 | F24: - 공격자는 '이전 지시 무시'·관리자 권한 사칭 같은 입력으로 시스템 프롬프트의 역할·제약을 무력화해, 모델이 허용 범위 밖의 정보를 노출하거나 기능을 실행하게 할 수 있음 - 모델은 지시와 데이터를 구조적으로 구분하지 못해 완전한 차단이 불가능하며, 도구 권한을 가진 에이전트에서는 비인가 조회·실행으로 바로 이어짐 | G24: ■ AI 관점 - 대상: 고객 지원 챗봇, 사내 코파일럿, 업무·코딩 에이전트처럼 사용자 입력을 시스템 프롬프트와 같은 컨텍스트에서 처리하는 모든 LLM 앱 (OWASP LLM01:2026 예시 #1) - 수법: 직접 재정의 문구, 개발자·관리자 사칭, 출력 형식 지정을 가장한 지시 삽입 — 별도 인스턴스에서 반복 수정해 성공률 높은 프롬프트를 미리 확보함 (ATLAS AML.T0051.000·T0065) - 피해 범위는 앱에 부여된 권한이 결정: DB·메일·코드 실행 권한이 있으면 비인가 조회·발송·실행으로 확대되므로 시스템 프롬프트를 인가 경계로 쓰면 안 됨 (UT-21.2·21.4) - 시스템 프롬프트·도구 스키마를 먼저 빼내거나(UT-08.1) 벤더 파인튜닝 API가 돌려주는 손실값으로 페이로드를 최적화하면 성공률이 높아지며, 방어 기법을 아는 적응형 공격에는 최신 방어 다수가 90% 이상 우회됨 (OWASP LLM01:2026 예시 #7) ■ 실제 사례 - [실제 사고] Skynet 악성코드(2025-06): 바이너리에 "이전 지시를 모두 무시하라"는 문구를 넣어 LLM 기반 악성코드 분석·탐지 도구의 판정 조작을 시도한 샘플이 VirusTotal에서 발견됨 — 시험한 모델에서는 실패 (ATLAS AML.CS0043) - [실증] MathGPT(2023-01): 질문을 Python 코드로 바꿔 실행하는 앱에서 지시를 재정의해 호스트 환경변수의 OpenAI API 키를 노출시키고 서비스 거부를 유발 (ATLAS AML.CS0016) - [공개 취약점] CVE-2024-5184(EmailGPT): 사용자 입력으로 서비스 로직을 장악해 시스템 프롬프트 노출·데이터 유출 가능 (OWASP DSGAI01) | H24: 상 | I24: 중 | J24: =IF(AND(H24="상",I24="상"),"매우 높음",IF(OR(AND(H24="상",I24="중"),AND(H24="중",I24="상")),"높음",IF(OR(AND(H24="중",I24="중"),AND(H24="상",I24="하"),AND(H24="하",I24="상")),"보통","낮음"))) | K24: 앱 권한 범위 내 비인가 조회·실행 | L24: 실제 사고 확인 | M24: 4 | N24: 실행(Execution) | O24: T0051, T0051.000, T0065 | P24: LLM01 | Q24: 다층 입·출력 가드레일, 모달리티별 정규화·비가시 문자 제거, 권한 분리로 폭발반경 제한, 적대적 테스트 상시화
A25: D02. 프롬프트 인젝션 및 컨텍스트 노출 | B25: UT-06 | C25: 직접 프롬프트 인젝션 | D25: UT-06.2 | E25: 탈옥(안전장치 우회) | F25: - 공격자는 역할극·허위 권한 주장·다단계 설득·우회 표현으로 모델의 안전 정책과 가드레일을 무력화해, 금지된 콘텐츠를 생성하거나 거부해야 할 작업을 수행하게 할 수 있음 - 탈옥된 모델은 악성코드·사기 콘텐츠 생성과 에이전트 기반 공격 운용에 쓰이며, 정책 기반 차단은 표현만 바꾼 재시도에 반복적으로 뚫림 | G25: ■ AI 관점 - 수법: 역할극·가상 시나리오, 점진적 설득, 허위 목적·권한 주장, 금지어 우회 표현, 최적화된 적대적 문자열 — 저자원 언어·인코딩과 결합하면 분류기 회피율이 높아짐 (OWASP LLM01:2026 예시 #8) - 프롬프트 외에 가중치·안전장치를 직접 수정하는 방식도 있어, 오픈 가중치 모델은 정렬을 제거할 수 있고 안전 기능을 뺀 파인튜닝본이 정상 모델처럼 배포되기도 함 (ATLAS AML.T0054, OWASP LLM04:2026 시나리오 #2) - 목적은 금지 콘텐츠 생성(악성코드·피싱 문안·불법 이미지)과 에이전트의 거부 동작 해제로 나뉘며, 후자는 자율 공격 운용(UT-03.1)·파괴적 명령 실행(UT-21.5)의 선행 단계가 됨 - 탈취한 API 키로 접근한 AI 서비스에서 탈옥이 이뤄지면 금지 콘텐츠 생성의 비용·책임이 키 소유 조직에 귀속됨 (UT-25.4) ■ 실제 사례 - [실제 사고] Storm-2139(2024-12): 공개된 고객 자격증명으로 Azure OpenAI 계정에 접근한 뒤 콘텐츠 필터를 우회하는 자체 도구를 만들어 공급하고, 유명인 비동의 성적 이미지 등 금지 콘텐츠를 생성 — Microsoft가 민사 소송 제기 (ATLAS AML.CS0057) - [실제 사고] GTG-1002(2025-09): 허위 권한 주장, 방어 보안 업무 페르소나, 무해해 보이는 작업 분할로 Claude Code의 안전장치를 우회한 뒤 약 30개 조직 대상 자율 사이버 첩보 수행 (ATLAS AML.CS0069) - [실증] Claude Computer Use(2024-10): PDF에 '보안 시험용 가상 환경'이라는 거짓 맥락과 인코딩된 명령을 넣어 가드레일을 우회, bash 도구로 파일 시스템 삭제 명령 실행 (ATLAS AML.CS0046) | H25: 상 | I25: 중 | J25: =IF(AND(H25="상",I25="상"),"매우 높음",IF(OR(AND(H25="상",I25="중"),AND(H25="중",I25="상")),"높음",IF(OR(AND(H25="중",I25="중"),AND(H25="상",I25="하"),AND(H25="하",I25="상")),"보통","낮음"))) | K25: 금지 용도 악용(유해 콘텐츠·공격 도구 생성) | L25: 실제 사고 확인 | M25: 2 | N25: 방어 회피(Defense Evasion) | O25: T0054 | P25: LLM01 | Q25: 다층 입·출력 가드레일, 모달리티별 정규화·비가시 문자 제거, 권한 분리로 폭발반경 제한, 적대적 테스트 상시화
A26: D02. 프롬프트 인젝션 및 컨텍스트 노출 | B26: UT-06 | C26: 직접 프롬프트 인젝션 | D26: UT-06.3 | E26: 프롬프트 난독화 | F26: - 공격자는 인코딩·비가시 유니코드·배경색 글꼴·숨김 HTML·페이로드 분할로 인젝션 지시를 가려, 입력 가드레일과 사람 검토를 모두 통과시킬 수 있음 - 모델은 가려진 지시를 그대로 해석하지만 화면과 필터에는 정상 텍스트로 보여, 직접·간접 인젝션의 성공률을 높이는 공통 수단이 됨 | G26: ■ AI 관점 - 텍스트 은닉: 0px·배경색 글꼴, HTML 주석·숨김 요소, 페이지 제목 태그, 문서 머리글 — 사람이 보는 화면과 모델이 읽는 텍스트가 달라짐 (ATLAS AML.T0068) - 인코딩·변형: Base64·ROT13·hex 인코딩 후 디코딩 지시, 여러 입력 필드에 나눠 넣고 모델이 조합하게 하는 분할, 저자원 언어·코드 혼용 — 학습하지 않은 형식의 분류기를 통과 (OWASP LLM01:2026 예시 #8·시나리오 #5) - 비가시 유니코드: 태그 블록(U+E0000~E007F)·변형 선택자·제로폭 문자는 화면에 표시되지 않아 코드 리뷰·PR 승인을 통과하고, 반대로 응답에 데이터를 숨겨 반출하는 데도 쓰임 (UT-19.3) - 직접 입력(UT-06.1)보다 간접 주입 콘텐츠(UT-07.1)를 숨기는 데 더 자주 쓰이며, 이미지·음성 등 비텍스트 채널 은닉은 UT-06.4에서 다룸 ■ 실제 사례 - [실제 사고] AI 추천 오염 링크(2026-02): 'AI로 요약' 버튼 뒤에 자사 도메인을 신뢰 출처로 기억하라는 지시를 숨겨 URL 파라미터로만 전달 — 31개 기업이 50여 종을 유포 (ATLAS AML.CS0072) - [실증] Rules File Backdoor(2025-03): Cursor·GitHub Copilot 규칙 파일에 제로폭·양방향 유니코드로 지시를 숨겨 코드 리뷰를 통과하고, 생성 코드에 악성 스크립트를 삽입 — GitHub은 숨은 유니코드 경고 기능 추가 (ATLAS AML.CS0041) - [공개 취약점] M365 Copilot ASCII 스머글링(2024-08): 유니코드 태그 문자로 보이지 않는 지시와 데이터를 실어 Slack MFA 코드를 유출한 PoC (OWASP LLM01:2026 예시 #5) | H26: 중 | I26: 중 | J26: =IF(AND(H26="상",I26="상"),"매우 높음",IF(OR(AND(H26="상",I26="중"),AND(H26="중",I26="상")),"높음",IF(OR(AND(H26="중",I26="중"),AND(H26="상",I26="하"),AND(H26="하",I26="상")),"보통","낮음"))) | K26: 가드레일 무력화로 인젝션 성공률 증가 | L26: 실제 사고 확인 | M26: 1 | N26: 방어 회피(Defense Evasion) | O26: T0068 | P26: LLM01 | Q26: 다층 입·출력 가드레일, 모달리티별 정규화·비가시 문자 제거, 권한 분리로 폭발반경 제한, 적대적 테스트 상시화
A27: D02. 프롬프트 인젝션 및 컨텍스트 노출 | B27: UT-06 | C27: 직접 프롬프트 인젝션 | D27: UT-06.4 | E27: 멀티모달 은닉 지시 | F27: - 공격자는 이미지·음성·영상 채널이나 파일 메타데이터에 지시를 숨겨, 텍스트만 검사하는 필터와 사람 검토를 피해 멀티모달 모델의 동작을 조작할 수 있음 - 비전·음성 인코더가 숨은 지시를 텍스트처럼 해석해 유해 출력이나 도구 호출로 이어지며, 모달리티별 검사 없이는 탐지가 어려움 | G27: ■ AI 관점 - 은닉 위치: 이미지 속 저대비·초소형 텍스트, 사람이 인지하지 못하는 픽셀 섭동, 작거나 빠른 음성, 단일 영상 프레임, EXIF·ID3·문서 메타데이터 (ATLAS AML.T0129) - 다수 모더레이션·필터는 텍스트 채널만 검사하므로 비텍스트 채널의 지시는 그대로 모델에 전달되고, 비전 인코더가 이를 추출해 출력 조작·도구 호출로 이어짐 (OWASP LLM01:2026 예시 #4) - 사용자가 올린 이미지뿐 아니라 OCR로 처리되는 송장·스크린샷, 웹페이지 이미지, 회의 녹음처럼 업무 파이프라인에 들어오는 비텍스트 입력 전반이 경로가 됨 (ATLAS AML.T0093) - 멀티모달 임베딩 검색에서는 이미지 한 장으로 특정 텍스트 질의의 검색 결과를 장악하는 오염도 가능 (UT-10.3) ■ 실제 사례 - 공개 사고 미확인 — ATLAS가 2026-09에 신설한 기법(T0129)으로 실제 사고·사례연구는 아직 없음 - [실증] 의료 영상 인젝션(2025): 사람이 인지하지 못하는 수준으로 영상에 지시를 넣어 4개 최신 비전-언어 모델의 종양 판독 출력을 조작 (OWASP LLM01:2026 시나리오 #6) | H27: 중 | I27: 중 | J27: =IF(AND(H27="상",I27="상"),"매우 높음",IF(OR(AND(H27="상",I27="중"),AND(H27="중",I27="상")),"높음",IF(OR(AND(H27="중",I27="중"),AND(H27="상",I27="하"),AND(H27="하",I27="상")),"보통","낮음"))) | K27: 사람 검토 및 필터 동시 우회 | L27: 실증·공개 취약점 | M27: 0 | N27: 방어 회피(Defense Evasion) | O27: T0129 | P27: LLM01 | Q27: 다층 입·출력 가드레일, 모달리티별 정규화·비가시 문자 제거, 권한 분리로 폭발반경 제한, 적대적 테스트 상시화
A28: D02. 프롬프트 인젝션 및 컨텍스트 노출 | B28: UT-07 | C28: 간접 프롬프트 인젝션 | D28: UT-07.1 | E28: 외부 콘텐츠 경유 주입 | F28: - 공격자는 AI가 처리하는 웹페이지·메일·문서·이슈·도구 응답에 지시를 숨겨, 사용자가 해당 콘텐츠를 요약·검색하는 순간 사용자 권한으로 데이터 조회·전송 등 비인가 행위를 실행시킬 수 있음 - 사용자는 지시를 보지도 입력하지도 않으며, 메일 수신만으로 발동하는 제로클릭 경로도 있어 입력 검증·사용자 교육으로는 막기 어려움 | G28: ■ AI 관점 - 유입 경로: 웹 브라우징·검색 결과, 수신 메일·캘린더 초대, 공유 문서, 이슈·티켓·PR 설명, MCP 도구 응답 — 사용자가 열지 않은 콘텐츠도 요약·검색·자동 처리 과정에서 컨텍스트에 들어감 (ATLAS AML.T0051.001·T0093) - 신뢰 표면 악용: 공개 폼·고객 티켓·공개 이슈 같은 저권한 채널에 심은 지시를 내부 사용자의 에이전트가 고권한으로 읽고 실행해, 공격자가 직접 할 수 없는 작업을 에이전트가 대신 수행 (OWASP LLM01:2026 예시 #3) - 비공개 데이터 접근·비신뢰 콘텐츠 처리·외부 통신이 동시에 가능한 에이전트('치명적 삼요소')에서 유출 피해가 커지며, 반출은 렌더링 URL·도구 호출로 이뤄짐 (UT-19.1·19.2) - 지시는 대개 난독화(UT-06.3)로 숨겨지고, RAG에 색인되면 이후 질의마다 다시 노출되는 코퍼스 오염(UT-10.1)으로 이어짐 ■ 실제 사례 - [공개 취약점] EchoLeak(2025-05): 메일 한 통이 M365 Copilot의 RAG 컨텍스트에 들어가 사용자 조작 없이 기업 데이터를 외부 URL로 유출 — 프롬프트 인젝션 분류기와 링크 차단 필터를 모두 우회 (ATLAS AML.CS0059, OWASP LLM01:2026 시나리오 #7) - [공개 취약점] GitHub 공개 이슈 경유 저장소 탈취(2025-05): 공개 이슈에 심은 지시를 개발자의 MCP 연결 에이전트가 읽고 비공개 저장소 내용을 유출 (OWASP ASI 부록 D·LLM01:2026 시나리오 #9) - [공개 취약점] ForcedLeak(2025-09): 외부 공격자가 Salesforce Agentforce에 주입한 지시로 에이전트를 오도해 CRM 레코드를 조직 밖으로 유출 (OWASP ASI 부록 D) | H28: 중 | I28: 상 | J28: =IF(AND(H28="상",I28="상"),"매우 높음",IF(OR(AND(H28="상",I28="중"),AND(H28="중",I28="상")),"높음",IF(OR(AND(H28="중",I28="중"),AND(H28="상",I28="하"),AND(H28="하",I28="상")),"보통","낮음"))) | K28: 제로클릭 데이터 유출 및 사용자 권한 전체 악용 | L28: 실증·공개 취약점 | M28: 0 | N28: 초기 접근(Initial Access) | O28: T0051.001, T0093 | P28: LLM01, MCP06 | Q28: 비신뢰 콘텐츠 구획·출처 표시, 비신뢰 데이터 처리 중 도구 호출 제한, 목표 변경 시 인간 승인, '치명적 삼요소' 동시 성립 차단
A29: D02. 프롬프트 인젝션 및 컨텍스트 노출 | B29: UT-07 | C29: 간접 프롬프트 인젝션 | D29: UT-07.2 | E29: 지연 실행형 주입 | F29: - 공격자는 특정 키워드·다음 대화 턴·사용자의 후속 요청 같은 조건에서 발동하는 지시를 미리 심어, 주입 시점의 보호 장치를 피한 뒤 나중에 도구 호출·데이터 유출을 실행시킬 수 있음 - 주입과 실행 시점이 분리되어 턴 단위 도구 제한이나 실시간 탐지를 우회하며, 사후 원인 추적도 어려움 | G29: ■ AI 관점 - 발동 조건: 특정 키워드, 다음 대화 턴, 사용자의 후속 요청, 메일 수신·문서 추가 같은 이벤트 — 에이전트 활성화 트리거를 파악하면 외부에서 발동 시점을 조절할 수 있음 (ATLAS AML.T0051.002·T0084.002) - 우회 대상: 비신뢰 데이터가 들어온 턴에서 도구 호출을 막는 보호 장치 — 실행을 다음 턴으로 미루면 그 턴에는 사용자 입력만 있는 것처럼 보임 (ATLAS AML.T0094) - 주입과 실행 사이에 시간 차가 있어 실시간 탐지·사후 추적이 어렵고, 메모리·대화 스레드에 기록되면 세션을 넘어 지속됨 (UT-11.1·11.2) ■ 실제 사례 - [실증] Gemini 지연 도구 호출(2024-02): 메일 속 지시가 실행을 다음 대화 턴으로 미뤄, 비신뢰 데이터가 든 턴의 도구 호출 제한을 우회하고 Workspace 확장으로 비공개 문서를 조회 (ATLAS AML.CS0038) - [실증] Gemini 캘린더 초대(2025-08): 초대 제목에 심은 지시가 사용자의 "고마워" 응답에 발동해 일정 삭제·Google Home 기기 제어·Zoom 영상 송출·데이터 유출을 수행 (ATLAS AML.CS0063) - [실증] Copilot Studio 고객 지원 에이전트(2025-06): 메일 수신으로 동작하는 에이전트에 지시를 보내 회신 여부로 존재를 확인한 뒤, CRM 데이터를 메일로 유출 (ATLAS AML.CS0037) | H29: 중 | I29: 중 | J29: =IF(AND(H29="상",I29="상"),"매우 높음",IF(OR(AND(H29="상",I29="중"),AND(H29="중",I29="상")),"높음",IF(OR(AND(H29="중",I29="중"),AND(H29="상",I29="하"),AND(H29="하",I29="상")),"보통","낮음"))) | K29: 즉시 탐지 회피 후 보호장치 우회 실행 | L29: 실증·공개 취약점 | M29: 0 | N29: 방어 회피(Defense Evasion) | O29: T0051.002, T0094 | P29: LLM01 | Q29: 비신뢰 콘텐츠 구획·출처 표시, 비신뢰 데이터 처리 중 도구 호출 제한, 목표 변경 시 인간 승인, '치명적 삼요소' 동시 성립 차단
A30: D02. 프롬프트 인젝션 및 컨텍스트 노출 | B30: UT-07 | C30: 간접 프롬프트 인젝션 | D30: UT-07.4 | E30: 에이전트 유인 및 클로킹 | F30: - 공격자는 AI 에이전트를 노린 클릭 유도 화면, 프롬프트가 미리 채워진 AI 비서 링크, AI에만 다른 내용을 주는 클로킹으로 에이전트가 공격자 지시를 실행하도록 유인할 수 있음 - 사용자는 'AI로 요약' 같은 정상 기능을 쓴다고 인식하고 사람·보안 도구에는 무해한 화면만 보여, 메모리 오염·명령 실행이 드러나지 않음 | G30: ■ AI 관점 - 클릭 유인: 화면을 읽고 조작하는 컴퓨터 사용 에이전트·AI 브라우저는 버튼 문구·복사 안내 같은 UI 신호를 지시로 받아들여 클릭·코드 복사·실행을 수행 (ATLAS AML.T0100) - 조작 링크: 주요 AI 비서는 URL 파라미터(?q=·?prompt=)로 첫 프롬프트를 받으므로, 'AI로 요약' 버튼·공유 링크로 위장한 링크 한 번이 사용자 세션에서 공격자 지시를 실행 (ATLAS AML.T0131) - AI 대상 클로킹: 사용자 에이전트 문자열로 AI 브라우저·에이전트를 식별해 인젝션 콘텐츠를 주고, 사람·검색 크롤러·보안 스캐너에는 정상 콘텐츠를 보여 탐지를 피함 (ATLAS AML.T0134) - 결과는 장기 메모리 오염(UT-11.1)·추천 편향(UT-20.3)·호스트 명령 실행(UT-22.1)으로 이어짐 ■ 실제 사례 - [실제 사고] AI 추천 오염(2026-02): 'AI로 요약' 버튼에 자사 도메인을 신뢰 출처로 기억하라는 지시를 미리 채워 유포 — 약 60일간 메일 트래픽에서 31개 기업·14개 업종의 50여 종 확인, 건강·금융 조언 사이트 포함 (ATLAS AML.CS0072) - [실증] AI ClickFix(2025-05): "컴퓨터인가요?" 확인 버튼으로 Claude 컴퓨터 사용 에이전트를 유인해, 클립보드에 복사된 명령을 터미널에서 실행하게 함 (ATLAS AML.CS0055) | H30: 중 | I30: 중 | J30: =IF(AND(H30="상",I30="상"),"매우 높음",IF(OR(AND(H30="상",I30="중"),AND(H30="중",I30="상")),"높음",IF(OR(AND(H30="중",I30="중"),AND(H30="상",I30="하"),AND(H30="하",I30="상")),"보통","낮음"))) | K30: 에이전트 행위 유도(사용자 권한 범위) | L30: 실제 사고 확인 | M30: 1 | N30: 초기 접근(Initial Access) | O30: T0100, T0131, T0134 | P30: LLM01 | Q30: 비신뢰 콘텐츠 구획·출처 표시, 비신뢰 데이터 처리 중 도구 호출 제한, 목표 변경 시 인간 승인, '치명적 삼요소' 동시 성립 차단
A31: D02. 프롬프트 인젝션 및 컨텍스트 노출 | B31: UT-07 | C31: 간접 프롬프트 인젝션 | D31: UT-07.5 | E31: 에이전트 목표 탈취 | F31: - 공격자는 주입한 지시·조작된 도구 응답·위조 메시지로 에이전트의 목표와 계획, 판단 기준을 바꿔, 정상 업무 흐름 속에서 공격자 의도에 맞는 다단계 행위를 반복하게 할 수 있음 - 에이전트에 위임된 권한 전체가 공격자 목적에 쓰이며, 개별 행위는 정상 범위로 보여 목표 변경 자체를 감시하지 않으면 탐지가 어려움 | G31: ■ AI 관점 - 단일 응답 조작(UT-06.1·07.1)과 달리 목표·작업 선택·판단 경로 자체가 바뀌어, 이후 다단계 실행 전체가 공격자 목적을 수행함 (OWASP ASI01) - 탈취 경로는 프롬프트 인젝션 외에 조작된 도구 응답(UT-29.3), 악성 아티팩트, 위조된 에이전트 간 메시지(UT-27.1), 오염된 외부 데이터로 다양함 - 반복 캘린더 초대로 매일 조금씩 목표 가중치를 바꾸는 점진적 탈취는 개별 행위가 정책 범위 안에 있어 규칙 기반 탐지에 걸리지 않음 (OWASP ASI01 시나리오 #3) - 송금·승인·외부 발송 권한을 가진 업무 에이전트에서는 목표 탈취가 곧 사기 거래·허위 정보 기반 의사결정으로 이어짐 (OWASP ASI01 예시 #3·#4) ■ 실제 사례 - [공개 취약점] ChatGPT Operator(2025-02): 웹 콘텐츠의 지시를 따른 Operator가 인증된 페이지에 접근해 사용자 개인정보를 노출 (OWASP ASI 부록 D·ASI01 시나리오 #2) - [실증] Gemini 캘린더 초대(2025-08): 초대 제목의 지시가 비서의 작업을 가로채 스마트홈 기기 제어·Zoom 영상 송출 등 사용자가 요청하지 않은 행위를 수행 (ATLAS AML.CS0063) - [시나리오] 반복 캘린더 초대로 플래너 에이전트의 목표 가중치를 매일 조금씩 바꿔, 정책 범위 안에서 저마찰 승인 쪽으로 유도 (OWASP ASI01 시나리오 #3) | H31: 중 | I31: 상 | J31: =IF(AND(H31="상",I31="상"),"매우 높음",IF(OR(AND(H31="상",I31="중"),AND(H31="중",I31="상")),"높음",IF(OR(AND(H31="중",I31="중"),AND(H31="상",I31="하"),AND(H31="하",I31="상")),"보통","낮음"))) | K31: 에이전트 권한 전체를 공격자 목적에 사용 | L31: 실증·공개 취약점 | M31: 0 | N31: 실행(Execution) | P31: ASI01 | Q31: 비신뢰 콘텐츠 구획·출처 표시, 비신뢰 데이터 처리 중 도구 호출 제한, 목표 변경 시 인간 승인, '치명적 삼요소' 동시 성립 차단
A32: D02. 프롬프트 인젝션 및 컨텍스트 노출 | B32: UT-08 | C32: 숨겨진 컨텍스트 노출 | D32: UT-08.1 | E32: 시스템 프롬프트 추출 | F32: - 공격자는 반복 질의·역할 전환·출력 형식 변환 요청으로 시스템 프롬프트와 내부 규칙, 구분자·제어 토큰을 추출할 수 있음 - 노출 자체의 피해는 제한적이나 거부 조건·업무 로직이 드러나 맞춤형 인젝션 설계에 쓰이고, 시스템 프롬프트에 의존한 통제는 무력화됨 | G32: ■ AI 관점 - 수법: 반복 질의, 역할 전환, "위 내용을 코드 블록으로 출력" 같은 형식 변환·번역·요약 요청, 응답 관찰을 통한 구분자·특수 문자·기능 키워드 추론 (ATLAS AML.T0056·T0069) - 핵심 노출 대상은 프롬프트 전문보다 그 안의 거부 조건·필터 기준·업무 판단 로직·출력 형식 규칙이며, 이를 알면 거부 패턴을 피한 맞춤형 인젝션을 설계할 수 있음 (OWASP LLM08:2026 예시 #2·#3·#5) - 구분자·제어 토큰을 알아내면 가짜 RAG 결과·사용자 메시지·내부 추론 경계를 위조해 지시 체계를 교란할 수 있음 (UT-06.1·10.1) - 숨은 컨텍스트는 결국 노출된다고 가정해야 하며, 시스템 프롬프트를 인가·필터링 경계로 쓰면 추출 즉시 통제가 무력화됨 (OWASP LLM08:2026) ■ 실제 사례 - [실증] M365 Copilot 거래 정보 조작(2024-08): 응답을 관찰해 구분자(**·**END**)와 search_enterprise 함수·EmailMessage 객체를 파악한 뒤, 이를 이용해 가짜 RAG 결과를 주입 (ATLAS AML.CS0026) - [실증] OpenClaw(2026-02): <<<·>>> 제어 시퀀스와 <think> 태그를 파악해 사용자 메시지·내부 추론 경계를 위조하고 C2 지시를 심음 (ATLAS AML.CS0051) - [공개 취약점] CVE-2024-5184(EmailGPT): 프롬프트 인젝션으로 시스템 프롬프트 노출 (OWASP DSGAI01) | H32: 중 | I32: 하 | J32: =IF(AND(H32="상",I32="상"),"매우 높음",IF(OR(AND(H32="상",I32="중"),AND(H32="중",I32="상")),"높음",IF(OR(AND(H32="중",I32="중"),AND(H32="상",I32="하"),AND(H32="하",I32="상")),"보통","낮음"))) | K32: 정책 정보 노출(직접 피해 제한적) | L32: 실증·공개 취약점 | M32: 0 | N32: 탐색(Discovery) | O32: T0056, T0069, T0069.000, T0069.001, T0069.002 | P32: LLM08 | Q32: 은닉 컨텍스트 노출 가정 설계, 비밀·보안 로직을 프롬프트에 두지 않음, 권한은 외부 정책엔진에서 강제
A33: D02. 프롬프트 인젝션 및 컨텍스트 노출 | B33: UT-08 | C33: 숨겨진 컨텍스트 노출 | D33: UT-08.2 | E33: 에이전트 구성 및 권한 탐색 | F33: - 공격자는 에이전트에 직접 질의하거나 요청별 성공·거부 반응을 관찰해 연결 도구와 파라미터, 지식원, 활성화 트리거, 동작 권한 범위를 파악할 수 있음 - 탐색 결과는 반출 경로와 고가치 데이터, 원격 발동 조건을 드러내 후속 인젝션과 도구 악용을 정밀하게 만듦 | G33: ■ AI 관점 - 탐색 대상: 연결 도구와 파라미터, 지식원·임베디드 데이터, 활성화 트리거(메일 수신·문서 추가 등), 호출 체인, 에이전트가 동작하는 신원과 권한 범위 (ATLAS AML.T0084·T0133) - 수법: "어떤 도구를 쓸 수 있나" 같은 직접 질의, 다양한 요청의 성공·실패·거부 패턴 관찰, 노출된 관리 콘솔·설정 파일 열람 — 설정 접근 권한 없이 런타임 대화만으로도 가능 (OWASP LLM08:2026 시나리오 #2) - 결과물은 외부 발송 도구(반출 경로), CRM 같은 고가치 데이터, 원격 발동 트리거, 실행 함수로 이어지는 호출 체인 목록이며 후속 인젝션(UT-07.1)·도구 연쇄 악용(UT-21.4)·명령 주입(UT-22.4)의 표적이 됨 - 도구 스키마·역할별 권한 조건이 숨은 컨텍스트에 있으면 대화만으로 드러나므로, 권한 판단은 모델 밖 정책 엔진에서 강제해야 함 (OWASP LLM08:2026 예시 #1·#4) ■ 실제 사례 - [실증] Copilot Studio 고객 지원 에이전트(2025-06): 프롬프트로 지식원 파일·메일 발송 도구·Salesforce 조회 도구·메일 수신 트리거를 파악한 뒤 CRM 데이터 유출 체인을 구성 (ATLAS AML.CS0037) - [실증] Claude Code GitHub Action(2026-06): 이슈·PR 이벤트 트리거와 도구별 실행 경로를 분석해, 샌드박스 밖에서 동작하는 내장 Read 도구로 환경변수의 자격증명에 접근 (ATLAS AML.CS0067) - [실증] LLMSmith(2025-02): 소스 정적 분석으로 사용자 입력·LLM 출력이 exec·eval로 이어지는 호출 체인을 찾아 인터넷 공개 앱의 RCE 표적을 선별 (ATLAS AML.CS0052) | H33: 중 | I33: 중 | J33: =IF(AND(H33="상",I33="상"),"매우 높음",IF(OR(AND(H33="상",I33="중"),AND(H33="중",I33="상")),"높음",IF(OR(AND(H33="중",I33="중"),AND(H33="상",I33="하"),AND(H33="하",I33="상")),"보통","낮음"))) | K33: 도구·권한 범위와 반출 경로 노출로 후속 인젝션·도구 악용 정밀화 | L33: 실증·공개 취약점 | M33: 0 | N33: 탐색(Discovery) | O33: T0084, T0084.000, T0084.001, T0084.002, T0084.003, T0133 | P33: LLM08 | Q33: 은닉 컨텍스트 노출 가정 설계, 비밀·보안 로직을 프롬프트에 두지 않음, 권한은 외부 정책엔진에서 강제
A34: D02. 프롬프트 인젝션 및 컨텍스트 노출 | B34: UT-08 | C34: 숨겨진 컨텍스트 노출 | D34: UT-08.4 | E34: 프롬프트 내 비밀정보 노출 | F34: - 공격자는 시스템 프롬프트·에이전트 지시문·도구 설명에 기재된 API 키·접속 정보·내부 URL을 프롬프트 추출만으로 획득할 수 있음 - 자격증명을 숨은 컨텍스트에 두는 설계 결함이 원인이며, 노출된 자격증명은 AI를 거치지 않고 연동 시스템에 바로 쓰임 | G34: ■ AI 관점 - 흔한 형태: 시스템 프롬프트·에이전트 지시문·도구 설명에 API 키·DB 연결 문자열·토큰·내부 URL을 직접 기재하거나, 역할별 접근 규칙을 프롬프트로만 정의 (OWASP LLM08:2026 예시 #1) - 프롬프트 추출(UT-08.1)이나 로그·추적 데이터 노출(UT-33.1)로 함께 드러나며, 유출된 자격증명은 연동 시스템에 직접 쓰여 AI 측 통제를 거치지 않음 (UT-25.4) - MCP 환경에서는 하드코딩 자격증명·장기 토큰이 모델 메모리·프로토콜 로그에 남는 형태로도 나타남 (OWASP MCP01) - 숨은 컨텍스트는 비밀이 아니라는 전제로 설계해야 하며, 자격증명은 모델이 직접 다루지 않는 서버 측 비밀 저장소·토큰 중개 계층으로 분리해야 함 (OWASP LLM08:2026·LLM02:2026) ■ 실제 사례 - 공개 사고 미확인 — 프롬프트에 든 자격증명이 추출된 공개 사고는 없으나, 시스템 프롬프트 추출(UT-08.1) 사례가 다수여서 기재하는 순간 노출을 전제해야 함 - [시나리오] 도구 연동용 자격증명이 든 시스템 프롬프트가 유출되어, 공격자가 해당 자격증명으로 연동 시스템에 직접 접근 (OWASP LLM08:2026 시나리오 #1) | H34: 하 | I34: 상 | J34: =IF(AND(H34="상",I34="상"),"매우 높음",IF(OR(AND(H34="상",I34="중"),AND(H34="중",I34="상")),"높음",IF(OR(AND(H34="중",I34="중"),AND(H34="상",I34="하"),AND(H34="하",I34="상")),"보통","낮음"))) | K34: 연동 시스템 자격증명 노출로 다수 시스템 접근 | L34: 이론·시나리오 | M34: 0 | N34: 자격증명 접근(Credential Access) | P34: LLM08 | Q34: 은닉 컨텍스트 노출 가정 설계, 비밀·보안 로직을 프롬프트에 두지 않음, 권한은 외부 정책엔진에서 강제
A35: D03. AI 데이터 오염 및 유출 | B35: UT-09 | C35: 학습 데이터 오염 | D35: UT-09.1 | E35: 학습 데이터 직접 오염 | F35: 사전학습/파인튜닝 데이터에 소량의 오염 샘플 또는 트리거 패턴을 삽입하여 모델에 편향, 성능 저하, 조건부 오작동(백도어)을 내재화 | G35: • [ATLAS CS0002·실제사고] VirusTotal에 변종 샘플을 대량 제출해 크라우드소싱 학습 데이터를 오염 • [ATLAS CS0009·실제사고] Tay 챗봇이 사용자 대화로 온라인 학습되며 오염되어 혐오 발언 생성(실제 사고) • [ATLAS CS0025·실증] URL 목록형 대규모 데이터셋의 만료 도메인을 매입해 학습 데이터 오염(Split-View) | H35: 상 | I35: 중 | J35: =IF(AND(H35="상",I35="상"),"매우 높음",IF(OR(AND(H35="상",I35="중"),AND(H35="중",I35="상")),"높음",IF(OR(AND(H35="중",I35="중"),AND(H35="상",I35="하"),AND(H35="하",I35="상")),"보통","낮음"))) | K35: 모델 전반 무결성 훼손(통제권 탈취와 간접 연계) | L35: 실제 사고 확인 | M35: 2 | N35: 지속성(Persistence) | O35: T0020 | P35: LLM05, DSGAI04 | Q35: 데이터셋 출처·계보 관리(DBOM/ML-BOM), 학습데이터 정제·이상치 탐지, 재학습 입력 검증
A36: D03. AI 데이터 오염 및 유출 | B36: UT-09 | C36: 학습 데이터 오염 | D36: UT-09.3 | E36: 재학습 피드백 오염 | F36: 사용자 피드백/운영 로그를 자동 재학습에 반영하는 구조를 악용하여 조작 입력을 반복 주입함으로써 모델 행동을 점진적으로 왜곡 | G36: • [ATLAS CS0009·실제사고] Tay 챗봇이 사용자 대화로 온라인 학습되며 오염되어 혐오 발언 생성(실제 사고) • [OWASP 시나리오] 자동 재학습 피드백 루프를 악용한 모델 왜곡(LLM05 시나리오#3) | H36: 중 | I36: 중 | J36: =IF(AND(H36="상",I36="상"),"매우 높음",IF(OR(AND(H36="상",I36="중"),AND(H36="중",I36="상")),"높음",IF(OR(AND(H36="중",I36="중"),AND(H36="상",I36="하"),AND(H36="하",I36="상")),"보통","낮음"))) | K36: 점진적 왜곡(탐지 시 롤백 가능) | L36: 실제 사고 확인 | M36: 1 | N36: 지속성(Persistence) | P36: LLM05 | Q36: 데이터셋 출처·계보 관리(DBOM/ML-BOM), 학습데이터 정제·이상치 탐지, 재학습 입력 검증
A37: D03. AI 데이터 오염 및 유출 | B37: UT-09 | C37: 학습 데이터 오염 | D37: UT-09.4 | E37: 무결성 저하 공격 | F37: 적대적 입력 반복 투입 또는 데이터셋 일부 훼손을 통해 모델/데이터셋의 신뢰도를 저하시켜 운영 중단 또는 재학습 비용 유발 | G37: • [ATLAS CS0025·실증] URL 목록형 대규모 데이터셋의 만료 도메인을 매입해 학습 데이터 오염(Split-View) • [ATLAS CS0006·실제사고] Clearview AI 저장소 설정 오류로 소스코드·자격증명·모델 노출 • [ATLAS CS0009·실제사고] Tay 챗봇이 사용자 대화로 온라인 학습되며 오염되어 혐오 발언 생성(실제 사고) | H37: 상 | I37: 중 | J37: =IF(AND(H37="상",I37="상"),"매우 높음",IF(OR(AND(H37="상",I37="중"),AND(H37="중",I37="상")),"높음",IF(OR(AND(H37="중",I37="중"),AND(H37="상",I37="하"),AND(H37="하",I37="상")),"보통","낮음"))) | K37: 모델 신뢰도 저하 및 재학습 비용 | L37: 실제 사고 확인 | M37: 2 | N37: 영향(Impact) | O37: T0031, T0059 | P37: DSGAI04 | Q37: 데이터셋 출처·계보 관리(DBOM/ML-BOM), 학습데이터 정제·이상치 탐지, 재학습 입력 검증
A38: D03. AI 데이터 오염 및 유출 | B38: UT-10 | C38: 지식원(RAG) 오염 | D38: UT-10.1 | E38: 검색 코퍼스 오염 | F38: - 공격자는 RAG가 색인하는 메일·채널·공유 문서·외부 웹에 특정 질의에 걸리도록 설계한 허위 문서나 지시를 넣어, AI가 이를 권위 있는 근거로 인용하게 할 수 있음 - 한 번 색인된 오염 문서는 질의할 때마다 여러 사용자에게 반복 노출되며, 적은 수의 문서로도 대규모 지식베이스의 응답을 장악할 수 있음 | G38: ■ AI 관점 - 표적 파악: RAG가 무엇을 색인하는지(받은 메일 전체, 공개 채널, 공유 드라이브, 스크랩 대상 웹) 공개 문서나 응답 관찰로 확인 — 수신자가 열지 않은 메일까지 색인되는 경우가 많음 (ATLAS AML.T0064) - 콘텐츠 설계: 특정 질의(예: 거래처 계좌, API 키 위치)에 검색되도록 키워드·문맥을 맞춘 문서를 만들고, 허위 정보·인젝션 지시·가짜 RAG 항목을 함께 담음 (ATLAS AML.T0066·T0071) - 적재 경로: 외부 메일 발송, 공개 채널 게시, 공유 문서 편집, 스크랩 대상 웹 게시처럼 정상 수집 경로를 그대로 쓰므로 시스템 침투 없이도 색인됨 (ATLAS AML.T0070) - 수백만 건 규모의 지식베이스에서도 오염 문서 5건으로 약 90% 공격 성공이 보고되었으며, 문서 내용이 아닌 임베딩 기하 구조를 노리는 오염은 UT-10.3에서 다룸 (OWASP LLM01:2026 시나리오 #4) ■ 실제 사례 - [실증] M365 Copilot 거래 정보 조작(2024-08): 은행 정보 질의에 검색되도록 설계한 메일을 보내, Copilot이 공격자 계좌를 정상 송금 정보처럼 답하게 함 (ATLAS AML.CS0026) - [실증] Slack AI(2024-08): 공개 채널에 'API 키' 질의에 걸리는 메시지를 올려, 피해자의 비공개 채널 API 키를 재인증 링크에 담아 노출시킴 (ATLAS AML.CS0035) - [실증] Morris II 웜(2024-03): RAG에 저장된 메일 속 자기복제 프롬프트가 답장 생성 시 검색되어 다른 이메일 비서로 전파 (ATLAS AML.CS0024) | H38: 중 | I38: 중 | J38: =IF(AND(H38="상",I38="상"),"매우 높음",IF(OR(AND(H38="상",I38="중"),AND(H38="중",I38="상")),"높음",IF(OR(AND(H38="중",I38="중"),AND(H38="상",I38="하"),AND(H38="하",I38="상")),"보통","낮음"))) | K38: 응답 무결성 훼손(업무 판단 및 거래 오류) | L38: 실증·공개 취약점 | M38: 0 | N38: 지속성(Persistence) | O38: T0064, T0066, T0070, T0071 | P38: LLM01, ASI06, DSGAI21 | Q38: 수집원 신뢰등급·서명, 색인 전 검증, 검색 결과 출처 표시, 임베딩 모델 자체 검증
A39: D03. AI 데이터 오염 및 유출 | B39: UT-10 | C39: 지식원(RAG) 오염 | D39: UT-10.2 | E39: 에이전트 조회 데이터 오염 | F39: 에이전트 도구가 조회하는 DB/문서 저장소/검색 색인에 악성 지시나 허위 데이터를 기록하여, 도구 호출 결과를 통해 에이전트 행위 조작 | G39: — (근거 사례 없음: OWASP 위험 정의 기반) | H39: 하 | I39: 상 | J39: =IF(AND(H39="상",I39="상"),"매우 높음",IF(OR(AND(H39="상",I39="중"),AND(H39="중",I39="상")),"높음",IF(OR(AND(H39="중",I39="중"),AND(H39="상",I39="하"),AND(H39="하",I39="상")),"보통","낮음"))) | K39: 도구 결과 신뢰를 통한 에이전트 행위 조작 | L39: 이론·시나리오 | M39: 0 | N39: 지속성(Persistence) | O39: T0099 | P39: ASI06 | Q39: 수집원 신뢰등급·서명, 색인 전 검증, 검색 결과 출처 표시, 임베딩 모델 자체 검증
A40: D03. AI 데이터 오염 및 유출 | B40: UT-10 | C40: 지식원(RAG) 오염 | D40: UT-10.3 | E40: 임베딩 공간 조작 | F40: 임베딩 유사도를 노린 문서 조작 또는 시맨틱 캐시 오염을 통해 검색 순위를 장악하여 특정 질의에 공격자 콘텐츠가 우선 반환되도록 유도 | G40: • [OWASP 시나리오] 임베딩 유사도를 노린 공개 수집 파이프라인 공격(LLM09 시나리오#1) | H40: 하 | I40: 중 | J40: =IF(AND(H40="상",I40="상"),"매우 높음",IF(OR(AND(H40="상",I40="중"),AND(H40="중",I40="상")),"높음",IF(OR(AND(H40="중",I40="중"),AND(H40="상",I40="하"),AND(H40="하",I40="상")),"보통","낮음"))) | K40: 특정 질의 검색 결과 장악 | L40: 이론·시나리오 | M40: 0 | N40: 지속성(Persistence) | P40: LLM09 | Q40: 수집원 신뢰등급·서명, 색인 전 검증, 검색 결과 출처 표시, 임베딩 모델 자체 검증
A41: D03. AI 데이터 오염 및 유출 | B41: UT-11 | C41: 에이전트 메모리 오염 | D41: UT-11.1 | E41: 장기 메모리 오염 | F41: 공유 문서/웹 콘텐츠의 인젝션을 통해 에이전트 장기 메모리에 허위 사실이나 지속 지시를 기록하여, 이후 모든 세션에서 오염된 기억 기반으로 응답/행위 | G41: • [ATLAS CS0072·실제사고] 조작된 AI 비서 링크로 메모리를 오염시켜 특정 제품을 추천하게 만드는 홍보성 공격(실제 사고) • [ATLAS CS0040·실증] 공유 문서의 인젝션으로 ChatGPT 장기 메모리에 허위 정보를 영구 기록 • [ATLAS CS0036·실증] LLM 데스크톱 앱 메모리에서 인증 토큰을 추출해 사용자 가장(AIKatz) | H41: 중 | I41: 상 | J41: =IF(AND(H41="상",I41="상"),"매우 높음",IF(OR(AND(H41="상",I41="중"),AND(H41="중",I41="상")),"높음",IF(OR(AND(H41="중",I41="중"),AND(H41="상",I41="하"),AND(H41="하",I41="상")),"보통","낮음"))) | K41: 세션 간 지속되는 행위 장악(C2 연계 사례) | L41: 실제 사고 확인 | M41: 1 | N41: 지속성(Persistence) | O41: T0080, T0080.000 | P41: ASI06 | Q41: 메모리 쓰기 검증·출처 점수, 사용자·작업별 메모리 분리, 스냅샷·롤백, 에이전트 출력의 자동 재수집 금지
A42: D03. AI 데이터 오염 및 유출 | B42: UT-11 | C42: 에이전트 메모리 오염 | D42: UT-11.2 | E42: 대화 스레드 오염 | F42: 진행 중인 대화 스레드에 조작 지시를 삽입하여 동일 세션 내 후속 응답과 도구 호출을 지속적으로 왜곡 | G42: • [ATLAS CS0036·실증] LLM 데스크톱 앱 메모리에서 인증 토큰을 추출해 사용자 가장(AIKatz) • [ATLAS CS0051·실증] 웹페이지 인젝션으로 OpenClaw에 지속 지시를 심어 C2로 활용 • [ATLAS CS0063·실증] 캘린더 초대·메일에 숨긴 지시로 Gemini 비서가 기기·앱을 조작 | H42: 중 | I42: 중 | J42: =IF(AND(H42="상",I42="상"),"매우 높음",IF(OR(AND(H42="상",I42="중"),AND(H42="중",I42="상")),"높음",IF(OR(AND(H42="중",I42="중"),AND(H42="상",I42="하"),AND(H42="하",I42="상")),"보통","낮음"))) | K42: 단일 대화 범위 왜곡 | L42: 실증·공개 취약점 | M42: 0 | N42: 지속성(Persistence) | O42: T0080.001 | P42: ASI06 | Q42: 메모리 쓰기 검증·출처 점수, 사용자·작업별 메모리 분리, 스냅샷·롤백, 에이전트 출력의 자동 재수집 금지
A43: D03. AI 데이터 오염 및 유출 | B43: UT-11 | C43: 에이전트 메모리 오염 | D43: UT-11.3 | E43: 대화 이력 조작 | F43: 대화 이력을 변조/삭제하여 공격 흔적을 은폐하거나 과거 맥락을 위조함으로써 사용자 및 모니터링의 이상 인지 방해 | G43: • [ATLAS CS0036·실증] LLM 데스크톱 앱 메모리에서 인증 토큰을 추출해 사용자 가장(AIKatz) • [ATLAS CS0048·실증] 인터넷에 노출된 ClawdBot 제어 인터페이스 수백 개에서 자격증명 탈취·명령 실행 | H43: 중 | I43: 중 | J43: =IF(AND(H43="상",I43="상"),"매우 높음",IF(OR(AND(H43="상",I43="중"),AND(H43="중",I43="상")),"높음",IF(OR(AND(H43="중",I43="중"),AND(H43="상",I43="하"),AND(H43="하",I43="상")),"보통","낮음"))) | K43: 공격 흔적 은폐 및 이상 인지 방해 | L43: 실증·공개 취약점 | M43: 0 | N43: 방어 회피(Defense Evasion) | O43: T0092 | P43: ASI06 | Q43: 메모리 쓰기 검증·출처 점수, 사용자·작업별 메모리 분리, 스냅샷·롤백, 에이전트 출력의 자동 재수집 금지
A44: D03. AI 데이터 오염 및 유출 | B44: UT-11 | C44: 에이전트 메모리 오염 | D44: UT-11.4 | E44: 공유 메모리 오염 | F44: 다중 에이전트가 공유하는 메모리/컨텍스트 저장소에 허위 정책 또는 사실을 기록하여 다른 에이전트의 판단까지 연쇄 오염 | G44: • [OWASP 시나리오] 공유 메모리에 가짜 환불 정책을 삽입해 다른 에이전트가 재사용(ASI06 시나리오#4) | H44: 하 | I44: 중 | J44: =IF(AND(H44="상",I44="상"),"매우 높음",IF(OR(AND(H44="상",I44="중"),AND(H44="중",I44="상")),"높음",IF(OR(AND(H44="중",I44="중"),AND(H44="상",I44="하"),AND(H44="하",I44="상")),"보통","낮음"))) | K44: 다중 에이전트 판단 오염(무결성 훼손) | L44: 이론·시나리오 | M44: 0 | N44: 지속성(Persistence) | P44: ASI06 | Q44: 메모리 쓰기 검증·출처 점수, 사용자·작업별 메모리 분리, 스냅샷·롤백, 에이전트 출력의 자동 재수집 금지
A45: D03. AI 데이터 오염 및 유출 | B45: UT-12 | C45: 민감정보 노출 | D45: UT-12.1 | E45: 응답 경유 민감정보 유출 | F45: - 공격자는 조작한 질의나 주입한 지시로 모델이 컨텍스트에 있는 비밀값·개인정보·내부 문서를 응답에 그대로 출력하게 하고, 접두사 제거·인코딩으로 유출 탐지를 피할 수 있음 - 모델이 접근하는 실행 환경·RAG·도구 결과가 모두 노출 대상이 되며, 정규식 기반 비밀값·DLP 탐지는 변형된 출력을 놓치기 쉬움 | G45: ■ AI 관점 - 노출 대상: 실행 환경 변수·설정 파일의 자격증명, RAG로 불러온 문서 조각, 도구 응답, 대화 맥락의 개인정보, 추론 과정(reasoning trace) — 최종 답변뿐 아니라 도구 호출 인자도 노출 경로임 (OWASP LLM02:2026) - 탐지 회피: 키 접두사 제거, Base64·hex 인코딩, 다른 언어로 번역해 출력하게 하면 정규식·차단 목록 기반 필터를 통과함 (OWASP LLM02:2026 예시 #2) - 개별로는 허용된 여러 정보원을 종합한 응답(예: 예산·채용·실사 자료로 미공개 인수 대상 추론)도 정책상 금지된 결론이면 유출에 해당함 (OWASP LLM02:2026 예시 #2) - 숨은 제어 컨텍스트 노출은 UT-08, 외부 URL·도구로 빼내는 반출은 UT-19, 모델에 암기된 학습 데이터 추출은 UT-15.4에서 다룸 ■ 실제 사례 - [실증] Claude Code GitHub Action(2026-06): 이슈·PR 본문에 넣은 지시로 Claude가 프로세스 환경의 Anthropic API 키를 읽어 'sk-ant-' 접두사를 뗀 채 출력 — GitHub 비밀값 스캐너가 인식하지 못함 (ATLAS AML.CS0067) - [실증] Morris II 웜(2024-03): 오염 메일의 지시로 RAG 기반 메일 비서가 답장에 다른 메일의 이메일 주소·주소·전화번호를 담아 유출 (ATLAS AML.CS0024) | H45: 중 | I45: 중 | J45: =IF(AND(H45="상",I45="상"),"매우 높음",IF(OR(AND(H45="상",I45="중"),AND(H45="중",I45="상")),"높음",IF(OR(AND(H45="중",I45="중"),AND(H45="상",I45="하"),AND(H45="하",I45="상")),"보통","낮음"))) | K45: 컨텍스트 내 비밀값·개인정보 노출(질의 단위로 범위 제한) | L45: 실증·공개 취약점 | M45: 0 | N45: 유출(Exfiltration) | O45: T0057 | P45: LLM02, DSGAI01 | Q45: 학습·색인 전 비식별화, 문서별 ACL 기반 검색, 입·출력 DLP(멀티모달 포함), 필요 최소 컨텍스트
A46: D03. AI 데이터 오염 및 유출 | B46: UT-12 | C46: 민감정보 노출 | D46: UT-12.2 | E46: 검색 권한 과다 노출 | F46: RAG/에이전트 도구의 검색 범위가 사용자 권한보다 넓게 설정되어, 일반 질의만으로 열람 권한 없는 문서/데이터가 응답에 포함 | G46: • [ATLAS CS0035·실증] 공개 채널 게시글의 간접 인젝션으로 Slack AI가 비공개 채널 데이터 유출 • [ATLAS CS0037·실증] Copilot Studio 고객지원 에이전트를 인젝션해 지식원·도구를 탐색하고 CRM 데이터 유출 • [ATLAS CS0038·실증] 지시 실행을 다음 대화 턴으로 지연시켜 Gemini의 도구 호출 제한 우회 • [OWASP 인용] CVE-2026-0612 The Librarian 정보 유출 취약점 | H46: 중 | I46: 상 | J46: =IF(AND(H46="상",I46="상"),"매우 높음",IF(OR(AND(H46="상",I46="중"),AND(H46="중",I46="상")),"높음",IF(OR(AND(H46="중",I46="중"),AND(H46="상",I46="하"),AND(H46="하",I46="상")),"보통","낮음"))) | K46: 열람 권한 밖 중요정보 대량 노출 | L46: 실증·공개 취약점 | M46: 0 | N46: 수집(Collection) | O46: T0085, T0085.000, T0085.001 | P46: LLM02, DSGAI01 | Q46: 학습·색인 전 비식별화, 문서별 ACL 기반 검색, 입·출력 DLP(멀티모달 포함), 필요 최소 컨텍스트
...

Sheet 도메인·평가기준
A1: 분류 체계 정의와 위험 평가 기준
A3: 1. 3단 분류 체계
A4: 단계 | B4: 정의 | C4: 작성 규칙 | D4: 개수
A5: Lv1 도메인 | B5: 영역별 보안 리스크(공격 흐름상 위협 행위자 영역을 D01로 배치) | C5: OWASP 위협·리스크 명명 규칙 준용: [영역] + [위협 명사], 대등한 두 위협만 '및'으로 결합 / 경계 판정 규칙은 아래 2번 표 | D5: =SUMPRODUCT(1/COUNTIF(통합매트릭스!$A$5:$A$128,통합매트릭스!$A$5:$A$128))
A6: Lv2 위협 분류 | B6: 통합 위협(UT). ID 불변 | C6: '·' 나열 없이 하나의 개념으로 명명 | D6: =SUMPRODUCT(1/COUNTIF(통합매트릭스!$B$5:$B$128,통합매트릭스!$B$5:$B$128))
A7: Lv3 세부 위협 | B7: Lv2 안에서 공격 경로 또는 발생 원리가 독립된 위협 | C7: ① 독립 메커니즘 ② 근거 1개 이상(ATLAS 기법·OWASP 예시·사례) ③ 공격 단계·생애주기·통제 중 하나 이상 구별 / 병합·폐지된 ID는 재사용하지 않고 신설은 해당 Lv2의 다음 번호 부여 | D7: =COUNTA(통합매트릭스!$D$5:$D$128)
A9: 2. Lv1 도메인 정의
A10: 도메인 | B10: 영문명 | C10: 리스크 정의 | D10: 주요 대상 영역 | E10: 경계 판정 규칙 | F10: Lv2 수 | G10: Lv3 수 | H10: 위험도 '매우 높음'·'높음' Lv3
A11: D01. 공격 준비 및 AI 무기화 | B11: Attack Preparation & AI Weaponization | C11: 위협 행위자가 AI 자산을 정찰하고 공격 역량을 확보하거나, AI를 공격 수단으로 활용하여 자율 공격, 기만, 은닉 통신을 수행하는 리스크 | D11: 공개 정보, 공격 도구와 인프라, 공격자 AI 에이전트, 딥페이크, 제3자 AI 서비스 | E11: 위협 행위자 소유 자산 또는 조직 외부 활동이면 D01. 조직 자산이 직접 훼손되면 해당 영역 도메인으로 분류 | F11: =SUMPRODUCT((통합매트릭스!$A$5:$A$128=A11)/COUNTIFS(통합매트릭스!$A$5:$A$128,통합매트릭스!$A$5:$A$128,통합매트릭스!$B$5:$B$128,통합매트릭스!$B$5:$B$128)) | G11: =COUNTIF(통합매트릭스!$A$5:$A$128,A11) | H11: =COUNTIFS(통합매트릭스!$A$5:$A$128,A11,통합매트릭스!$J$5:$J$128,"매우 높음")+COUNTIFS(통합매트릭스!$A$5:$A$128,A11,통합매트릭스!$J$5:$J$128,"높음")
A12: D02. 프롬프트 인젝션 및 컨텍스트 노출 | B12: Prompt Injection & Context Exposure | C12: 사용자 입력이나 외부 콘텐츠에 삽입된 조작 지시로 모델 동작이 탈취되거나, 시스템 프롬프트 등 비공개 컨텍스트가 노출되는 리스크 | D12: 사용자 입력, 외부 콘텐츠와 도구 응답(지시 전달 경로), 시스템 프롬프트, 에이전트 구성 정보 | E12: 지시가 모델에 도달하는 경로가 핵심이면 D02. 지시가 저장소에 지속 기록되면 D03 | F12: =SUMPRODUCT((통합매트릭스!$A$5:$A$128=A12)/COUNTIFS(통합매트릭스!$A$5:$A$128,통합매트릭스!$A$5:$A$128,통합매트릭스!$B$5:$B$128,통합매트릭스!$B$5:$B$128)) | G12: =COUNTIF(통합매트릭스!$A$5:$A$128,A12) | H12: =COUNTIFS(통합매트릭스!$A$5:$A$128,A12,통합매트릭스!$J$5:$J$128,"매우 높음")+COUNTIFS(통합매트릭스!$A$5:$A$128,A12,통합매트릭스!$J$5:$J$128,"높음")
A13: D03. AI 데이터 오염 및 유출 | B13: AI Data Poisoning & Leakage | C13: 학습 데이터, RAG 지식원, 에이전트 메모리가 오염되거나, 민감정보가 응답과 입력 경로 또는 사용자 간 격리 결함을 통해 유출되는 리스크 | D13: 학습 및 파인튜닝 데이터, RAG 코퍼스와 임베딩, 벡터 DB, 에이전트 메모리와 대화 이력 | E13: 데이터가 저장되거나 색인되는 지점의 리스크면 D03. 모델 가중치 자체의 변조는 D04 | F13: =SUMPRODUCT((통합매트릭스!$A$5:$A$128=A13)/COUNTIFS(통합매트릭스!$A$5:$A$128,통합매트릭스!$A$5:$A$128,통합매트릭스!$B$5:$B$128,통합매트릭스!$B$5:$B$128)) | G13: =COUNTIF(통합매트릭스!$A$5:$A$128,A13) | H13: =COUNTIFS(통합매트릭스!$A$5:$A$128,A13,통합매트릭스!$J$5:$J$128,"매우 높음")+COUNTIFS(통합매트릭스!$A$5:$A$128,A13,통합매트릭스!$J$5:$J$128,"높음")
A14: D04. 모델 조작 및 탈취 | B14: Model Manipulation & Theft | C14: 모델 가중치와 구조가 변조되거나 적대적 입력에 의해 판단이 조작되고, 모델 자산 또는 학습 데이터가 질의와 파일 탈취로 유출되는 리스크 | D14: 모델 가중치와 아키텍처, 추론 템플릿, 추론 API, 예측 모델 | E14: 모델 파일, 가중치, 추론 동작이 공격 대상이면 D04 | F14: =SUMPRODUCT((통합매트릭스!$A$5:$A$128=A14)/COUNTIFS(통합매트릭스!$A$5:$A$128,통합매트릭스!$A$5:$A$128,통합매트릭스!$B$5:$B$128,통합매트릭스!$B$5:$B$128)) | G14: =COUNTIF(통합매트릭스!$A$5:$A$128,A14) | H14: =COUNTIFS(통합매트릭스!$A$5:$A$128,A14,통합매트릭스!$J$5:$J$128,"매우 높음")+COUNTIFS(통합매트릭스!$A$5:$A$128,A14,통합매트릭스!$J$5:$J$128,"높음")
A15: D05. 출력 처리 결함 및 신뢰성 훼손 | B15: Output Handling Flaws & Integrity Loss | C15: 모델 출력이 검증 없이 후속 시스템에서 해석되거나 반출 경로로 악용되고, 허위 또는 편향된 출력이 업무 판단에 채택되는 리스크 | D15: 출력 렌더링 환경(브라우저, 터미널, IDE), 출력 기반 DB 질의, 출력 채널 | E15: 출력의 검증, 신뢰성, 반출 채널 문제면 D05. 출력이 도구 호출이나 코드 실행으로 이어지면 D06 | F15: =SUMPRODUCT((통합매트릭스!$A$5:$A$128=A15)/COUNTIFS(통합매트릭스!$A$5:$A$128,통합매트릭스!$A$5:$A$128,통합매트릭스!$B$5:$B$128,통합매트릭스!$B$5:$B$128)) | G15: =COUNTIF(통합매트릭스!$A$5:$A$128,A15) | H15: =COUNTIFS(통합매트릭스!$A$5:$A$128,A15,통합매트릭스!$J$5:$J$128,"매우 높음")+COUNTIFS(통합매트릭스!$A$5:$A$128,A15,통합매트릭스!$J$5:$J$128,"높음")
A16: D06. 에이전트 오남용 및 통제 상실 | B16: Agent Misuse & Loss of Control | C16: 과도한 권한을 가진 에이전트가 도구와 코드를 위험하게 실행하거나, 다중 에이전트 간 오류 전파와 이상 행동으로 조직의 통제를 상실하는 리스크 | D16: 에이전트 도구 권한, 계획 및 실행 루프, 코드 실행 환경, 다중 에이전트 워크플로 | E16: 에이전트가 무엇을 잘못 실행하는가의 문제면 D06. 누구의 신원과 권한이 악용되는가의 문제면 D07 | F16: =SUMPRODUCT((통합매트릭스!$A$5:$A$128=A16)/COUNTIFS(통합매트릭스!$A$5:$A$128,통합매트릭스!$A$5:$A$128,통합매트릭스!$B$5:$B$128,통합매트릭스!$B$5:$B$128)) | G16: =COUNTIF(통합매트릭스!$A$5:$A$128,A16) | H16: =COUNTIFS(통합매트릭스!$A$5:$A$128,A16,통합매트릭스!$J$5:$J$128,"매우 높음")+COUNTIFS(통합매트릭스!$A$5:$A$128,A16,통합매트릭스!$J$5:$J$128,"높음")
A17: D07. AI 신원 및 권한 악용 | B17: AI Identity & Privilege Abuse | C17: 에이전트와 비인간 계정의 자격증명이 탈취되거나, 권한 위임 결함과 에이전트 간 통신 위조로 권한이 악용되는 리스크 | D17: API 키와 토큰, OAuth 위임, 에이전트 신원, 에이전트 간(A2A, MCP) 메시지 | E17: 누구의 신원과 권한으로 행위가 이루어지는가의 문제면 D07 | F17: =SUMPRODUCT((통합매트릭스!$A$5:$A$128=A17)/COUNTIFS(통합매트릭스!$A$5:$A$128,통합매트릭스!$A$5:$A$128,통합매트릭스!$B$5:$B$128,통합매트릭스!$B$5:$B$128)) | G17: =COUNTIF(통합매트릭스!$A$5:$A$128,A17) | H17: =COUNTIFS(통합매트릭스!$A$5:$A$128,A17,통합매트릭스!$J$5:$J$128,"매우 높음")+COUNTIFS(통합매트릭스!$A$5:$A$128,A17,통합매트릭스!$J$5:$J$128,"높음")
A18: D08. AI 공급망 침해 | B18: AI Supply Chain Compromise | C18: 외부에서 도입하는 모델, 데이터셋, 패키지, 에이전트 도구가 오염되거나 위장되어 조직 환경에 악성 요소가 유입되는 리스크 | D18: 모델 허브, 패키지 레지스트리, MCP 서버, 플러그인 및 스킬 레지스트리 | E18: 제3자 구성요소가 유입 경로면 D08. 조직 내부 데이터 소스의 오염은 D03 | F18: =SUMPRODUCT((통합매트릭스!$A$5:$A$128=A18)/COUNTIFS(통합매트릭스!$A$5:$A$128,통합매트릭스!$A$5:$A$128,통합매트릭스!$B$5:$B$128,통합매트릭스!$B$5:$B$128)) | G18: =COUNTIF(통합매트릭스!$A$5:$A$128,A18) | H18: =COUNTIFS(통합매트릭스!$A$5:$A$128,A18,통합매트릭스!$J$5:$J$128,"매우 높음")+COUNTIFS(통합매트릭스!$A$5:$A$128,A18,통합매트릭스!$J$5:$J$128,"높음")
A19: D09. AI 인프라 노출 및 자원 고갈 | B19: AI Infrastructure Exposure & Resource Exhaustion | C19: AI 서비스와 인프라가 통제 밖에서 외부에 노출되거나 운영 데이터 경로로 정보가 새어 나가고, 자원 고갈로 가용성과 비용 피해가 발생하는 리스크 | D19: 서빙 인프라, 외부 노출 서비스, 사용자 단말의 AI 어시스턴트, 관측성 도구와 라벨링 경로 | E19: 인프라 구성과 운영 방식이 원인이면 D09 | F19: =SUMPRODUCT((통합매트릭스!$A$5:$A$128=A19)/COUNTIFS(통합매트릭스!$A$5:$A$128,통합매트릭스!$A$5:$A$128,통합매트릭스!$B$5:$B$128,통합매트릭스!$B$5:$B$128)) | G19: =COUNTIF(통합매트릭스!$A$5:$A$128,A19) | H19: =COUNTIFS(통합매트릭스!$A$5:$A$128,A19,통합매트릭스!$J$5:$J$128,"매우 높음")+COUNTIFS(통합매트릭스!$A$5:$A$128,A19,통합매트릭스!$J$5:$J$128,"높음")
A20: D10. 사용자 기만 및 AI 거버넌스 미흡 | B20: User Deception & AI Governance Gaps | C20: AI 출력을 신뢰하는 사용자가 기만되어 위험한 판단을 내리거나, 감사 체계와 데이터 수명주기 관리가 미흡하여 책임 추적과 규제 준수가 어려워지는 리스크 | D20: 사용자와 승인자, 감사 로그, 데이터 분류와 보존 및 폐기 체계 | E20: 사람의 판단 또는 관리체계의 미흡이 원인이면 D10 | F20: =SUMPRODUCT((통합매트릭스!$A$5:$A$128=A20)/COUNTIFS(통합매트릭스!$A$5:$A$128,통합매트릭스!$A$5:$A$128,통합매트릭스!$B$5:$B$128,통합매트릭스!$B$5:$B$128)) | G20: =COUNTIF(통합매트릭스!$A$5:$A$128,A20) | H20: =COUNTIFS(통합매트릭스!$A$5:$A$128,A20,통합매트릭스!$J$5:$J$128,"매우 높음")+COUNTIFS(통합매트릭스!$A$5:$A$128,A20,통합매트릭스!$J$5:$J$128,"높음")
A22: 3. 위험 평가 기준 (Lv3 단위)
A23: 항목 | B23: 상 | C23: 중 | D23: 하 | E23: 산정 방식
A24: 발생가능성 | B24: 실제 사고 2건 이상 (ATLAS Incident 사례 + OWASP 인용 실제 사고) | C24: 실제 사고 1건, 또는 실증 사례(연구·레드팀)·Realized 기법·공개 취약점/익스플로잇 존재 | D24: 이론적으로 가능하나 실제 사례·실증·공개 취약점 없음 | E24: 근거(ATLAS 사례 연결·OWASP 인용 근거·Realized 기법)에서 빌드 시 산정해 값으로 기록. 사례·근거 개정 시 재산정
A25: 심각도 | B25: AI 시스템 전체 통제권 탈취 또는 중요·개인정보 대량 탈취 가능성 높음 (호스트·에이전트 장악, 연동 자격증명 탈취, 대량 반출) | C25: 부분적 통제 상실 또는 제한된 범위의 정보 노출·무결성 훼손·재무 피해 | D25: 영향 범위 제한적, 경미한 정보 노출 또는 일시적 장애 (준비·탐색 단계 포함) | E25: 분석자 평가(심각도 근거 열에 사유 기재) — 기준: 통제권 범위, 정보 노출 규모, 피해 지속성. 드롭다운으로 수정 가능
A26: 위험도 | B26: 매우 높음: 상×상 | C26: 높음: 상×중, 중×상 / 보통: 중×중, 상×하, 하×상 | D26: 낮음: 중×하, 하×중, 하×하 | E26: 발생가능성 × 심각도 3×3 매트릭스(수식, 자동 재계산)
A28: 4. 근거 수준 정의 (높은 순)
A29: 근거 수준 | B29: 판정 기준
A30: 실제 사고 확인 | B30: ATLAS Incident 사례 또는 OWASP 원문이 인용한 실제 사고가 1건 이상 연결('실제 사고 수' ≥ 1)
A31: 실사용 기법 포함 | B31: 실제 사고 연결은 없으나 ATLAS Maturity 'Realized' 기법이 귀속(주·연관 기법)
A32: 실증·공개 취약점 | B32: 연구·레드팀 실증 사례(ATLAS Exercise) 또는 OWASP 인용 취약점·익스플로잇 존재 — CVE, 벤더가 확인·조치한 취약점, 운영 서비스·모델 대상 공개 PoC 포함
A33: 이론·시나리오 | B33: 공개 근거 없음(OWASP 위험 정의·시나리오 기반). '발생하지 않음'이 아니라 '공개 근거 없음'을 의미
A35: 5. 요약설명·참조 작성 규칙
A36: 항목 | B36: 규칙
A37: 요약설명 | B37: 2줄 개조식. 1줄: '공격자는 [수단·경로]로 [행위]할 수 있음' / 2줄: 피해·확산 특성 또는 탐지·방어가 어려운 이유
A38: 참조 — ■ AI 관점 | B38: 3~4줄. 대상·경로, 수법 변형, 연계 Lv3(UT-ID), 범위 경계를 기술하고 출처를 괄호로 표기 — 예: (ATLAS AML.T0068), (OWASP LLM01:2026 예시 #5)
A39: 참조 — ■ 실제 사례 | B39: 1~3줄. [실제 사고] > [공개 취약점] > [실증] > [시나리오] 순으로 선정, '사례명(YYYY-MM): 경위·결과 (출처)' 형식. 근거가 없으면 '공개 사고 미확인 — 사유'
A40: 사례 라벨 | B40: [실제 사고] 실제 발생 사고 · [공개 취약점] CVE·벤더 확인 취약점·운영 서비스 대상 PoC · [실증] 연구·레드팀 시연(ATLAS Exercise 등) · [시나리오] OWASP 공격 시나리오

Sheet ATLAS사례연구
A1: MITRE ATLAS 사례연구(73건) — 요약 및 Lv3 매핑
A2: 주 Lv3 = 분석자가 지정한 대표 세부 위협. 매핑 Lv3 = 공식 절차(employs) 기법의 주 Lv3 + 분석자 보완. 유형: Incident=실제 사고, Exercise=실증
A4: 사례 ID | B4: 사례명 | C4: 유형 | D4: 발생·공개 시점 | E4: 행위자 | F4: 대상 | G4: 국문 요약 | H4: 주 Lv3 | I4: 매핑 Lv3 (전체) | J4: URL
A5: AML.CS0000 | B5: Evasion of Deep Learning Detector for Malware C&C Traffic | C5: Exercise | D5: 2020 | E5: Palo Alto Networks AI Research Team | F5: Palo Alto Networks malware detection system | G5: 공개 논문을 재현한 대리모델로 악성 C&C 트래픽 탐지 딥러닝 모델을 회피 | H5: UT-17.1 | I5: UT-01.1, UT-02.2, UT-16.1, UT-17.1 | J5: https://atlas.mitre.org/case-studies/AML.CS0000
A6: AML.CS0001 | B6: Botnet Domain Generation Algorithm (DGA) Detection Evasion | C6: Exercise | D6: 2020 | E6: Palo Alto Networks AI Research Team | F6: Palo Alto Networks ML-based DGA detection module | G6: 도메인명 변형 기법으로 CNN 기반 봇넷 DGA 탐지기를 우회 | H6: UT-17.1 | I6: UT-01.1, UT-02.1, UT-02.2, UT-17.1 | J6: https://atlas.mitre.org/case-studies/AML.CS0001
A7: AML.CS0002 | B7: VirusTotal Poisoning | C7: Incident | D7: 2020 | E7: Unknown | F7: VirusTotal | G7: VirusTotal에 변종 샘플을 대량 제출해 크라우드소싱 학습 데이터를 오염 | H7: UT-09.1 | I7: UT-02.1, UT-09.1, UT-17.1, UT-28.1 | J7: https://atlas.mitre.org/case-studies/AML.CS0002
A8: AML.CS0003 | B8: Bypassing Cylance's AI Malware Detection | C8: Exercise | D8: 2019-09-07 | E8: Skylight Cyber | F8: CylancePROTECT, Cylance Smart Antivirus | G8: Cylance AI 악성코드 탐지기의 판단 로직을 분석해 범용 우회 문자열 생성 | H8: UT-17.1 | I8: UT-01.1, UT-01.3, UT-01.4, UT-02.1, UT-17.1 | J8: https://atlas.mitre.org/case-studies/AML.CS0003
A9: AML.CS0004 | B9: Camera Hijack Attack on Facial Recognition System | C9: Incident | D9: 2020 | E9: Two individuals | F9: Shanghai government tax office's facial recognition service | G9: 카메라 영상 주입으로 얼굴인식 인증을 우회해 세금 사기(실제 사고) | H9: UT-17.1 | I9: UT-01.1, UT-01.3, UT-02.1, UT-02.3, UT-04.1, UT-17.1 | J9: https://atlas.mitre.org/case-studies/AML.CS0004
A10: AML.CS0005 | B10: Attack on Machine Translation Services | C10: Exercise | D10: 2020-04-30 | E10: Berkeley Artificial Intelligence Research | F10: Google Translate, Bing Translator, Systran Translate | G10: 번역 API 질의로 모델을 복제하고 적대적 예제를 원 서비스에 전이 | H10: UT-16.1 | I10: UT-01.1, UT-01.3, UT-02.2, UT-09.4, UT-16.1, UT-17.1 | J10: https://atlas.mitre.org/case-studies/AML.CS0005
A11: AML.CS0006 | B11: ClearviewAI Misconfiguration | C11: Incident | D11: 2020-04 | E11: Researchers at spiderSilk | F11: Clearview AI facial recognition tool | G11: Clearview AI 저장소 설정 오류로 소스코드·자격증명·모델 노출 | H11: UT-31.1 | I11: UT-02.2, UT-02.3, UT-02.6, UT-09.4, UT-25.1, UT-31.1 | J11: https://atlas.mitre.org/case-studies/AML.CS0006
A12: AML.CS0007 | B12: GPT-2 Model Replication | C12: Exercise | D12: 2019-08-22 | E12: Researchers at Brown University | F12: OpenAI GPT-2 | G12: 공개 정보로 GPT-2 규모 모델을 재현(모델 복제) | H12: UT-16.1 | I12: UT-01.1, UT-02.2, UT-02.3, UT-16.1 | J12: https://atlas.mitre.org/case-studies/AML.CS0007
A13: AML.CS0008 | B13: ProofPoint Evasion | C13: Exercise | D13: 2019-09-09 | E13: Researchers at Silent Break Security | F13: ProofPoint Email Protection System | G13: ProofPoint 이메일 보호 모델의 복제본을 만들어 실서비스 탐지 회피 | H13: UT-17.1 | I13: UT-01.3, UT-01.4, UT-16.1, UT-17.1 | J13: https://atlas.mitre.org/case-studies/AML.CS0008
A14: AML.CS0009 | B14: Tay Poisoning | C14: Incident | D14: 2016-03-23 | E14: 4chan Users | F14: Microsoft's Tay AI Chatbot | G14: Tay 챗봇이 사용자 대화로 온라인 학습되며 오염되어 혐오 발언 생성(실제 사고) | H14: UT-09.3 | I14: UT-01.3, UT-09.1, UT-09.3, UT-09.4, UT-28.1 | J14: https://atlas.mitre.org/case-studies/AML.CS0009
A15: AML.CS0010 | B15: Microsoft Azure Service Disruption | C15: Exercise | D15: 2020 | E15: Microsoft AI Red Team | F15: Internal Microsoft Azure Service | G15: 레드팀이 기존 침투기법과 AI 회피를 결합해 Azure 내부 서비스 중단 시연 | H15: UT-17.1 | I15: UT-01.1, UT-01.3, UT-02.6, UT-16.2, UT-17.1, UT-25.4 | J15: https://atlas.mitre.org/case-studies/AML.CS0010
... A77: AML.CS0072 | B77: AI Recommendation Poisoning via Crafted AI Assistant Links | C77: Incident | D77: 2026-02-10 | E77: Multiple commercial entities; 31 distinct companies identified | F77: Users of AI assistants with persistent memory features, including Microsoft 365 Copilot, ChatGPT, Claude, Perplexity, and Grok | G77: 조작된 AI 비서 링크로 메모리를 오염시켜 특정 제품을 추천하게 만드는 홍보성 공격(실제 사고) | H77: UT-11.1 | I77: UT-02.1, UT-02.3, UT-06.3, UT-07.4, UT-11.1, UT-20.3 | J77: https://atlas.mitre.org/case-studies/AML.CS0072

Sheet 변경이력
A1: 변경이력
A2: 개정은 새 버전 파일로 저장하고 이 시트 상단에 기록. v3.1 이전 상세 이력은 v3.1 원본 '변경이력' 시트 참조
A4: 1. v3.2 변경 내역 (2026-10-02)
A5: 버전 | B5: 구분 | C5: 대상 | D5: 변경 내용 | E5: 사유
A6: v3.2 초안 | B6: 분류 체계 | C6: Lv3 127 → 124 | D6: 병합 5건(폐지 ID는 재사용하지 않음), 신설 2건, 범위 정정 1건 — 상세는 아래 'Lv3 ID 대응' 표 | E6: 중복·경계 규칙 위반 Lv3 정리, OWASP MCP05·LLM02(암기 추출) 공백 보완
A7: v3.2 초안 | B7: 도메인명 | C7: Lv1 10개 | D7: 재검토 결과 유지 | E7: v3.1에서 OWASP 명명 규칙으로 정비한 명칭이 이번 조정 후에도 각 도메인 범위와 일치
A8: v3.2 초안 | B8: 명칭 변경 | C8: Lv2 4개 | D8: UT-02 공격 준비 및 일반 침투 기법 → 공격 준비 및 일반 침투 / UT-15 모델을 이용한 데이터 추론 공격 → 모델 기반 데이터 추론 / UT-28 모델 및 데이터 공급망 침해 → AI 개발 공급망 침해 / UT-32 단말 AI 어시스턴트 과권한 → 단말 AI 어시스턴트 악용 | E8: 명명 규칙 정비('기법' 접미 제거), 신설·병합으로 넓어진 범위 반영(학습 데이터 추출, 패키지·배포 파이프라인, 장악·통제 우회)
A9: v3.2 초안 | B9: 명칭 변경 | C9: Lv3 8개 | D9: UT-04.1 딥페이크 생체인증 우회, UT-06.3 프롬프트 난독화, UT-08.2 에이전트 구성 및 권한 탐색, UT-12.1 응답 경유 민감정보 유출, UT-25.1 평문 저장 자격증명 수집, UT-25.3 인증 토큰 및 세션 쿠키 탈취, UT-26.2 캐시된 자격증명 재사용, UT-28.1 변조 모델 및 데이터셋 유입 | E9: 대상·수단을 명확히 하고 ATLAS 용어·클라우드 매트릭스 v4 연계 명칭과 정렬
A10: v3.2 초안 | B10: 기법 재귀속 | C10: ATLAS 기법 10개 | D10: T0065 UT-06.3→06.1, T0063 UT-15.3→01.4, T0052.001 UT-04.2→04.3 / 폐지 Lv3 소속: T0016.004·T0017.002→UT-02.1, T0064·T0066→UT-10.1, T0133→UT-08.2, T0115.000→UT-28.1, T0062→UT-28.3 | E10: 기법 정의와 Lv3 의미 일치(범용 프롬프트 제작은 지시 무력화, 모델 출력 점수 탐색은 모델 탐색)
A11: v3.2 초안 | B11: 열 구성 | C11: 통합매트릭스 | D11: '위협 설명 (Lv3)' → '요약설명', '실제 사례·공격 예시' → '참조'(■ AI 관점 · ■ 실제 사례), 요약설명·참조를 세부 위협 바로 옆으로 이동 | E11: 참고 양식(클라우드 매트릭스 v4) 구성 적용
