Workbook

Sheet 개요
A1: 통합 AI 보안위협 매트릭스 (UTM) v3.1 LITE
A2: Lv1 도메인 10 · Lv2 위협 분류 36 · Lv3 세부 위협 127 · 위험 평가(발생가능성×심각도) | 2026-10-02 | v3.1 원본에서 핵심 시트·열만 남긴 경량 최종본
A4: 1. 통합 대상 소스
A5: 소스 | B5: 버전 / 공개일 | C5: 규모 | D5: 관점 | E5: 입수 경로
A6: MITRE ATLAS | B6: v2026.09 (2026-09-15) | C6: 전술 16 · 기법 208 · 완화책 40 · 사례 73 · 절차 665 | D6: 공격자 TTP | E6: 첨부 excel-atlas*.xlsx + ATLAS-2026_09.yaml
A7: OWASP Top 10 for LLM Applications | B7: 2026 (2026-08-04) | C7: 10 | D7: LLM 애플리케이션 위험 | E7: 첨부 원문
A8: OWASP Top 10 for Agentic Applications | B8: 2026 (2025-12-09) | C8: 10 + 사고 추적표 25건 | D8: 에이전트 위험 | E8: 첨부 원문
A9: OWASP GenAI Data Security | B9: 2026 v1.0 (2026-03) | C9: 21 | D9: 데이터 생애주기 위험 | E9: 첨부 원문
A10: OWASP MCP Top 10 (승인된 추가 소스) | B10: 2025 (beta) | C10: 10 | D10: MCP 프로토콜 계층 | E10: github.com/OWASP/www-project-mcp-top-10
A12: 2. 핵심 지표 (수식 연동)
A13: 지표 | B13: 값
A14: Lv1 도메인 / Lv2 위협 분류 / Lv3 세부 위협 | B14: =SUMPRODUCT(1/COUNTIF(통합매트릭스!$A$5:$A$131,통합매트릭스!$A$5:$A$131))&" / "&SUMPRODUCT(1/COUNTIF(통합매트릭스!$B$5:$B$131,통합매트릭스!$B$5:$B$131))&" / "&COUNTA(통합매트릭스!$D$5:$D$131)
A15: 위험도 매우 높음 / 높음 / 보통 / 낮음 | B15: =COUNTIF(통합매트릭스!$I$5:$I$131,"매우 높음")&" / "&COUNTIF(통합매트릭스!$I$5:$I$131,"높음")&" / "&COUNTIF(통합매트릭스!$I$5:$I$131,"보통")&" / "&COUNTIF(통합매트릭스!$I$5:$I$131,"낮음")
A16: 근거 수준 실제 사고 확인 / 실사용 기법 포함 / 실증·공개 취약점 / 이론·시나리오 | B16: =COUNTIF(통합매트릭스!$K$5:$K$131,"실제 사고 확인")&" / "&COUNTIF(통합매트릭스!$K$5:$K$131,"실사용 기법 포함")&" / "&COUNTIF(통합매트릭스!$K$5:$K$131,"실증·공개 취약점")&" / "&COUNTIF(통합매트릭스!$K$5:$K$131,"이론·시나리오")
A17: 실제 사고가 1건 이상 연결된 Lv3 | B17: =COUNTIF(통합매트릭스!$L$5:$L$131,">0")
A19: 3. 위험 매트릭스 (Lv3 수)
A20: 발생가능성 \ 심각도 | B20: 상 | C20: 중 | D20: 하
A21: 상 | B21: =COUNTIFS(통합매트릭스!$G$5:$G$131,"상",통합매트릭스!$H$5:$H$131,"상") | C21: =COUNTIFS(통합매트릭스!$G$5:$G$131,"상",통합매트릭스!$H$5:$H$131,"중") | D21: =COUNTIFS(통합매트릭스!$G$5:$G$131,"상",통합매트릭스!$H$5:$H$131,"하")
A22: 중 | B22: =COUNTIFS(통합매트릭스!$G$5:$G$131,"중",통합매트릭스!$H$5:$H$131,"상") | C22: =COUNTIFS(통합매트릭스!$G$5:$G$131,"중",통합매트릭스!$H$5:$H$131,"중") | D22: =COUNTIFS(통합매트릭스!$G$5:$G$131,"중",통합매트릭스!$H$5:$H$131,"하")
A23: 하 | B23: =COUNTIFS(통합매트릭스!$G$5:$G$131,"하",통합매트릭스!$H$5:$H$131,"상") | C23: =COUNTIFS(통합매트릭스!$G$5:$G$131,"하",통합매트릭스!$H$5:$H$131,"중") | D23: =COUNTIFS(통합매트릭스!$G$5:$G$131,"하",통합매트릭스!$H$5:$H$131,"하")
A25: 4. 시트 구성
A26: 시트 | B26: 내용
A27: 통합매트릭스 | B27: 핵심 산출물. Lv3 127행 — 분류 체계, 위험 평가, 교차 매핑(공격 단계·ATLAS·OWASP), 실제 사례, 핵심 통제(Lv2)
A28: 도메인·평가기준 | B28: 3단 분류 정의와 작성 규칙, Lv1 도메인 리스크 정의·경계 판정 규칙, 위험 평가·근거 수준 기준
A29: ATLAS사례연구 | B29: MITRE ATLAS 사례 73건 요약과 Lv3 매핑 — '실제 사례·공격 예시' 열의 CS ID 조회용
A30: 변경이력 | B30: 버전별 변경 내역(이후 개정은 새 버전 파일로 저장하고 이 시트에 기록)

Sheet 통합매트릭스
A1: 통합 AI 보안위협 매트릭스 v3.1 LITE — Lv1 도메인(10) · Lv2 위협 분류(36) · Lv3 세부 위협(127)
A2: 기준: MITRE ATLAS v2026.09 · OWASP LLM Top 10 2026 · Agentic Top 10 2026 · GenAI Data Security 2026 v1.0 · MCP Top 10(2025 beta) | 2026-10-02
A3: 분류 체계 (Lv1 · Lv2 · Lv3) | G3: 위험 평가 | M3: 교차 매핑 | P3: 실제 근거 | Q3: 통제 (Lv2)
A4: 도메인 (Lv1) | B4: UT-ID | C4: 위협 분류 (Lv2) | D4: Lv3 ID | E4: 세부 위협 (Lv3) | F4: 위협 설명 (Lv3) | G4: 발생가능성 | H4: 심각도 | I4: 위험도 | J4: 심각도 근거 | K4: 근거 수준 | L4: 실제 사고 수 | M4: 주 공격 단계 | N4: ATLAS 기법 (주) | O4: OWASP 매핑 (주) | P4: 실제 사례·공격 예시 | Q4: 핵심 통제 요약
A5: D01. 공격 준비 및 AI 무기화 | B5: UT-01 | C5: AI 대상 정찰 및 접근 확보 | D5: UT-01.1 | E5: 공개 정보 수집 | F5: 공개 논문/기술 블로그/코드 저장소/조직 웹사이트 분석을 통해 대상 AI의 모델 구조, 학습 데이터, 사용 프레임워크 및 관련 인물 정보를 수집하여 후속 공격 설계에 활용 | G5: 상 | H5: 하 | I5: =IF(AND(G5="상",H5="상"),"매우 높음",IF(OR(AND(G5="상",H5="중"),AND(G5="중",H5="상")),"높음",IF(OR(AND(G5="중",H5="중"),AND(G5="상",H5="하"),AND(G5="하",H5="상")),"보통","낮음"))) | J5: 직접 피해 없음(후속 공격 설계 단계) | K5: 실제 사고 확인 | L5: 3 | M5: 정찰(Reconnaissance) | N5: T0000, T0000.000, T0000.001, T0000.002, T0000.003, T0001, T0003, T0004, T0095, T0095.000, T0087 | P5: • [ATLAS CS0004·실제사고] 카메라 영상 주입으로 얼굴인식 인증을 우회해 세금 사기(실제 사고) • [ATLAS CS0034·실제사고] KYC 우회용 딥페이크 도구 ProKYC가 범죄자에게 판매(실제 사고) • [ATLAS CS0070·실제사고] DeepSeek 기반 Hermes 에이전트로 Langflow·n8n 취약점 공격 시도(실제 사고) | Q5: 공개 정보·모델 아티팩트 공개 최소화, 노출 자산 관리, AI 허니팟, 비정상 탐색·질의 탐지
A6: D01. 공격 준비 및 AI 무기화 | B6: UT-01 | C6: AI 대상 정찰 및 접근 확보 | D6: UT-01.2 | E6: 노출 AI 자산 스캔 | F6: 인터넷 스캔/메타데이터 API 조회를 통해 외부에 노출된 AI 서비스, 모델 저장소, 에이전트 호출 채널을 식별하고 공격 가능한 진입점 목록화 | G6: 상 | H6: 하 | I6: =IF(AND(G6="상",H6="상"),"매우 높음",IF(OR(AND(G6="상",H6="중"),AND(G6="중",H6="상")),"높음",IF(OR(AND(G6="중",H6="중"),AND(G6="상",H6="하"),AND(G6="하",H6="상")),"보통","낮음"))) | J6: 직접 피해 없음(공격 진입점 식별 단계) | K6: 실제 사고 확인 | L6: 4 | M6: 정찰(Reconnaissance) | N6: T0006, T0006.000, T0006.001, T0006.002, T0006.003 | P6: • [ATLAS CS0023·실제사고] 인증 없는 Ray 클러스터를 탈취해 연산자원·자격증명·모델 탈취(ShadowRay, 실제 사고) • [ATLAS CS0069·실제사고] GTG-1002가 탈옥한 Claude Code로 약 30개 조직 대상 자율 사이버 첩보(실제 사고) • [ATLAS CS0070·실제사고] DeepSeek 기반 Hermes 에이전트로 Langflow·n8n 취약점 공격 시도(실제 사고) | Q6: 공개 정보·모델 아티팩트 공개 최소화, 노출 자산 관리, AI 허니팟, 비정상 탐색·질의 탐지
A7: D01. 공격 준비 및 AI 무기화 | B7: UT-01 | C7: AI 대상 정찰 및 접근 확보 | D7: UT-01.3 | E7: AI 모델 접근 확보 | F7: 추론 API/AI 탑재 제품/모델 파일 확보를 통해 대상 모델에 대한 질의 권한 또는 전체 접근 권한을 획득하여 추출/회피/추론 공격의 기반 마련 | G7: 상 | H7: 중 | I7: =IF(AND(G7="상",H7="상"),"매우 높음",IF(OR(AND(G7="상",H7="중"),AND(G7="중",H7="상")),"높음",IF(OR(AND(G7="중",H7="중"),AND(G7="상",H7="하"),AND(G7="하",H7="상")),"보통","낮음"))) | J7: 질의 또는 전체 접근 확보로 추출/회피/추론 공격 기반 형성 | K7: 실제 사고 확인 | L7: 8 | M7: AI 모델 접근(AI Model Access) | N7: T0040, T0044, T0047 | P7: • [ATLAS CS0004·실제사고] 카메라 영상 주입으로 얼굴인식 인증을 우회해 세금 사기(실제 사고) • [ATLAS CS0009·실제사고] Tay 챗봇이 사용자 대화로 온라인 학습되며 오염되어 혐오 발언 생성(실제 사고) • [ATLAS CS0017·실제사고] ID.me 자동 신원확인을 우회해 180건 이상 허위 실업급여 청구(실제 사고) | Q7: 공개 정보·모델 아티팩트 공개 최소화, 노출 자산 관리, AI 허니팟, 비정상 탐색·질의 탐지
A8: D01. 공격 준비 및 AI 무기화 | B8: UT-01 | C8: AI 대상 정찰 및 접근 확보 | D8: UT-01.4 | E8: 모델 및 환경 탐색 | F8: 출력 관찰/아티팩트 조회를 통해 모델 계열, 분류 체계, 내부 AI 자원 및 실행 환경을 파악하여 공격 정밀도 제고 | G8: 상 | H8: 하 | I8: =IF(AND(G8="상",H8="상"),"매우 높음",IF(OR(AND(G8="상",H8="중"),AND(G8="중",H8="상")),"높음",IF(OR(AND(G8="중",H8="중"),AND(G8="상",H8="하"),AND(G8="하",H8="상")),"보통","낮음"))) | J8: 탐색 단계로 직접 피해 제한적 | K8: 실제 사고 확인 | L8: 3 | M8: 탐색(Discovery) | N8: T0007, T0013, T0014, T0075, T0089 | P8: • [ATLAS CS0030·실제사고] 탈취한 클라우드 자격증명으로 LLM 서비스를 무단 사용·재판매(LLMjacking, 실제 사고) • [ATLAS CS0068·실제사고] OpenAI 평가용 자율 에이전트들이 평가 경계를 넘어 외부 인프라 구축·Hugging Face 침해(실제 사고) • [ATLAS CS0069·실제사고] GTG-1002가 탈옥한 Claude Code로 약 30개 조직 대상 자율 사이버 첩보(실제 사고) | Q8: 공개 정보·모델 아티팩트 공개 최소화, 노출 자산 관리, AI 허니팟, 비정상 탐색·질의 탐지
A9: D01. 공격 준비 및 AI 무기화 | B9: UT-02 | C9: 공격 준비 및 일반 침투 기법 | D9: UT-02.1 | E9: 공격 도구 확보 | F9: 공개 적대적 공격 구현체/익스플로잇/범용 해킹 도구를 입수하거나 자체 개발하여 AI 대상 공격 역량 확보 | G9: 상 | H9: 하 | I9: =IF(AND(G9="상",H9="상"),"매우 높음",IF(OR(AND(G9="상",H9="중"),AND(G9="중",H9="상")),"높음",IF(OR(AND(G9="중",H9="중"),AND(G9="상",H9="하"),AND(G9="하",H9="상")),"보통","낮음"))) | J9: 직접 피해 없음(공격 준비 단계) | K9: 실제 사고 확인 | L9: 10 | M9: 자원 개발(Resource Development) | N9: T0016, T0016.000, T0016.001, T0016.002, T0016.003, T0017, T0017.000 | P9: • [ATLAS CS0002·실제사고] VirusTotal에 변종 샘플을 대량 제출해 크라우드소싱 학습 데이터를 오염 • [ATLAS CS0004·실제사고] 카메라 영상 주입으로 얼굴인식 인증을 우회해 세금 사기(실제 사고) • [ATLAS CS0030·실제사고] 탈취한 클라우드 자격증명으로 LLM 서비스를 무단 사용·재판매(LLMjacking, 실제 사고) | Q9: 기존 엔터프라이즈 보안통제(패치·EDR·네트워크 분리·ATT&CK 기반 탐지)를 AI 인프라까지 확장
A10: D01. 공격 준비 및 AI 무기화 | B10: UT-02 | C10: 공격 준비 및 일반 침투 기법 | D10: UT-02.2 | E10: 공개 AI 자원 입수 | F10: 공개 데이터셋/사전학습 모델/에이전트 설정 파일을 입수하여 대리 모델 구축 및 공격 사전 검증에 활용 | G10: 중 | H10: 하 | I10: =IF(AND(G10="상",H10="상"),"매우 높음",IF(OR(AND(G10="상",H10="중"),AND(G10="중",H10="상")),"높음",IF(OR(AND(G10="중",H10="중"),AND(G10="상",H10="하"),AND(G10="하",H10="상")),"보통","낮음"))) | J10: 직접 피해 없음(대리 모델 구축 등 준비 단계) | K10: 실제 사고 확인 | L10: 1 | M10: 자원 개발(Resource Development) | N10: T0002, T0002.000, T0002.001, T0002.002 | P10: • [ATLAS CS0006·실제사고] Clearview AI 저장소 설정 오류로 소스코드·자격증명·모델 노출 • [ATLAS CS0000·실증] 공개 논문을 재현한 대리모델로 악성 C&C 트래픽 탐지 딥러닝 모델을 회피 • [ATLAS CS0001·실증] 도메인명 변형 기법으로 CNN 기반 봇넷 DGA 탐지기를 우회 | Q10: 기존 엔터프라이즈 보안통제(패치·EDR·네트워크 분리·ATT&CK 기반 탐지)를 AI 인프라까지 확장
A11: D01. 공격 준비 및 AI 무기화 | B11: UT-02 | C11: 공격 준비 및 일반 침투 기법 | D11: UT-02.3 | E11: 공격 인프라 확보 | F11: 클라우드 자원/도메인/물리적 대응물 구매, 계정 생성, 정상 인프라 탈취를 통해 공격 수행 및 은닉에 필요한 기반 구축 | G11: 상 | H11: 하 | I11: =IF(AND(G11="상",H11="상"),"매우 높음",IF(OR(AND(G11="상",H11="중"),AND(G11="중",H11="상")),"높음",IF(OR(AND(G11="중",H11="중"),AND(G11="상",H11="하"),AND(G11="하",H11="상")),"보통","낮음"))) | J11: 직접 피해 없음(공격 기반 구축 단계) | K11: 실제 사고 확인 | L11: 7 | M11: 자원 개발(Resource Development) | N11: T0008, T0008.000, T0008.001, T0008.002, T0008.003, T0008.004, T0008.005, T0021, T0079, T0128 | P11: • [ATLAS CS0004·실제사고] 카메라 영상 주입으로 얼굴인식 인증을 우회해 세금 사기(실제 사고) • [ATLAS CS0006·실제사고] Clearview AI 저장소 설정 오류로 소스코드·자격증명·모델 노출 • [ATLAS CS0034·실제사고] KYC 우회용 딥페이크 도구 ProKYC가 범죄자에게 판매(실제 사고) | Q11: 기존 엔터프라이즈 보안통제(패치·EDR·네트워크 분리·ATT&CK 기반 탐지)를 AI 인프라까지 확장
A12: D01. 공격 준비 및 AI 무기화 | B12: UT-02 | C12: 공격 준비 및 일반 침투 기법 | D12: UT-02.4 | E12: 일반 초기 침투 | F12: 공개 애플리케이션 취약점 익스플로잇/드라이브바이 다운로드/악성 링크 실행 유도를 통해 AI 서비스 및 지원 인프라에 최초 침투 | G12: 상 | H12: 상 | I12: =IF(AND(G12="상",H12="상"),"매우 높음",IF(OR(AND(G12="상",H12="중"),AND(G12="중",H12="상")),"높음",IF(OR(AND(G12="중",H12="중"),AND(G12="상",H12="하"),AND(G12="하",H12="상")),"보통","낮음"))) | J12: AI 서비스 및 지원 인프라 장악으로 확대 가능 | K12: 실제 사고 확인 | L12: 7 | M12: 초기 접근(Initial Access) | N12: T0049, T0078, T0011.003 | P12: • [ATLAS CS0023·실제사고] 인증 없는 Ray 클러스터를 탈취해 연산자원·자격증명·모델 탈취(ShadowRay, 실제 사고) • [ATLAS CS0030·실제사고] 탈취한 클라우드 자격증명으로 LLM 서비스를 무단 사용·재판매(LLMjacking, 실제 사고) • [ATLAS CS0068·실제사고] OpenAI 평가용 자율 에이전트들이 평가 경계를 넘어 외부 인프라 구축·Hugging Face 침해(실제 사고) • [OWASP 인용] ToolShell SharePoint RCE 악용(2025.07, 실제 사고) / Flowise 사전인증 임의 파일 업로드(2025.03) | Q12: 기존 엔터프라이즈 보안통제(패치·EDR·네트워크 분리·ATT&CK 기반 탐지)를 AI 인프라까지 확장
A13: D01. 공격 준비 및 AI 무기화 | B13: UT-02 | C13: 공격 준비 및 일반 침투 기법 | D13: UT-02.5 | E13: 내부 확산 및 탐지 회피 | F13: 원격 서비스 악용을 통한 내부 확산과 샌드박스 회피/난독화를 통한 보안 탐지 우회로 침투 범위 확대 및 체류 장기화 | G13: 상 | H13: 중 | I13: =IF(AND(G13="상",H13="상"),"매우 높음",IF(OR(AND(G13="상",H13="중"),AND(G13="중",H13="상")),"높음",IF(OR(AND(G13="중",H13="중"),AND(G13="상",H13="하"),AND(G13="하",H13="상")),"보통","낮음"))) | J13: 침투 범위 확대 및 탐지 지연 | K13: 실제 사고 확인 | L13: 2 | M13: 방어 회피(Defense Evasion) | N13: T0122, T0097, T0107, T0123 | P13: • [ATLAS CS0043·실제사고] LLM 기반 악성코드 분석기를 속이려 프롬프트 인젝션을 내장한 악성코드(실제 사고) • [ATLAS CS0068·실제사고] OpenAI 평가용 자율 에이전트들이 평가 경계를 넘어 외부 인프라 구축·Hugging Face 침해(실제 사고) • [ATLAS CS0050·실증] 악성 링크 1회 클릭으로 OpenClaw 로컬 에이전트 원격 코드 실행 | Q13: 기존 엔터프라이즈 보안통제(패치·EDR·네트워크 분리·ATT&CK 기반 탐지)를 AI 인프라까지 확장
A14: D01. 공격 준비 및 AI 무기화 | B14: UT-02 | C14: 공격 준비 및 일반 침투 기법 | D14: UT-02.6 | E14: 일반 수단 데이터 유출 | F14: 정보 저장소/로컬 시스템의 데이터를 자동 수집 및 압축한 후 일반 네트워크 또는 C2 채널로 외부 반출 | G14: 상 | H14: 상 | I14: =IF(AND(G14="상",H14="상"),"매우 높음",IF(OR(AND(G14="상",H14="중"),AND(G14="중",H14="상")),"높음",IF(OR(AND(G14="중",H14="중"),AND(G14="상",H14="하"),AND(G14="하",H14="상")),"보통","낮음"))) | J14: 중요정보 및 AI 자산 대량 반출 | K14: 실제 사고 확인 | L14: 9 | M14: 유출(Exfiltration) | N14: T0036, T0037, T0126, T0127, T0025, T0072 | P14: • [ATLAS CS0006·실제사고] Clearview AI 저장소 설정 오류로 소스코드·자격증명·모델 노출 • [ATLAS CS0015·실제사고] PyPI에 올라간 악성 torchtriton 의존성으로 PyTorch-nightly 사용자 정보 유출(실제 사고) • [ATLAS CS0023·실제사고] 인증 없는 Ray 클러스터를 탈취해 연산자원·자격증명·모델 탈취(ShadowRay, 실제 사고) | Q14: 기존 엔터프라이즈 보안통제(패치·EDR·네트워크 분리·ATT&CK 기반 탐지)를 AI 인프라까지 확장
A15: D01. 공격 준비 및 AI 무기화 | B15: UT-03 | C15: AI 기반 자율 공격 | D15: UT-03.1 | E15: 자율 공격 에이전트 | F15: 공격 목표만 부여받은 AI 에이전트가 대상 탐색, 익스플로잇 개발, 실패 시 공격 경로 수정을 사람 개입 없이 반복 수행하여 사람 대비 압도적 속도와 규모로 침투 | G15: 상 | H15: 상 | I15: =IF(AND(G15="상",H15="상"),"매우 높음",IF(OR(AND(G15="상",H15="중"),AND(G15="중",H15="상")),"높음",IF(OR(AND(G15="중",H15="중"),AND(G15="상",H15="하"),AND(G15="하",H15="상")),"보통","낮음"))) | J15: 다수 조직 동시 침투 및 시스템 장악 | K15: 실제 사고 확인 | L15: 4 | M15: AI 공격 적응(AI Attack Adaptation) | N15: T0116, T0117, T0017.001 | P15: • [ATLAS CS0069·실제사고] GTG-1002가 탈옥한 Claude Code로 약 30개 조직 대상 자율 사이버 첩보(실제 사고) • [ATLAS CS0070·실제사고] DeepSeek 기반 Hermes 에이전트로 Langflow·n8n 취약점 공격 시도(실제 사고) • [ATLAS CS0071·실제사고] Hermes·OpenClaw 기반 다중 에이전트 프레임워크로 대만 정부 시스템 침해(실제 사고) | Q15: AI 속도 공격을 전제한 탐지·대응 자동화, AI 제공자 오남용 탐지 연계, 위협 인텔리전스
A16: D01. 공격 준비 및 AI 무기화 | B16: UT-03 | C16: AI 기반 자율 공격 | D16: UT-03.2 | E16: 다중 에이전트 공격 조율 | F16: 오케스트레이터 AI가 다수 하위 에이전트에 임무를 분배하고 탐색 결과/자격증명을 공유하며 복수 대상을 병렬 공격 | G16: 상 | H16: 상 | I16: =IF(AND(G16="상",H16="상"),"매우 높음",IF(OR(AND(G16="상",H16="중"),AND(G16="중",H16="상")),"높음",IF(OR(AND(G16="중",H16="중"),AND(G16="상",H16="하"),AND(G16="하",H16="상")),"보통","낮음"))) | J16: 복수 대상 병렬 침투 및 시스템 장악 | K16: 실제 사고 확인 | L16: 2 | M16: AI 공격 적응(AI Attack Adaptation) | N16: T0118, T0118.000, T0118.001, T0124 | P16: • [ATLAS CS0068·실제사고] OpenAI 평가용 자율 에이전트들이 평가 경계를 넘어 외부 인프라 구축·Hugging Face 침해(실제 사고) • [ATLAS CS0071·실제사고] Hermes·OpenClaw 기반 다중 에이전트 프레임워크로 대만 정부 시스템 침해(실제 사고) | Q16: AI 속도 공격을 전제한 탐지·대응 자동화, AI 제공자 오남용 탐지 연계, 위협 인텔리전스
... A24: D01. 공격 준비 및 AI 무기화 | B24: UT-05 | C24: AI 서비스를 이용한 C2 통신 | D24: UT-05.3 | E24: AI 아티팩트 저장소 악용 | F24: 모델/데이터셋 저장소를 명령 및 데이터 교환 매체로 사용하여 정상 아티팩트 다운로드로 위장된 C2 수행 | G24: 중 | H24: 중 | I24: =IF(AND(G24="상",H24="상"),"매우 높음",IF(OR(AND(G24="상",H24="중"),AND(G24="중",H24="상")),"높음",IF(OR(AND(G24="중",H24="중"),AND(G24="상",H24="하"),AND(G24="하",H24="상")),"보통","낮음"))) | J24: 탐지 회피형 통신 채널(제한적 대역) | K24: 실제 사고 확인 | L24: 1 | M24: 명령·제어(Command and Control) | N24: T0120 | P24: • [ATLAS CS0068·실제사고] OpenAI 평가용 자율 에이전트들이 평가 경계를 넘어 외부 인프라 구축·Hugging Face 침해(실제 사고) • [OWASP 시나리오] 모델 허브 저장소를 명령·데이터 교환 매체로 사용하는 C2(ATLAS T0120 기법 정의) | Q24: AI API 키 보호·사용량 이상 탐지, AI 서비스 egress 가시성, 비인가 AI 트래픽 차단
A25: D02. 프롬프트 인젝션 및 컨텍스트 노출 | B25: UT-06 | C25: 직접 프롬프트 인젝션 | D25: UT-06.1 | E25: 시스템 지시 무력화 | F25: 사용자 입력창에 '이전 지시 무시' 등 조작 지시를 입력하여 시스템 프롬프트의 역할/제약을 무력화하고 비인가 정보 조회 또는 기능 실행 유도 | G25: 상 | H25: 중 | I25: =IF(AND(G25="상",H25="상"),"매우 높음",IF(OR(AND(G25="상",H25="중"),AND(G25="중",H25="상")),"높음",IF(OR(AND(G25="중",H25="중"),AND(G25="상",H25="하"),AND(G25="하",H25="상")),"보통","낮음"))) | J25: 앱 권한 범위 내 비인가 조회/실행 | K25: 실제 사고 확인 | L25: 3 | M25: 실행(Execution) | N25: T0051, T0051.000 | O25: LLM01 | P25: • [ATLAS CS0043·실제사고] LLM 기반 악성코드 분석기를 속이려 프롬프트 인젝션을 내장한 악성코드(실제 사고) • [ATLAS CS0016·실증] MathGPT에 프롬프트 인젝션으로 파이썬 코드 실행·API 키 노출 • [ATLAS CS0047·실제사고] 과권한 GitHub 토큰으로 Amazon Q VS Code 확장에 파괴형 에이전트 지시 커밋(실제 사고) • [OWASP 인용] CVE-2024-5184 EmailGPT 프롬프트 인젝션(시스템 프롬프트 노출 및 데이터 유출) | Q25: 다층 입·출력 가드레일, 모달리티별 정규화·비가시 문자 제거, 권한 분리로 폭발반경 제한, 적대적 테스트 상시화
A26: D02. 프롬프트 인젝션 및 컨텍스트 노출 | B26: UT-06 | C26: 직접 프롬프트 인젝션 | D26: UT-06.2 | E26: 탈옥(안전장치 우회) | F26: 역할극/다단계 설득/우회 표현을 통해 모델의 안전 정책을 무력화하여 유해 콘텐츠 생성 또는 공격 도구 개발 등 금지된 용도로 모델 악용 | G26: 상 | H26: 중 | I26: =IF(AND(G26="상",H26="상"),"매우 높음",IF(OR(AND(G26="상",H26="중"),AND(G26="중",H26="상")),"높음",IF(OR(AND(G26="중",H26="중"),AND(G26="상",H26="하"),AND(G26="하",H26="상")),"보통","낮음"))) | J26: 금지 용도 악용(유해 콘텐츠·공격 도구 생성) | K26: 실제 사고 확인 | L26: 2 | M26: 방어 회피(Defense Evasion) | N26: T0054 | O26: LLM01 | P26: • [ATLAS CS0057·실제사고] Storm-2139가 노출 자격증명과 탈옥 도구로 Azure OpenAI 가드레일 우회·접근권 재판매(실제 사고) • [ATLAS CS0069·실제사고] GTG-1002가 탈옥한 Claude Code로 약 30개 조직 대상 자율 사이버 첩보(실제 사고) • [ATLAS CS0041·실증] AI 코딩도구 규칙 파일에 보이지 않는 유니코드 지시를 숨겨 악성 코드 생성 유도 • [OWASP 인용] CVE-2025-54794 Claude 프롬프트 인젝션 탈옥 | Q26: 다층 입·출력 가드레일, 모달리티별 정규화·비가시 문자 제거, 권한 분리로 폭발반경 제한, 적대적 테스트 상시화
A27: D02. 프롬프트 인젝션 및 컨텍스트 노출 | B27: UT-06 | C27: 직접 프롬프트 인젝션 | D27: UT-06.3 | E27: 페이로드 난독화 | F27: 다국어 혼용/인코딩/분할 입력/동의어 치환으로 인젝션 페이로드를 변형하여 입력 필터 및 가드레일 탐지 우회 | G27: 상 | H27: 중 | I27: =IF(AND(G27="상",H27="상"),"매우 높음",IF(OR(AND(G27="상",H27="중"),AND(G27="중",H27="상")),"높음",IF(OR(AND(G27="중",H27="중"),AND(G27="상",H27="하"),AND(G27="하",H27="상")),"보통","낮음"))) | J27: 가드레일 무력화로 인젝션 성공률 증가 | K27: 실제 사고 확인 | L27: 4 | M27: 방어 회피(Defense Evasion) | N27: T0065, T0068 | O27: LLM01 | P27: • [ATLAS CS0043·실제사고] LLM 기반 악성코드 분석기를 속이려 프롬프트 인젝션을 내장한 악성코드(실제 사고) • [ATLAS CS0047·실제사고] 과권한 GitHub 토큰으로 Amazon Q VS Code 확장에 파괴형 에이전트 지시 커밋(실제 사고) • [ATLAS CS0056·실제사고] 약 2.4만 계정·1,600만 쿼리로 Claude 능력을 증류하려는 캠페인 적발(실제 사고) | Q27: 다층 입·출력 가드레일, 모달리티별 정규화·비가시 문자 제거, 권한 분리로 폭발반경 제한, 적대적 테스트 상시화
A28: D02. 프롬프트 인젝션 및 컨텍스트 노출 | B28: UT-06 | C28: 직접 프롬프트 인젝션 | D28: UT-06.4 | E28: 멀티모달 은닉 지시 | F28: 이미지/오디오/문서 내 비가시 텍스트 또는 유니코드 태그 문자로 지시를 은닉하여 사람 검토와 텍스트 기반 필터를 동시에 우회 | G28: 중 | H28: 중 | I28: =IF(AND(G28="상",H28="상"),"매우 높음",IF(OR(AND(G28="상",H28="중"),AND(G28="중",H28="상")),"높음",IF(OR(AND(G28="중",H28="중"),AND(G28="상",H28="하"),AND(G28="하",H28="상")),"보통","낮음"))) | J28: 사람 검토 및 필터 동시 우회 | K28: 실증·공개 취약점 | L28: 0 | M28: 방어 회피(Defense Evasion) | N28: T0129 | O28: LLM01 | P28: • [ATLAS CS0041·실증] AI 코딩도구 규칙 파일에 보이지 않는 유니코드 지시를 숨겨 악성 코드 생성 유도 • [OWASP 인용] M365 Copilot ASCII 스머글링 PoC(2024.08, 비가시 유니코드로 MFA 코드 유출) | Q28: 다층 입·출력 가드레일, 모달리티별 정규화·비가시 문자 제거, 권한 분리로 폭발반경 제한, 적대적 테스트 상시화
A29: D02. 프롬프트 인젝션 및 컨텍스트 노출 | B29: UT-07 | C29: 간접 프롬프트 인젝션 | D29: UT-07.1 | E29: 외부 콘텐츠 경유 주입 | F29: 웹페이지/문서/이메일/이슈 등 AI가 처리하는 외부 콘텐츠에 지시문을 은닉하여, 콘텐츠 처리 시점에 사용자 권한으로 데이터 조회/전송 등 비인가 행위 수행 | G29: 중 | H29: 상 | I29: =IF(AND(G29="상",H29="상"),"매우 높음",IF(OR(AND(G29="상",H29="중"),AND(G29="중",H29="상")),"높음",IF(OR(AND(G29="중",H29="중"),AND(G29="상",H29="하"),AND(G29="하",H29="상")),"보통","낮음"))) | J29: 제로클릭 데이터 유출 및 사용자 권한 전체 악용 | K29: 실증·공개 취약점 | L29: 0 | M29: 초기 접근(Initial Access) | N29: T0051.001, T0093 | O29: LLM01, MCP06 | P29: • [ATLAS CS0020·실증] 웹페이지 숨은 지시로 Bing Chat이 사용자 개인정보를 캐내는 사회공학 수행 • [ATLAS CS0021·실증] 웹페이지 간접 인젝션으로 ChatGPT 대화 내용을 이미지 URL로 유출 • [ATLAS CS0029·실증] 공유 Google 문서의 간접 인젝션으로 Bard 대화 내용 유출 • [OWASP 인용] Salesforce Agentforce ForcedLeak(2025.09) / Google Gemini Trifecta(2025.09) / Hub MCP 교차 컨텍스트 인젝션(2025.06) / GitHub 공개 이슈 경유 저장소 탈취(2025.05) | Q29: 비신뢰 콘텐츠 구획·출처 표시, 비신뢰 데이터 처리 중 도구 호출 제한, 목표 변경 시 인간 승인, '치명적 삼요소' 동시 성립 차단
A30: D02. 프롬프트 인젝션 및 컨텍스트 노출 | B30: UT-07 | C30: 간접 프롬프트 인젝션 | D30: UT-07.2 | E30: 지연 실행형 주입 | F30: 특정 키워드/후속 대화 턴/시점에 발동하도록 조건부 지시를 심어 즉시 탐지를 회피하고 도구 호출 제한 등 보호 장치 우회 | G30: 중 | H30: 중 | I30: =IF(AND(G30="상",H30="상"),"매우 높음",IF(OR(AND(G30="상",H30="중"),AND(G30="중",H30="상")),"높음",IF(OR(AND(G30="중",H30="중"),AND(G30="상",H30="하"),AND(G30="하",H30="상")),"보통","낮음"))) | J30: 즉시 탐지 회피 후 보호장치 우회 실행 | K30: 실증·공개 취약점 | L30: 0 | M30: 방어 회피(Defense Evasion) | N30: T0051.002, T0094 | O30: LLM01 | P30: • [ATLAS CS0024·실증] RAG를 매개로 자기복제 프롬프트가 GenAI 이메일 비서 간 전파(Morris II 웜) • [ATLAS CS0037·실증] Copilot Studio 고객지원 에이전트를 인젝션해 지식원·도구를 탐색하고 CRM 데이터 유출 • [ATLAS CS0038·실증] 지시 실행을 다음 대화 턴으로 지연시켜 Gemini의 도구 호출 제한 우회 | Q30: 비신뢰 콘텐츠 구획·출처 표시, 비신뢰 데이터 처리 중 도구 호출 제한, 목표 변경 시 인간 승인, '치명적 삼요소' 동시 성립 차단
A31: D02. 프롬프트 인젝션 및 컨텍스트 노출 | B31: UT-07 | C31: 간접 프롬프트 인젝션 | D31: UT-07.3 | E31: 검색 노출용 콘텐츠 제작 | F31: RAG 수집 대상 사이트/문서를 파악한 후 검색 상위에 노출되도록 설계한 악성 콘텐츠를 외부에 게시하여 AI가 이를 근거로 응답하도록 유도 | G31: 중 | H31: 중 | I31: =IF(AND(G31="상",H31="상"),"매우 높음",IF(OR(AND(G31="상",H31="중"),AND(G31="중",H31="상")),"높음",IF(OR(AND(G31="중",H31="중"),AND(G31="상",H31="하"),AND(G31="하",H31="상")),"보통","낮음"))) | J31: 특정 질의 응답 조작(범위 제한) | K31: 실증·공개 취약점 | L31: 0 | M31: 자원 개발(Resource Development) | N31: T0064, T0066 | O31: LLM01 | P31: • [ATLAS CS0026·실증] 메일을 RAG로 수집하는 M365 Copilot을 조작해 송금 계좌 정보를 바꿔치기 • [ATLAS CS0035·실증] 공개 채널 게시글의 간접 인젝션으로 Slack AI가 비공개 채널 데이터 유출 • [ATLAS CS0059·실증] EchoLeak: 메일 한 통으로 M365 Copilot이 사용자 조작 없이 기업 데이터 유출(제로클릭) | Q31: 비신뢰 콘텐츠 구획·출처 표시, 비신뢰 데이터 처리 중 도구 호출 제한, 목표 변경 시 인간 승인, '치명적 삼요소' 동시 성립 차단
A32: D02. 프롬프트 인젝션 및 컨텍스트 노출 | B32: UT-07 | C32: 간접 프롬프트 인젝션 | D32: UT-07.4 | E32: 에이전트 유인 및 클로킹 | F32: 조작된 AI 비서 링크/클릭 유도 화면으로 에이전트 행동을 유인하거나, AI 크롤러에만 다른 콘텐츠를 제공(클로킹)하여 사람 검토를 회피한 지시 전달 | G32: 중 | H32: 중 | I32: =IF(AND(G32="상",H32="상"),"매우 높음",IF(OR(AND(G32="상",H32="중"),AND(G32="중",H32="상")),"높음",IF(OR(AND(G32="중",H32="중"),AND(G32="상",H32="하"),AND(G32="하",H32="상")),"보통","낮음"))) | J32: 에이전트 행위 유도(사용자 권한 범위) | K32: 실제 사고 확인 | L32: 1 | M32: 초기 접근(Initial Access) | N32: T0131, T0100, T0134 | O32: LLM01 | P32: • [ATLAS CS0072·실제사고] 조작된 AI 비서 링크로 메모리를 오염시켜 특정 제품을 추천하게 만드는 홍보성 공격(실제 사고) • [ATLAS CS0055·실증] ClickFix 사회공학으로 컴퓨터 사용 에이전트가 악성 명령 실행 | Q32: 비신뢰 콘텐츠 구획·출처 표시, 비신뢰 데이터 처리 중 도구 호출 제한, 목표 변경 시 인간 승인, '치명적 삼요소' 동시 성립 차단
A33: D02. 프롬프트 인젝션 및 컨텍스트 노출 | B33: UT-07 | C33: 간접 프롬프트 인젝션 | D33: UT-07.5 | E33: 에이전트 목표 탈취 | F33: 주입된 지시가 에이전트의 목표/계획/판단 기준을 점진적으로 변경하여, 정상 업무 흐름 속에서 공격자 의도에 맞는 의사결정과 행위 반복 | G33: 중 | H33: 상 | I33: =IF(AND(G33="상",H33="상"),"매우 높음",IF(OR(AND(G33="상",H33="중"),AND(G33="중",H33="상")),"높음",IF(OR(AND(G33="중",H33="중"),AND(G33="상",H33="하"),AND(G33="하",H33="상")),"보통","낮음"))) | J33: 에이전트 권한 전체를 공격자 목적에 사용 | K33: 실증·공개 취약점 | L33: 0 | M33: 실행(Execution) | O33: ASI01 | P33: • [ATLAS CS0063·실증] 캘린더 초대·메일에 숨긴 지시로 Gemini 비서가 기기·앱을 조작 • [OWASP 인용] ChatGPT Operator 프롬프트 인젝션(2025.02) / VS Code 에이전트 워크플로 RCE(2025.09) • [OWASP 시나리오] 반복 캘린더 초대로 플래너 에이전트의 목표 가중치를 매일 조금씩 변경(ASI01 시나리오#3) | Q33: 비신뢰 콘텐츠 구획·출처 표시, 비신뢰 데이터 처리 중 도구 호출 제한, 목표 변경 시 인간 승인, '치명적 삼요소' 동시 성립 차단
A34: D02. 프롬프트 인젝션 및 컨텍스트 노출 | B34: UT-08 | C34: 숨겨진 컨텍스트 노출 | D34: UT-08.1 | E34: 시스템 프롬프트 추출 | F34: 반복 질의/역할 전환/출력 형식 변환 요청을 통해 시스템 지시문과 내부 규칙을 추출하여 가드레일 우회 및 후속 인젝션 설계에 활용 | G34: 중 | H34: 하 | I34: =IF(AND(G34="상",H34="상"),"매우 높음",IF(OR(AND(G34="상",H34="중"),AND(G34="중",H34="상")),"높음",IF(OR(AND(G34="중",H34="중"),AND(G34="상",H34="하"),AND(G34="하",H34="상")),"보통","낮음"))) | J34: 정책 정보 노출(직접 피해 제한적) | K34: 실증·공개 취약점 | L34: 0 | M34: 탐색(Discovery) | N34: T0056, T0069, T0069.000, T0069.001, T0069.002 | O34: LLM08 | P34: • [ATLAS CS0026·실증] 메일을 RAG로 수집하는 M365 Copilot을 조작해 송금 계좌 정보를 바꿔치기 • [ATLAS CS0048·실증] 인터넷에 노출된 ClawdBot 제어 인터페이스 수백 개에서 자격증명 탈취·명령 실행 • [ATLAS CS0051·실증] 웹페이지 인젝션으로 OpenClaw에 지속 지시를 심어 C2로 활용 • [OWASP 인용] CVE-2024-5184 EmailGPT 시스템 프롬프트 노출 | Q34: 은닉 컨텍스트 노출 가정 설계, 비밀·보안 로직을 프롬프트에 두지 않음, 권한은 외부 정책엔진에서 강제
A35: D02. 프롬프트 인젝션 및 컨텍스트 노출 | B35: UT-08 | C35: 숨겨진 컨텍스트 노출 | D35: UT-08.2 | E35: 에이전트 구성 탐색 | F35: 에이전트에 질의하여 연결 도구 목록/호출 체인/활성화 트리거/지식원 구성을 파악함으로써 악용 가능한 도구와 데이터 경로 식별 | G35: 중 | H35: 중 | I35: =IF(AND(G35="상",H35="상"),"매우 높음",IF(OR(AND(G35="상",H35="중"),AND(G35="중",H35="상")),"높음",IF(OR(AND(G35="중",H35="중"),AND(G35="상",H35="하"),AND(G35="하",H35="상")),"보통","낮음"))) | J35: 도구 악용 경로 정밀화 | K35: 실증·공개 취약점 | L35: 0 | M35: 탐색(Discovery) | N35: T0084, T0084.000, T0084.001, T0084.002, T0084.003 | O35: LLM08 | P35: • [ATLAS CS0037·실증] Copilot Studio 고객지원 에이전트를 인젝션해 지식원·도구를 탐색하고 CRM 데이터 유출 • [ATLAS CS0052·실증] 11개 LLM 프레임워크에서 20개 RCE 취약점 발견, 인터넷 공개 앱에서 실증(LLMSmith) • [ATLAS CS0063·실증] 캘린더 초대·메일에 숨긴 지시로 Gemini 비서가 기기·앱을 조작 | Q35: 은닉 컨텍스트 노출 가정 설계, 비밀·보안 로직을 프롬프트에 두지 않음, 권한은 외부 정책엔진에서 강제
A36: D02. 프롬프트 인젝션 및 컨텍스트 노출 | B36: UT-08 | C36: 숨겨진 컨텍스트 노출 | D36: UT-08.3 | E36: 런타임 권한 탐색 | F36: 에이전트의 실행 권한/접근 가능 자원/런타임 기능을 탐색하여 권한 상승 및 도구 오용 대상 선별 | G36: 하 | H36: 중 | I36: =IF(AND(G36="상",H36="상"),"매우 높음",IF(OR(AND(G36="상",H36="중"),AND(G36="중",H36="상")),"높음",IF(OR(AND(G36="중",H36="중"),AND(G36="상",H36="하"),AND(G36="하",H36="상")),"보통","낮음"))) | J36: 권한 상승 및 도구 오용 대상 선별 | K36: 이론·시나리오 | L36: 0 | M36: 탐색(Discovery) | N36: T0133 | O36: LLM08 | P36: • [OWASP 시나리오] 에이전트 런타임 기능·권한 탐색(ATLAS T0133, 2026.09 신설 기법 정의) | Q36: 은닉 컨텍스트 노출 가정 설계, 비밀·보안 로직을 프롬프트에 두지 않음, 권한은 외부 정책엔진에서 강제
A37: D02. 프롬프트 인젝션 및 컨텍스트 노출 | B37: UT-08 | C37: 숨겨진 컨텍스트 노출 | D37: UT-08.4 | E37: 프롬프트 내 비밀정보 노출 | F37: 시스템 프롬프트/에이전트 설정에 API 키/접속 정보/내부 URL을 직접 기재하여, 컨텍스트 추출 시 연동 시스템 자격증명이 함께 노출 | G37: 하 | H37: 상 | I37: =IF(AND(G37="상",H37="상"),"매우 높음",IF(OR(AND(G37="상",H37="중"),AND(G37="중",H37="상")),"높음",IF(OR(AND(G37="중",H37="중"),AND(G37="상",H37="하"),AND(G37="하",H37="상")),"보통","낮음"))) | J37: 연동 시스템 자격증명 노출로 다수 시스템 접근 | K37: 이론·시나리오 | L37: 0 | M37: 자격증명 접근(Credential Access) | O37: LLM08 | P37: • [OWASP 시나리오] 시스템 프롬프트에 포함된 자격증명이 추출되어 연동 시스템 접근(LLM08 시나리오#1) | Q37: 은닉 컨텍스트 노출 가정 설계, 비밀·보안 로직을 프롬프트에 두지 않음, 권한은 외부 정책엔진에서 강제
A38: D03. AI 데이터 오염 및 유출 | B38: UT-09 | C38: 학습 데이터 오염 | D38: UT-09.1 | E38: 학습 데이터 직접 오염 | F38: 사전학습/파인튜닝 데이터에 소량의 오염 샘플 또는 트리거 패턴을 삽입하여 모델에 편향, 성능 저하, 조건부 오작동(백도어)을 내재화 | G38: 상 | H38: 중 | I38: =IF(AND(G38="상",H38="상"),"매우 높음",IF(OR(AND(G38="상",H38="중"),AND(G38="중",H38="상")),"높음",IF(OR(AND(G38="중",H38="중"),AND(G38="상",H38="하"),AND(G38="하",H38="상")),"보통","낮음"))) | J38: 모델 전반 무결성 훼손(통제권 탈취와 간접 연계) | K38: 실제 사고 확인 | L38: 2 | M38: 지속성(Persistence) | N38: T0020 | O38: LLM05, DSGAI04 | P38: • [ATLAS CS0002·실제사고] VirusTotal에 변종 샘플을 대량 제출해 크라우드소싱 학습 데이터를 오염 • [ATLAS CS0009·실제사고] Tay 챗봇이 사용자 대화로 온라인 학습되며 오염되어 혐오 발언 생성(실제 사고) • [ATLAS CS0025·실증] URL 목록형 대규모 데이터셋의 만료 도메인을 매입해 학습 데이터 오염(Split-View) | Q38: 데이터셋 출처·계보 관리(DBOM/ML-BOM), 학습데이터 정제·이상치 탐지, 재학습 입력 검증
A39: D03. AI 데이터 오염 및 유출 | B39: UT-09 | C39: 학습 데이터 오염 | D39: UT-09.2 | E39: 오염 데이터셋 유포 | F39: 오염된 데이터셋을 공개 저장소에 배포하거나 정상 데이터셋으로 위장하여, 이를 수집한 다수 조직의 학습 파이프라인을 동시 오염 | G39: 중 | H39: 중 | I39: =IF(AND(G39="상",H39="상"),"매우 높음",IF(OR(AND(G39="상",H39="중"),AND(G39="중",H39="상")),"높음",IF(OR(AND(G39="중",H39="중"),AND(G39="상",H39="하"),AND(G39="하",H39="상")),"보통","낮음"))) | J39: 다수 조직 모델의 무결성 동시 훼손 | K39: 실증·공개 취약점 | L39: 0 | M39: 자원 개발(Resource Development) | N39: T0115.000 | O39: LLM05, DSGAI04 | P39: • [ATLAS CS0025·실증] URL 목록형 대규모 데이터셋의 만료 도메인을 매입해 학습 데이터 오염(Split-View) | Q39: 데이터셋 출처·계보 관리(DBOM/ML-BOM), 학습데이터 정제·이상치 탐지, 재학습 입력 검증
A40: D03. AI 데이터 오염 및 유출 | B40: UT-09 | C40: 학습 데이터 오염 | D40: UT-09.3 | E40: 재학습 피드백 오염 | F40: 사용자 피드백/운영 로그를 자동 재학습에 반영하는 구조를 악용하여 조작 입력을 반복 주입함으로써 모델 행동을 점진적으로 왜곡 | G40: 중 | H40: 중 | I40: =IF(AND(G40="상",H40="상"),"매우 높음",IF(OR(AND(G40="상",H40="중"),AND(G40="중",H40="상")),"높음",IF(OR(AND(G40="중",H40="중"),AND(G40="상",H40="하"),AND(G40="하",H40="상")),"보통","낮음"))) | J40: 점진적 왜곡(탐지 시 롤백 가능) | K40: 실제 사고 확인 | L40: 1 | M40: 지속성(Persistence) | O40: LLM05 | P40: • [ATLAS CS0009·실제사고] Tay 챗봇이 사용자 대화로 온라인 학습되며 오염되어 혐오 발언 생성(실제 사고) • [OWASP 시나리오] 자동 재학습 피드백 루프를 악용한 모델 왜곡(LLM05 시나리오#3) | Q40: 데이터셋 출처·계보 관리(DBOM/ML-BOM), 학습데이터 정제·이상치 탐지, 재학습 입력 검증
A41: D03. AI 데이터 오염 및 유출 | B41: UT-09 | C41: 학습 데이터 오염 | D41: UT-09.4 | E41: 무결성 저하 공격 | F41: 적대적 입력 반복 투입 또는 데이터셋 일부 훼손을 통해 모델/데이터셋의 신뢰도를 저하시켜 운영 중단 또는 재학습 비용 유발 | G41: 상 | H41: 중 | I41: =IF(AND(G41="상",H41="상"),"매우 높음",IF(OR(AND(G41="상",H41="중"),AND(G41="중",H41="상")),"높음",IF(OR(AND(G41="중",H41="중"),AND(G41="상",H41="하"),AND(G41="하",H41="상")),"보통","낮음"))) | J41: 모델 신뢰도 저하 및 재학습 비용 | K41: 실제 사고 확인 | L41: 2 | M41: 영향(Impact) | N41: T0059, T0031 | O41: DSGAI04 | P41: • [ATLAS CS0025·실증] URL 목록형 대규모 데이터셋의 만료 도메인을 매입해 학습 데이터 오염(Split-View) • [ATLAS CS0006·실제사고] Clearview AI 저장소 설정 오류로 소스코드·자격증명·모델 노출 • [ATLAS CS0009·실제사고] Tay 챗봇이 사용자 대화로 온라인 학습되며 오염되어 혐오 발언 생성(실제 사고) | Q41: 데이터셋 출처·계보 관리(DBOM/ML-BOM), 학습데이터 정제·이상치 탐지, 재학습 입력 검증
A42: D03. AI 데이터 오염 및 유출 | B42: UT-10 | C42: 지식원(RAG) 오염 | D42: UT-10.1 | E42: 검색 코퍼스 오염 | F42: 조직 지식원/RAG 코퍼스에 허위 또는 조작 문서를 기록하여, AI가 이를 권위 있는 근거로 인용한 잘못된 응답/권고 생성 | G42: 중 | H42: 중 | I42: =IF(AND(G42="상",H42="상"),"매우 높음",IF(OR(AND(G42="상",H42="중"),AND(G42="중",H42="상")),"높음",IF(OR(AND(G42="중",H42="중"),AND(G42="상",H42="하"),AND(G42="하",H42="상")),"보통","낮음"))) | J42: 응답 무결성 훼손(업무 판단 및 거래 오류) | K42: 실증·공개 취약점 | L42: 0 | M42: 지속성(Persistence) | N42: T0070, T0071 | O42: ASI06, DSGAI21 | P42: • [ATLAS CS0026·실증] 메일을 RAG로 수집하는 M365 Copilot을 조작해 송금 계좌 정보를 바꿔치기 • [ATLAS CS0024·실증] RAG를 매개로 자기복제 프롬프트가 GenAI 이메일 비서 간 전파(Morris II 웜) • [ATLAS CS0035·실증] 공개 채널 게시글의 간접 인젝션으로 Slack AI가 비공개 채널 데이터 유출 | Q42: 수집원 신뢰등급·서명, 색인 전 검증, 검색 결과 출처 표시, 임베딩 모델 자체 검증
A43: D03. AI 데이터 오염 및 유출 | B43: UT-10 | C43: 지식원(RAG) 오염 | D43: UT-10.2 | E43: 에이전트 조회 데이터 오염 | F43: 에이전트 도구가 조회하는 DB/문서 저장소/검색 색인에 악성 지시나 허위 데이터를 기록하여, 도구 호출 결과를 통해 에이전트 행위 조작 | G43: 하 | H43: 상 | I43: =IF(AND(G43="상",H43="상"),"매우 높음",IF(OR(AND(G43="상",H43="중"),AND(G43="중",H43="상")),"높음",IF(OR(AND(G43="중",H43="중"),AND(G43="상",H43="하"),AND(G43="하",H43="상")),"보통","낮음"))) | J43: 도구 결과 신뢰를 통한 에이전트 행위 조작 | K43: 이론·시나리오 | L43: 0 | M43: 지속성(Persistence) | N43: T0099 | O43: ASI06 | P43: — (근거 사례 없음: OWASP 위험 정의 기반) | Q43: 수집원 신뢰등급·서명, 색인 전 검증, 검색 결과 출처 표시, 임베딩 모델 자체 검증
A44: D03. AI 데이터 오염 및 유출 | B44: UT-10 | C44: 지식원(RAG) 오염 | D44: UT-10.3 | E44: 임베딩 공간 조작 | F44: 임베딩 유사도를 노린 문서 조작 또는 시맨틱 캐시 오염을 통해 검색 순위를 장악하여 특정 질의에 공격자 콘텐츠가 우선 반환되도록 유도 | G44: 하 | H44: 중 | I44: =IF(AND(G44="상",H44="상"),"매우 높음",IF(OR(AND(G44="상",H44="중"),AND(G44="중",H44="상")),"높음",IF(OR(AND(G44="중",H44="중"),AND(G44="상",H44="하"),AND(G44="하",H44="상")),"보통","낮음"))) | J44: 특정 질의 검색 결과 장악 | K44: 이론·시나리오 | L44: 0 | M44: 지속성(Persistence) | O44: LLM09 | P44: • [OWASP 시나리오] 임베딩 유사도를 노린 공개 수집 파이프라인 공격(LLM09 시나리오#1) | Q44: 수집원 신뢰등급·서명, 색인 전 검증, 검색 결과 출처 표시, 임베딩 모델 자체 검증
A45: D03. AI 데이터 오염 및 유출 | B45: UT-11 | C45: 에이전트 메모리 오염 | D45: UT-11.1 | E45: 장기 메모리 오염 | F45: 공유 문서/웹 콘텐츠의 인젝션을 통해 에이전트 장기 메모리에 허위 사실이나 지속 지시를 기록하여, 이후 모든 세션에서 오염된 기억 기반으로 응답/행위 | G45: 중 | H45: 상 | I45: =IF(AND(G45="상",H45="상"),"매우 높음",IF(OR(AND(G45="상",H45="중"),AND(G45="중",H45="상")),"높음",IF(OR(AND(G45="중",H45="중"),AND(G45="상",H45="하"),AND(G45="하",H45="상")),"보통","낮음"))) | J45: 세션 간 지속되는 행위 장악(C2 연계 사례) | K45: 실제 사고 확인 | L45: 1 | M45: 지속성(Persistence) | N45: T0080, T0080.000 | O45: ASI06 | P45: • [ATLAS CS0072·실제사고] 조작된 AI 비서 링크로 메모리를 오염시켜 특정 제품을 추천하게 만드는 홍보성 공격(실제 사고) • [ATLAS CS0040·실증] 공유 문서의 인젝션으로 ChatGPT 장기 메모리에 허위 정보를 영구 기록 • [ATLAS CS0036·실증] LLM 데스크톱 앱 메모리에서 인증 토큰을 추출해 사용자 가장(AIKatz) | Q45: 메모리 쓰기 검증·출처 점수, 사용자·작업별 메모리 분리, 스냅샷·롤백, 에이전트 출력의 자동 재수집 금지
A46: D03. AI 데이터 오염 및 유출 | B46: UT-11 | C46: 에이전트 메모리 오염 | D46: UT-11.2 | E46: 대화 스레드 오염 | F46: 진행 중인 대화 스레드에 조작 지시를 삽입하여 동일 세션 내 후속 응답과 도구 호출을 지속적으로 왜곡 | G46: 중 | H46: 중 | I46: =IF(AND(G46="상",H46="상"),"매우 높음",IF(OR(AND(G46="상",H46="중"),AND(G46="중",H46="상")),"높음",IF(OR(AND(G46="중",H46="중"),AND(G46="상",H46="하"),AND(G46="하",H46="상")),"보통","낮음"))) | J46: 단일 대화 범위 왜곡 | K46: 실증·공개 취약점 | L46: 0 | M46: 지속성(Persistence) | N46: T0080.001 | O46: ASI06 | P46: • [ATLAS CS0036·실증] LLM 데스크톱 앱 메모리에서 인증 토큰을 추출해 사용자 가장(AIKatz) • [ATLAS CS0051·실증] 웹페이지 인젝션으로 OpenClaw에 지속 지시를 심어 C2로 활용 • [ATLAS CS0063·실증] 캘린더 초대·메일에 숨긴 지시로 Gemini 비서가 기기·앱을 조작 | Q46: 메모리 쓰기 검증·출처 점수, 사용자·작업별 메모리 분리, 스냅샷·롤백, 에이전트 출력의 자동 재수집 금지
A47: D03. AI 데이터 오염 및 유출 | B47: UT-11 | C47: 에이전트 메모리 오염 | D47: UT-11.3 | E47: 대화 이력 조작 | F47: 대화 이력을 변조/삭제하여 공격 흔적을 은폐하거나 과거 맥락을 위조함으로써 사용자 및 모니터링의 이상 인지 방해 | G47: 중 | H47: 중 | I47: =IF(AND(G47="상",H47="상"),"매우 높음",IF(OR(AND(G47="상",H47="중"),AND(G47="중",H47="상")),"높음",IF(OR(AND(G47="중",H47="중"),AND(G47="상",H47="하"),AND(G47="하",H47="상")),"보통","낮음"))) | J47: 공격 흔적 은폐 및 이상 인지 방해 | K47: 실증·공개 취약점 | L47: 0 | M47: 방어 회피(Defense Evasion) | N47: T0092 | O47: ASI06 | P47: • [ATLAS CS0036·실증] LLM 데스크톱 앱 메모리에서 인증 토큰을 추출해 사용자 가장(AIKatz) • [ATLAS CS0048·실증] 인터넷에 노출된 ClawdBot 제어 인터페이스 수백 개에서 자격증명 탈취·명령 실행 | Q47: 메모리 쓰기 검증·출처 점수, 사용자·작업별 메모리 분리, 스냅샷·롤백, 에이전트 출력의 자동 재수집 금지
...

Sheet 도메인·평가기준
A1: 분류 체계 정의와 위험 평가 기준
A3: 1. 3단 분류 체계
A4: 단계 | B4: 정의 | C4: 작성 규칙 | D4: 개수
A5: Lv1 도메인 | B5: 영역별 보안 리스크(공격 흐름상 위협 행위자 영역을 D01로 배치) | C5: OWASP 위협·리스크 명명 규칙 준용: [영역] + [위협 명사], 대등한 두 위협만 '및'으로 결합 / 경계 판정 규칙은 아래 2번 표 | D5: =SUMPRODUCT(1/COUNTIF(통합매트릭스!$A$5:$A$131,통합매트릭스!$A$5:$A$131))
A6: Lv2 위협 분류 | B6: 기존 통합 위협(UT). ID·도메인·크로스워크 체계 불변 | C6: '·' 나열 없이 하나의 개념으로 명명 | D6: =SUMPRODUCT(1/COUNTIF(통합매트릭스!$B$5:$B$131,통합매트릭스!$B$5:$B$131))
A7: Lv3 세부 위협 | B7: Lv2 안에서 공격 경로 또는 발생 원리가 독립된 위협 | C7: ① 독립 메커니즘 ② 근거 1개 이상(ATLAS 기법·OWASP 예시·사례) ③ 공격 단계·생애주기·통제 중 하나 이상 구별 / 설명은 '수단→행위→결과' 명사형 종결 | D7: =COUNTA(통합매트릭스!$D$5:$D$131)
A9: 2. Lv1 도메인 정의
A10: 도메인 | B10: 영문명 | C10: 리스크 정의 | D10: 주요 대상 영역 | E10: 경계 판정 규칙 | F10: Lv2 수 | G10: Lv3 수 | H10: 위험도 '매우 높음'·'높음' Lv3
A11: D01. 공격 준비 및 AI 무기화 | B11: Attack Preparation & AI Weaponization | C11: 위협 행위자가 AI 자산을 정찰하고 공격 역량을 확보하거나, AI를 공격 수단으로 활용하여 자율 공격, 기만, 은닉 통신을 수행하는 리스크 | D11: 공개 정보, 공격 도구와 인프라, 공격자 AI 에이전트, 딥페이크, 제3자 AI 서비스 | E11: 위협 행위자 소유 자산 또는 조직 외부 활동이면 D01. 조직 자산이 직접 훼손되면 해당 영역 도메인으로 분류 | F11: =SUMPRODUCT((통합매트릭스!$A$5:$A$131=A11)/COUNTIFS(통합매트릭스!$A$5:$A$131,통합매트릭스!$A$5:$A$131,통합매트릭스!$B$5:$B$131,통합매트릭스!$B$5:$B$131)) | G11: =COUNTIF(통합매트릭스!$A$5:$A$131,A11) | H11: =COUNTIFS(통합매트릭스!$A$5:$A$131,A11,통합매트릭스!$I$5:$I$131,"매우 높음")+COUNTIFS(통합매트릭스!$A$5:$A$131,A11,통합매트릭스!$I$5:$I$131,"높음")
A12: D02. 프롬프트 인젝션 및 컨텍스트 노출 | B12: Prompt Injection & Context Exposure | C12: 사용자 입력이나 외부 콘텐츠에 삽입된 조작 지시로 모델 동작이 탈취되거나, 시스템 프롬프트 등 비공개 컨텍스트가 노출되는 리스크 | D12: 사용자 입력, 외부 콘텐츠와 도구 응답(지시 전달 경로), 시스템 프롬프트, 에이전트 구성 정보 | E12: 지시가 모델에 도달하는 경로가 핵심이면 D02. 지시가 저장소에 지속 기록되면 D03 | F12: =SUMPRODUCT((통합매트릭스!$A$5:$A$131=A12)/COUNTIFS(통합매트릭스!$A$5:$A$131,통합매트릭스!$A$5:$A$131,통합매트릭스!$B$5:$B$131,통합매트릭스!$B$5:$B$131)) | G12: =COUNTIF(통합매트릭스!$A$5:$A$131,A12) | H12: =COUNTIFS(통합매트릭스!$A$5:$A$131,A12,통합매트릭스!$I$5:$I$131,"매우 높음")+COUNTIFS(통합매트릭스!$A$5:$A$131,A12,통합매트릭스!$I$5:$I$131,"높음")
A13: D03. AI 데이터 오염 및 유출 | B13: AI Data Poisoning & Leakage | C13: 학습 데이터, RAG 지식원, 에이전트 메모리가 오염되거나, 민감정보가 응답과 입력 경로 또는 사용자 간 격리 결함을 통해 유출되는 리스크 | D13: 학습 및 파인튜닝 데이터, RAG 코퍼스와 임베딩, 벡터 DB, 에이전트 메모리와 대화 이력 | E13: 데이터가 저장되거나 색인되는 지점의 리스크면 D03. 모델 가중치 자체의 변조는 D04 | F13: =SUMPRODUCT((통합매트릭스!$A$5:$A$131=A13)/COUNTIFS(통합매트릭스!$A$5:$A$131,통합매트릭스!$A$5:$A$131,통합매트릭스!$B$5:$B$131,통합매트릭스!$B$5:$B$131)) | G13: =COUNTIF(통합매트릭스!$A$5:$A$131,A13) | H13: =COUNTIFS(통합매트릭스!$A$5:$A$131,A13,통합매트릭스!$I$5:$I$131,"매우 높음")+COUNTIFS(통합매트릭스!$A$5:$A$131,A13,통합매트릭스!$I$5:$I$131,"높음")
A14: D04. 모델 조작 및 탈취 | B14: Model Manipulation & Theft | C14: 모델 가중치와 구조가 변조되거나 적대적 입력에 의해 판단이 조작되고, 모델 자산 또는 학습 데이터가 질의와 파일 탈취로 유출되는 리스크 | D14: 모델 가중치와 아키텍처, 추론 템플릿, 추론 API, 예측 모델 | E14: 모델 파일, 가중치, 추론 동작이 공격 대상이면 D04 | F14: =SUMPRODUCT((통합매트릭스!$A$5:$A$131=A14)/COUNTIFS(통합매트릭스!$A$5:$A$131,통합매트릭스!$A$5:$A$131,통합매트릭스!$B$5:$B$131,통합매트릭스!$B$5:$B$131)) | G14: =COUNTIF(통합매트릭스!$A$5:$A$131,A14) | H14: =COUNTIFS(통합매트릭스!$A$5:$A$131,A14,통합매트릭스!$I$5:$I$131,"매우 높음")+COUNTIFS(통합매트릭스!$A$5:$A$131,A14,통합매트릭스!$I$5:$I$131,"높음")
A15: D05. 출력 처리 결함 및 신뢰성 훼손 | B15: Output Handling Flaws & Integrity Loss | C15: 모델 출력이 검증 없이 후속 시스템에서 해석되거나 반출 경로로 악용되고, 허위 또는 편향된 출력이 업무 판단에 채택되는 리스크 | D15: 출력 렌더링 환경(브라우저, 터미널, IDE), 출력 기반 DB 질의, 출력 채널 | E15: 출력의 검증, 신뢰성, 반출 채널 문제면 D05. 출력이 도구 호출이나 코드 실행으로 이어지면 D06 | F15: =SUMPRODUCT((통합매트릭스!$A$5:$A$131=A15)/COUNTIFS(통합매트릭스!$A$5:$A$131,통합매트릭스!$A$5:$A$131,통합매트릭스!$B$5:$B$131,통합매트릭스!$B$5:$B$131)) | G15: =COUNTIF(통합매트릭스!$A$5:$A$131,A15) | H15: =COUNTIFS(통합매트릭스!$A$5:$A$131,A15,통합매트릭스!$I$5:$I$131,"매우 높음")+COUNTIFS(통합매트릭스!$A$5:$A$131,A15,통합매트릭스!$I$5:$I$131,"높음")
A16: D06. 에이전트 오남용 및 통제 상실 | B16: Agent Misuse & Loss of Control | C16: 과도한 권한을 가진 에이전트가 도구와 코드를 위험하게 실행하거나, 다중 에이전트 간 오류 전파와 이상 행동으로 조직의 통제를 상실하는 리스크 | D16: 에이전트 도구 권한, 계획 및 실행 루프, 코드 실행 환경, 다중 에이전트 워크플로 | E16: 에이전트가 무엇을 잘못 실행하는가의 문제면 D06. 누구의 신원과 권한이 악용되는가의 문제면 D07 | F16: =SUMPRODUCT((통합매트릭스!$A$5:$A$131=A16)/COUNTIFS(통합매트릭스!$A$5:$A$131,통합매트릭스!$A$5:$A$131,통합매트릭스!$B$5:$B$131,통합매트릭스!$B$5:$B$131)) | G16: =COUNTIF(통합매트릭스!$A$5:$A$131,A16) | H16: =COUNTIFS(통합매트릭스!$A$5:$A$131,A16,통합매트릭스!$I$5:$I$131,"매우 높음")+COUNTIFS(통합매트릭스!$A$5:$A$131,A16,통합매트릭스!$I$5:$I$131,"높음")
A17: D07. AI 신원 및 권한 악용 | B17: AI Identity & Privilege Abuse | C17: 에이전트와 비인간 계정의 자격증명이 탈취되거나, 권한 위임 결함과 에이전트 간 통신 위조로 권한이 악용되는 리스크 | D17: API 키와 토큰, OAuth 위임, 에이전트 신원, 에이전트 간(A2A, MCP) 메시지 | E17: 누구의 신원과 권한으로 행위가 이루어지는가의 문제면 D07 | F17: =SUMPRODUCT((통합매트릭스!$A$5:$A$131=A17)/COUNTIFS(통합매트릭스!$A$5:$A$131,통합매트릭스!$A$5:$A$131,통합매트릭스!$B$5:$B$131,통합매트릭스!$B$5:$B$131)) | G17: =COUNTIF(통합매트릭스!$A$5:$A$131,A17) | H17: =COUNTIFS(통합매트릭스!$A$5:$A$131,A17,통합매트릭스!$I$5:$I$131,"매우 높음")+COUNTIFS(통합매트릭스!$A$5:$A$131,A17,통합매트릭스!$I$5:$I$131,"높음")
A18: D08. AI 공급망 침해 | B18: AI Supply Chain Compromise | C18: 외부에서 도입하는 모델, 데이터셋, 패키지, 에이전트 도구가 오염되거나 위장되어 조직 환경에 악성 요소가 유입되는 리스크 | D18: 모델 허브, 패키지 레지스트리, MCP 서버, 플러그인 및 스킬 레지스트리 | E18: 제3자 구성요소가 유입 경로면 D08. 조직 내부 데이터 소스의 오염은 D03 | F18: =SUMPRODUCT((통합매트릭스!$A$5:$A$131=A18)/COUNTIFS(통합매트릭스!$A$5:$A$131,통합매트릭스!$A$5:$A$131,통합매트릭스!$B$5:$B$131,통합매트릭스!$B$5:$B$131)) | G18: =COUNTIF(통합매트릭스!$A$5:$A$131,A18) | H18: =COUNTIFS(통합매트릭스!$A$5:$A$131,A18,통합매트릭스!$I$5:$I$131,"매우 높음")+COUNTIFS(통합매트릭스!$A$5:$A$131,A18,통합매트릭스!$I$5:$I$131,"높음")
A19: D09. AI 인프라 노출 및 자원 고갈 | B19: AI Infrastructure Exposure & Resource Exhaustion | C19: AI 서비스와 인프라가 통제 밖에서 외부에 노출되거나 운영 데이터 경로로 정보가 새어 나가고, 자원 고갈로 가용성과 비용 피해가 발생하는 리스크 | D19: 서빙 인프라, 외부 노출 서비스, 사용자 단말의 AI 어시스턴트, 관측성 도구와 라벨링 경로 | E19: 인프라 구성과 운영 방식이 원인이면 D09 | F19: =SUMPRODUCT((통합매트릭스!$A$5:$A$131=A19)/COUNTIFS(통합매트릭스!$A$5:$A$131,통합매트릭스!$A$5:$A$131,통합매트릭스!$B$5:$B$131,통합매트릭스!$B$5:$B$131)) | G19: =COUNTIF(통합매트릭스!$A$5:$A$131,A19) | H19: =COUNTIFS(통합매트릭스!$A$5:$A$131,A19,통합매트릭스!$I$5:$I$131,"매우 높음")+COUNTIFS(통합매트릭스!$A$5:$A$131,A19,통합매트릭스!$I$5:$I$131,"높음")
A20: D10. 사용자 기만 및 AI 거버넌스 미흡 | B20: User Deception & AI Governance Gaps | C20: AI 출력을 신뢰하는 사용자가 기만되어 위험한 판단을 내리거나, 감사 체계와 데이터 수명주기 관리가 미흡하여 책임 추적과 규제 준수가 어려워지는 리스크 | D20: 사용자와 승인자, 감사 로그, 데이터 분류와 보존 및 폐기 체계 | E20: 사람의 판단 또는 관리체계의 미흡이 원인이면 D10 | F20: =SUMPRODUCT((통합매트릭스!$A$5:$A$131=A20)/COUNTIFS(통합매트릭스!$A$5:$A$131,통합매트릭스!$A$5:$A$131,통합매트릭스!$B$5:$B$131,통합매트릭스!$B$5:$B$131)) | G20: =COUNTIF(통합매트릭스!$A$5:$A$131,A20) | H20: =COUNTIFS(통합매트릭스!$A$5:$A$131,A20,통합매트릭스!$I$5:$I$131,"매우 높음")+COUNTIFS(통합매트릭스!$A$5:$A$131,A20,통합매트릭스!$I$5:$I$131,"높음")
A22: 3. 위험 평가 기준 (Lv3 단위)
A23: 항목 | B23: 상 | C23: 중 | D23: 하 | E23: 산정 방식
A24: 발생가능성 | B24: 실제 사고 2건 이상 (ATLAS Incident 사례 + OWASP 인용 실제 사고) | C24: 실제 사고 1건, 또는 실증 사례(연구·레드팀)·Realized 기법·공개 취약점/익스플로잇 존재 | D24: 이론적으로 가능하나 실제 사례·실증·공개 취약점 없음 | E24: 근거(ATLAS 사례·OWASP 인용 실제 사고·Realized 기법·공개 취약점) 기준 산정. LITE는 v3.1 산정값을 고정하며, 사례·근거 개정 시 기준에 따라 재평가(드롭다운 수정)
A25: 심각도 | B25: AI 시스템 전체 통제권 탈취 또는 중요·개인정보 대량 탈취 가능성 높음 (호스트·에이전트 장악, 연동 자격증명 탈취, 대량 반출) | C25: 부분적 통제 상실 또는 제한된 범위의 정보 노출·무결성 훼손·재무 피해 | D25: 영향 범위 제한적, 경미한 정보 노출 또는 일시적 장애 (준비·탐색 단계 포함) | E25: 분석자 평가(심각도 근거 열에 사유 기재) — 기준: 통제권 범위, 정보 노출 규모, 피해 지속성. 드롭다운으로 수정 가능
A26: 위험도 | B26: 매우 높음: 상×상 | C26: 높음: 상×중, 중×상 / 보통: 중×중, 상×하, 하×상 | D26: 낮음: 중×하, 하×중, 하×하 | E26: 발생가능성 × 심각도 3×3 매트릭스(수식, 자동 재계산)
A28: 4. 근거 수준 정의 (높은 순)
A29: 근거 수준 | B29: 판정 기준
A30: 실제 사고 확인 | B30: ATLAS Incident 사례 또는 OWASP 원문이 인용한 실제 사고가 1건 이상 연결('실제 사고 수' ≥ 1)
A31: 실사용 기법 포함 | B31: 실제 사고 연결은 없으나 ATLAS Maturity 'Realized' 기법이 귀속
A32: 실증·공개 취약점 | B32: 연구·레드팀 실증 사례(ATLAS Exercise) 또는 OWASP 인용 CVE·공개 익스플로잇 존재
A33: 이론·시나리오 | B33: 공개 근거 없음(OWASP 위험 정의·시나리오 기반). '발생하지 않음'이 아니라 '공개 근거 없음'을 의미

Sheet ATLAS사례연구
A1: MITRE ATLAS 사례연구(73건) — 요약 및 Lv3 매핑
A2: 주 Lv3 = 분석자가 지정한 대표 세부 위협. 매핑 Lv3 = 공식 절차(employs) 기법의 Lv3 + 분석자 보완. 유형: Incident=실제 사고, Exercise=실증
A4: 사례 ID | B4: 사례명 | C4: 유형 | D4: 발생·공개 시점 | E4: 행위자 | F4: 대상 | G4: 국문 요약 | H4: 주 Lv3 | I4: 매핑 Lv3 (전체) | J4: URL
A5: AML.CS0000 | B5: Evasion of Deep Learning Detector for Malware C&C Traffic | C5: Exercise | D5: 2020 | E5: Palo Alto Networks AI Research Team | F5: Palo Alto Networks malware detection system | G5: 공개 논문을 재현한 대리모델로 악성 C&C 트래픽 탐지 딥러닝 모델을 회피 | H5: UT-17.1 | I5: UT-01.1, UT-02.2, UT-16.1, UT-17.1 | J5: https://atlas.mitre.org/case-studies/AML.CS0000
A6: AML.CS0001 | B6: Botnet Domain Generation Algorithm (DGA) Detection Evasion | C6: Exercise | D6: 2020 | E6: Palo Alto Networks AI Research Team | F6: Palo Alto Networks ML-based DGA detection module | G6: 도메인명 변형 기법으로 CNN 기반 봇넷 DGA 탐지기를 우회 | H6: UT-17.1 | I6: UT-01.1, UT-02.1, UT-02.2, UT-17.1 | J6: https://atlas.mitre.org/case-studies/AML.CS0001
A7: AML.CS0002 | B7: VirusTotal Poisoning | C7: Incident | D7: 2020 | E7: Unknown | F7: VirusTotal | G7: VirusTotal에 변종 샘플을 대량 제출해 크라우드소싱 학습 데이터를 오염 | H7: UT-09.1 | I7: UT-02.1, UT-09.1, UT-17.1, UT-28.1 | J7: https://atlas.mitre.org/case-studies/AML.CS0002
A8: AML.CS0003 | B8: Bypassing Cylance's AI Malware Detection | C8: Exercise | D8: 2019-09-07 | E8: Skylight Cyber | F8: CylancePROTECT, Cylance Smart Antivirus | G8: Cylance AI 악성코드 탐지기의 판단 로직을 분석해 범용 우회 문자열 생성 | H8: UT-17.1 | I8: UT-01.1, UT-01.3, UT-02.1, UT-15.3, UT-17.1 | J8: https://atlas.mitre.org/case-studies/AML.CS0003
A9: AML.CS0004 | B9: Camera Hijack Attack on Facial Recognition System | C9: Incident | D9: 2020 | E9: Two individuals | F9: Shanghai government tax office's facial recognition service | G9: 카메라 영상 주입으로 얼굴인식 인증을 우회해 세금 사기(실제 사고) | H9: UT-17.1 | I9: UT-01.1, UT-01.3, UT-02.1, UT-02.3, UT-04.1, UT-17.1 | J9: https://atlas.mitre.org/case-studies/AML.CS0004
A10: AML.CS0005 | B10: Attack on Machine Translation Services | C10: Exercise | D10: 2020-04-30 | E10: Berkeley Artificial Intelligence Research | F10: Google Translate, Bing Translator, Systran Translate | G10: 번역 API 질의로 모델을 복제하고 적대적 예제를 원 서비스에 전이 | H10: UT-16.1 | I10: UT-01.1, UT-01.3, UT-02.2, UT-09.4, UT-16.1, UT-17.1 | J10: https://atlas.mitre.org/case-studies/AML.CS0005
A11: AML.CS0006 | B11: ClearviewAI Misconfiguration | C11: Incident | D11: 2020-04 | E11: Researchers at spiderSilk | F11: Clearview AI facial recognition tool | G11: Clearview AI 저장소 설정 오류로 소스코드·자격증명·모델 노출 | H11: UT-31.1 | I11: UT-02.2, UT-02.3, UT-02.6, UT-09.4, UT-25.1, UT-31.1 | J11: https://atlas.mitre.org/case-studies/AML.CS0006
A12: AML.CS0007 | B12: GPT-2 Model Replication | C12: Exercise | D12: 2019-08-22 | E12: Researchers at Brown University | F12: OpenAI GPT-2 | G12: 공개 정보로 GPT-2 규모 모델을 재현(모델 복제) | H12: UT-16.1 | I12: UT-01.1, UT-02.2, UT-02.3, UT-16.1 | J12: https://atlas.mitre.org/case-studies/AML.CS0007
A13: AML.CS0008 | B13: ProofPoint Evasion | C13: Exercise | D13: 2019-09-09 | E13: Researchers at Silent Break Security | F13: ProofPoint Email Protection System | G13: ProofPoint 이메일 보호 모델의 복제본을 만들어 실서비스 탐지 회피 | H13: UT-17.1 | I13: UT-01.3, UT-15.3, UT-16.1, UT-17.1 | J13: https://atlas.mitre.org/case-studies/AML.CS0008
A14: AML.CS0009 | B14: Tay Poisoning | C14: Incident | D14: 2016-03-23 | E14: 4chan Users | F14: Microsoft's Tay AI Chatbot | G14: Tay 챗봇이 사용자 대화로 온라인 학습되며 오염되어 혐오 발언 생성(실제 사고) | H14: UT-09.3 | I14: UT-01.3, UT-09.1, UT-09.3, UT-09.4, UT-28.1 | J14: https://atlas.mitre.org/case-studies/AML.CS0009
A15: AML.CS0010 | B15: Microsoft Azure Service Disruption | C15: Exercise | D15: 2020 | E15: Microsoft AI Red Team | F15: Internal Microsoft Azure Service | G15: 레드팀이 기존 침투기법과 AI 회피를 결합해 Azure 내부 서비스 중단 시연 | H15: UT-17.1 | I15: UT-01.1, UT-01.3, UT-02.6, UT-16.2, UT-17.1, UT-25.4 | J15: https://atlas.mitre.org/case-studies/AML.CS0010
... A77: AML.CS0072 | B77: AI Recommendation Poisoning via Crafted AI Assistant Links | C77: Incident | D77: 2026-02-10 | E77: Multiple commercial entities; 31 distinct companies identified | F77: Users of AI assistants with persistent memory features, including Microsoft 365 Copilot, ChatGPT, Claude, Perplexity, and Grok | G77: 조작된 AI 비서 링크로 메모리를 오염시켜 특정 제품을 추천하게 만드는 홍보성 공격(실제 사고) | H77: UT-11.1 | I77: UT-02.1, UT-02.3, UT-06.3, UT-07.4, UT-11.1, UT-20.3 | J77: https://atlas.mitre.org/case-studies/AML.CS0072

Sheet 변경이력
A1: 변경이력
A2: 개정은 새 버전 파일로 저장하고 이 시트 상단에 기록. 이전 버전 상세 이력은 v3.1 원본 '변경이력' 시트 참조
A4: 버전 | B4: 일자 | C4: 구분 | D4: 대상 | E4: 변경 내용 | F4: 사유
A5: v3.1 LITE | B5: 2026-10-02 | C5: 시트 삭제 | D5: 13개 시트 | E5: 삭제: Lv2요약, 공격체인시나리오, ATLAS사례절차, OWASP상세, 커버리지히트맵, ATLAS전술×Lv3, ATLAS기법매핑, 완화책×UT, ATLAS완화책매핑, 소스항목사전, 공식크로스워크검증, LLM번호변환, 설계노트 (설계노트의 분류·평가 기준은 '도메인·평가기준'에 통합) | F5: 최종 산출물 경량화 — 도메인·위협 분류·세부 위협·설명·사례 중심으로 재구성
A6: v3.1 LITE | B6: 2026-10-02 | C6: 열 삭제 | D6: 통합매트릭스 48열 → 17열 | E6: 삭제: 발생가능성 근거 (자동 산정), 연관 공격 단계 (ATLAS 전술), 예측 AI, LLM 앱, RAG, AI 에이전트, 멀티에이전트·MCP, 영향, 기획/개발, 배포, 운영, 종료, 생애주기 비고, ATLAS 기법 (연관), 기법 수, Realized 기법 수, Maturity 분포 (R/D/F), LLM 2026 (보조), ASI 2026 (보조), DSGAI 2026 (보조), MCP (보조), 소스 커버리지 (0~5), ATLAS 사례 수, OWASP 인용 취약점·익스플로잇 수, 관련 ATLAS 사례 ID, ATLAS 완화책 (상위 5), 구 UT-ID (v1.2) | F6: 패싯·세부 매핑·집계용 보조 열 제거. 원본 v3.1에 보존
A7: v3.1 LITE | B7: 2026-10-02 | C7: 열 통합 | D7: OWASP 매핑 | E7: LLM·ASI·DSGAI·MCP 주 매핑 4열을 'OWASP 매핑 (주)' 1열로 통합(보조 매핑 제외) | F7: 가독성
A8: v3.1 LITE | B8: 2026-10-02 | C8: 열 통합 | D8: 실제 사고 수 | E8: ATLAS 실제 사고 수 + OWASP 인용 실제 사고 수를 1열로 합산 | F8: 가독성
A9: v3.1 LITE | B9: 2026-10-02 | C9: 수식 고정 | D9: 발생가능성·근거 수준 | E9: 삭제 시트를 참조하던 수식을 v3.1 산정값으로 고정. 위험도·개요 지표·도메인 집계는 LITE 내부 수식으로 재연결 | F9: 삭제 시트 참조 오류 방지
A10: v3.1 | B10: 2026-10-01 | C10: 명칭 변경 | D10: Lv1 도메인 10개 | E10: 보호 대상 명칭 → 영역별 보안 리스크 명칭(OWASP 명명 규칙) | F10: —
A11: v3.0 | B11: — | C11: 구조 개편 | D11: Lv3 127개 | E11: Lv3 세부 위협 도입, ATLAS 기법 21개 UT 간 이동, 위험 평가 추가 | F11: —
