Workbook

Sheet 개요
A1: 통합 AI 보안위협 매트릭스 (UTM) v3.1
A2: Lv1 도메인 10 · Lv2 위협 분류 36 · Lv3 세부 위협 127 · 위험 평가(발생가능성×심각도) | 2026-10-01
A4: 1. 통합 대상 소스
A5: 소스 | B5: 버전 / 공개일 | C5: 규모 | D5: 관점 | E5: 입수 경로
A6: MITRE ATLAS | B6: v2026.09 (2026-09-15) | C6: 전술 16 · 기법 208 · 완화책 40 · 사례 73 · 절차 665 | D6: 공격자 TTP | E6: 첨부 excel-atlas*.xlsx + ATLAS-2026_09.yaml
A7: OWASP Top 10 for LLM Applications | B7: 2026 (2026-08-04) | C7: 10 | D7: LLM 애플리케이션 위험 | E7: 첨부 원문
A8: OWASP Top 10 for Agentic Applications | B8: 2026 (2025-12-09) | C8: 10 + 사고 추적표 25건 | D8: 에이전트 위험 | E8: 첨부 원문
A9: OWASP GenAI Data Security | B9: 2026 v1.0 (2026-03) | C9: 21 | D9: 데이터 생애주기 위험 | E9: 첨부 원문
A10: OWASP MCP Top 10 (승인된 추가 소스) | B10: 2025 (beta) | C10: 10 | D10: MCP 프로토콜 계층 | E10: github.com/OWASP/www-project-mcp-top-10
A12: 2. 핵심 지표 (수식 연동)
A13: Lv1 도메인 / Lv2 위협 분류 / Lv3 세부 위협 | B13: =SUMPRODUCT(1/COUNTIF(통합매트릭스!$A$5:$A$131,통합매트릭스!$A$5:$A$131))&" / "&SUMPRODUCT(1/COUNTIF(통합매트릭스!$B$5:$B$131,통합매트릭스!$B$5:$B$131))&" / "&COUNTA(통합매트릭스!$D$5:$D$131) -> 10 / 36 / 127
A14: ATLAS 기법 귀속률 (Lv3 + 영향 패싯) | B14: =(COUNTIF(ATLAS기법매핑!G5:G212,"UT-*")+COUNTIF(ATLAS기법매핑!G5:G212,"영향 패싯"))/COUNTA(ATLAS기법매핑!A5:A212) -> 1
A15: 소스 항목(51) 매핑률 | B15: =COUNTIF(소스항목사전!G5:G55,">0")/COUNTA(소스항목사전!A5:A55) -> 1
A16: OWASP 공식 크로스워크 반영률 | B16: =공식크로스워크검증!B3 -> 1
A17: 사례 매핑 ↔ 공식 절차 주 UT 일치율 | B17: =COUNTIF(ATLAS사례연구!O5:O77,"일치*")/COUNTA(ATLAS사례연구!A5:A77) -> 0.97260274
A18: 실제 사고가 확인된 Lv3 | B18: =COUNTIF(통합매트릭스!$AQ$5:$AQ$131,"실제 사고 확인") -> 51
A19: 이론·시나리오 수준 Lv3 (공개 근거 없음) | B19: =COUNTIF(통합매트릭스!$AQ$5:$AQ$131,"이론·시나리오") -> 33
A20: 위험도 매우 높음 / 높음 / 보통 / 낮음 | B20: =COUNTIF(통합매트릭스!$I$5:$I$131,"매우 높음")&" / "&COUNTIF(통합매트릭스!$I$5:$I$131,"높음")&" / "&COUNTIF(통합매트릭스!$I$5:$I$131,"보통")&" / "&COUNTIF(통합매트릭스!$I$5:$I$131,"낮음") -> 17 / 39 / 38 / 33
A22: 3. 위험 매트릭스 (Lv3 수)
A23: 발생가능성 \ 심각도 | B23: 상 | C23: 중 | D23: 하
A24: 상 | B24: =COUNTIFS(통합매트릭스!$G$5:$G$131,"상",통합매트릭스!$H$5:$H$131,"상") -> 17 | C24: =COUNTIFS(통합매트릭스!$G$5:$G$131,"상",통합매트릭스!$H$5:$H$131,"중") -> 11 | D24: =COUNTIFS(통합매트릭스!$G$5:$G$131,"상",통합매트릭스!$H$5:$H$131,"하") -> 5
A25: 중 | B25: =COUNTIFS(통합매트릭스!$G$5:$G$131,"중",통합매트릭스!$H$5:$H$131,"상") -> 28 | C25: =COUNTIFS(통합매트릭스!$G$5:$G$131,"중",통합매트릭스!$H$5:$H$131,"중") -> 28 | D25: =COUNTIFS(통합매트릭스!$G$5:$G$131,"중",통합매트릭스!$H$5:$H$131,"하") -> 5
A26: 하 | B26: =COUNTIFS(통합매트릭스!$G$5:$G$131,"하",통합매트릭스!$H$5:$H$131,"상") -> 5 | C26: =COUNTIFS(통합매트릭스!$G$5:$G$131,"하",통합매트릭스!$H$5:$H$131,"중") -> 28 | D26: =COUNTIFS(통합매트릭스!$G$5:$G$131,"하",통합매트릭스!$H$5:$H$131,"하") -> 0
A28: 4. 위험도 '매우 높음' Lv3
A29: Lv3 ID | B29: 세부 위협 | C29: 위협 분류 (Lv2) | D29: 발생가능성 근거
A30: {=IF(1<=COUNTIF(통합매트릭스!$I$5:$I$131,"매우 높음"),INDEX(통합매트릭스!$D$5:$D$131,SMALL(IF(통합매트릭스!$I$5:$I$131="매우 높음",ROW(통합매트릭스!$I$5:$I$131)-5+1),1)),"")} -> UT-02.4 | B30: {=IF(1<=COUNTIF(통합매트릭스!$I$5:$I$131,"매우 높음"),INDEX(통합매트릭스!$E$5:$E$131,SMALL(IF(통합매트릭스!$I$5:$I$131="매우 높음",ROW(통합매트릭스!$I$5:$I$131)-5+1),1)),"")} -> 일반 초기 침투 | C30: {=IF(1<=COUNTIF(통합매트릭스!$I$5:$I$131,"매우 높음"),INDEX(통합매트릭스!$C$5:$C$131,SMALL(IF(통합매트릭스!$I$5:$I$131="매우 높음",ROW(통합매트릭스!$I$5:$I$131)-5+1),1)),"")} -> 공격 준비 및 일반 침투 기법 | D30: {=IF(1<=COUNTIF(통합매트릭스!$I$5:$I$131,"매우 높음"),INDEX(통합매트릭스!$J$5:$J$131,SMALL(IF(통합매트릭스!$I$5:$I$131="매우 높음",ROW(통합매트릭스!$I$5:$I$131)-5+1),1)),"")} -> 실제 사고 7건(ATLAS 6 / OWASP 1), 실증 사례 7건, Realized 기법 1개, 취약점·익스플로잇 1건
A31: {=IF(2<=COUNTIF(통합매트릭스!$I$5:$I$131,"매우 높음"),INDEX(통합매트릭스!$D$5:$D$131,SMALL(IF(통합매트릭스!$I$5:$I$131="매우 높음",ROW(통합매트릭스!$I$5:$I$131)-5+1),2)),"")} -> UT-02.6 | B31: {=IF(2<=COUNTIF(통합매트릭스!$I$5:$I$131,"매우 높음"),INDEX(통합매트릭스!$E$5:$E$131,SMALL(IF(통합매트릭스!$I$5:$I$131="매우 높음",ROW(통합매트릭스!$I$5:$I$131)-5+1),2)),"")} -> 일반 수단 데이터 유출 | C31: {=IF(2<=COUNTIF(통합매트릭스!$I$5:$I$131,"매우 높음"),INDEX(통합매트릭스!$C$5:$C$131,SMALL(IF(통합매트릭스!$I$5:$I$131="매우 높음",ROW(통합매트릭스!$I$5:$I$131)-5+1),2)),"")} -> 공격 준비 및 일반 침투 기법 | D31: {=IF(2<=COUNTIF(통합매트릭스!$I$5:$I$131,"매우 높음"),INDEX(통합매트릭스!$J$5:$J$131,SMALL(IF(통합매트릭스!$I$5:$I$131="매우 높음",ROW(통합매트릭스!$I$5:$I$131)-5+1),2)),"")} -> 실제 사고 9건(ATLAS 9 / OWASP 0), 실증 사례 10건, Realized 기법 6개, 취약점·익스플로잇 0건
A32: {=IF(3<=COUNTIF(통합매트릭스!$I$5:$I$131,"매우 높음"),INDEX(통합매트릭스!$D$5:$D$131,SMALL(IF(통합매트릭스!$I$5:$I$131="매우 높음",ROW(통합매트릭스!$I$5:$I$131)-5+1),3)),"")} -> UT-03.1 | B32: {=IF(3<=COUNTIF(통합매트릭스!$I$5:$I$131,"매우 높음"),INDEX(통합매트릭스!$E$5:$E$131,SMALL(IF(통합매트릭스!$I$5:$I$131="매우 높음",ROW(통합매트릭스!$I$5:$I$131)-5+1),3)),"")} -> 자율 공격 에이전트 | C32: {=IF(3<=COUNTIF(통합매트릭스!$I$5:$I$131,"매우 높음"),INDEX(통합매트릭스!$C$5:$C$131,SMALL(IF(통합매트릭스!$I$5:$I$131="매우 높음",ROW(통합매트릭스!$I$5:$I$131)-5+1),3)),"")} -> AI 기반 자율 공격 | D32: {=IF(3<=COUNTIF(통합매트릭스!$I$5:$I$131,"매우 높음"),INDEX(통합매트릭스!$J$5:$J$131,SMALL(IF(통합매트릭스!$I$5:$I$131="매우 높음",ROW(통합매트릭스!$I$5:$I$131)-5+1),3)),"")} -> 실제 사고 4건(ATLAS 4 / OWASP 0), 실증 사례 0건, Realized 기법 3개, 취약점·익스플로잇 0건
A33: {=IF(4<=COUNTIF(통합매트릭스!$I$5:$I$131,"매우 높음"),INDEX(통합매트릭스!$D$5:$D$131,SMALL(IF(통합매트릭스!$I$5:$I$131="매우 높음",ROW(통합매트릭스!$I$5:$I$131)-5+1),4)),"")} -> UT-03.2 | B33: {=IF(4<=COUNTIF(통합매트릭스!$I$5:$I$131,"매우 높음"),INDEX(통합매트릭스!$E$5:$E$131,SMALL(IF(통합매트릭스!$I$5:$I$131="매우 높음",ROW(통합매트릭스!$I$5:$I$131)-5+1),4)),"")} -> 다중 에이전트 공격 조율 | C33: {=IF(4<=COUNTIF(통합매트릭스!$I$5:$I$131,"매우 높음"),INDEX(통합매트릭스!$C$5:$C$131,SMALL(IF(통합매트릭스!$I$5:$I$131="매우 높음",ROW(통합매트릭스!$I$5:$I$131)-5+1),4)),"")} -> AI 기반 자율 공격 | D33: {=IF(4<=COUNTIF(통합매트릭스!$I$5:$I$131,"매우 높음"),INDEX(통합매트릭스!$J$5:$J$131,SMALL(IF(통합매트릭스!$I$5:$I$131="매우 높음",ROW(통합매트릭스!$I$5:$I$131)-5+1),4)),"")} -> 실제 사고 2건(ATLAS 2 / OWASP 0), 실증 사례 0건, Realized 기법 4개, 취약점·익스플로잇 0건
A34: {=IF(5<=COUNTIF(통합매트릭스!$I$5:$I$131,"매우 높음"),INDEX(통합매트릭스!$D$5:$D$131,SMALL(IF(통합매트릭스!$I$5:$I$131="매우 높음",ROW(통합매트릭스!$I$5:$I$131)-5+1),5)),"")} -> UT-03.3 | B34: {=IF(5<=COUNTIF(통합매트릭스!$I$5:$I$131,"매우 높음"),INDEX(통합매트릭스!$E$5:$E$131,SMALL(IF(통합매트릭스!$I$5:$I$131="매우 높음",ROW(통합매트릭스!$I$5:$I$131)-5+1),5)),"")} -> AI 연동 악성코드 | C34: {=IF(5<=COUNTIF(통합매트릭스!$I$5:$I$131,"매우 높음"),INDEX(통합매트릭스!$C$5:$C$131,SMALL(IF(통합매트릭스!$I$5:$I$131="매우 높음",ROW(통합매트릭스!$I$5:$I$131)-5+1),5)),"")} -> AI 기반 자율 공격 | D34: {=IF(5<=COUNTIF(통합매트릭스!$I$5:$I$131,"매우 높음"),INDEX(통합매트릭스!$J$5:$J$131,SMALL(IF(통합매트릭스!$I$5:$I$131="매우 높음",ROW(통합매트릭스!$I$5:$I$131)-5+1),5)),"")} -> 실제 사고 3건(ATLAS 3 / OWASP 0), 실증 사례 0건, Realized 기법 1개, 취약점·익스플로잇 0건
A35: {=IF(6<=COUNTIF(통합매트릭스!$I$5:$I$131,"매우 높음"),INDEX(통합매트릭스!$D$5:$D$131,SMALL(IF(통합매트릭스!$I$5:$I$131="매우 높음",ROW(통합매트릭스!$I$5:$I$131)-5+1),6)),"")} -> UT-21.5 | B35: {=IF(6<=COUNTIF(통합매트릭스!$I$5:$I$131,"매우 높음"),INDEX(통합매트릭스!$E$5:$E$131,SMALL(IF(통합매트릭스!$I$5:$I$131="매우 높음",ROW(통합매트릭스!$I$5:$I$131)-5+1),6)),"")} -> 파괴적 도구 실행 | C35: {=IF(6<=COUNTIF(통합매트릭스!$I$5:$I$131,"매우 높음"),INDEX(통합매트릭스!$C$5:$C$131,SMALL(IF(통합매트릭스!$I$5:$I$131="매우 높음",ROW(통합매트릭스!$I$5:$I$131)-5+1),6)),"")} -> 과도한 에이전시 | D35: {=IF(6<=COUNTIF(통합매트릭스!$I$5:$I$131,"매우 높음"),INDEX(통합매트릭스!$J$5:$J$131,SMALL(IF(통합매트릭스!$I$5:$I$131="매우 높음",ROW(통합매트릭스!$I$5:$I$131)-5+1),6)),"")} -> 실제 사고 3건(ATLAS 1 / OWASP 2), 실증 사례 2건, Realized 기법 1개, 취약점·익스플로잇 0건
A36: {=IF(7<=COUNTIF(통합매트릭스!$I$5:$I$131,"매우 높음"),INDEX(통합매트릭스!$D$5:$D$131,SMALL(IF(통합매트릭스!$I$5:$I$131="매우 높음",ROW(통합매트릭스!$I$5:$I$131)-5+1),7)),"")} -> UT-22.1 | B36: {=IF(7<=COUNTIF(통합매트릭스!$I$5:$I$131,"매우 높음"),INDEX(통합매트릭스!$E$5:$E$131,SMALL(IF(통합매트릭스!$I$5:$I$131="매우 높음",ROW(통합매트릭스!$I$5:$I$131)-5+1),7)),"")} -> 생성 코드 실행 | C36: {=IF(7<=COUNTIF(통합매트릭스!$I$5:$I$131,"매우 높음"),INDEX(통합매트릭스!$C$5:$C$131,SMALL(IF(통합매트릭스!$I$5:$I$131="매우 높음",ROW(통합매트릭스!$I$5:$I$131)-5+1),7)),"")} -> 비의도적 코드 실행 | D36: {=IF(7<=COUNTIF(통합매트릭스!$I$5:$I$131,"매우 높음"),INDEX(통합매트릭스!$J$5:$J$131,SMALL(IF(통합매트릭스!$I$5:$I$131="매우 높음",ROW(통합매트릭스!$I$5:$I$131)-5+1),7)),"")} -> 실제 사고 2건(ATLAS 2 / OWASP 0), 실증 사례 11건, Realized 기법 1개, 취약점·익스플로잇 5건
A37: {=IF(8<=COUNTIF(통합매트릭스!$I$5:$I$131,"매우 높음"),INDEX(통합매트릭스!$D$5:$D$131,SMALL(IF(통합매트릭스!$I$5:$I$131="매우 높음",ROW(통합매트릭스!$I$5:$I$131)-5+1),8)),"")} -> UT-22.2 | B37: {=IF(8<=COUNTIF(통합매트릭스!$I$5:$I$131,"매우 높음"),INDEX(통합매트릭스!$E$5:$E$131,SMALL(IF(통합매트릭스!$I$5:$I$131="매우 높음",ROW(통합매트릭스!$I$5:$I$131)-5+1),8)),"")} -> 안전하지 않은 파일 실행 | C37: {=IF(8<=COUNTIF(통합매트릭스!$I$5:$I$131,"매우 높음"),INDEX(통합매트릭스!$C$5:$C$131,SMALL(IF(통합매트릭스!$I$5:$I$131="매우 높음",ROW(통합매트릭스!$I$5:$I$131)-5+1),8)),"")} -> 비의도적 코드 실행 | D37: {=IF(8<=COUNTIF(통합매트릭스!$I$5:$I$131,"매우 높음"),INDEX(통합매트릭스!$J$5:$J$131,SMALL(IF(통합매트릭스!$I$5:$I$131="매우 높음",ROW(통합매트릭스!$I$5:$I$131)-5+1),8)),"")} -> 실제 사고 2건(ATLAS 2 / OWASP 0), 실증 사례 2건, Realized 기법 1개, 취약점·익스플로잇 1건
A38: {=IF(9<=COUNTIF(통합매트릭스!$I$5:$I$131,"매우 높음"),INDEX(통합매트릭스!$D$5:$D$131,SMALL(IF(통합매트릭스!$I$5:$I$131="매우 높음",ROW(통합매트릭스!$I$5:$I$131)-5+1),9)),"")} -> UT-24.1 | B38: {=IF(9<=COUNTIF(통합매트릭스!$I$5:$I$131,"매우 높음"),INDEX(통합매트릭스!$E$5:$E$131,SMALL(IF(통합매트릭스!$I$5:$I$131="매우 높음",ROW(통합매트릭스!$I$5:$I$131)-5+1),9)),"")} -> 목표 이탈과 보상 해킹 | C38: {=IF(9<=COUNTIF(통합매트릭스!$I$5:$I$131,"매우 높음"),INDEX(통합매트릭스!$C$5:$C$131,SMALL(IF(통합매트릭스!$I$5:$I$131="매우 높음",ROW(통합매트릭스!$I$5:$I$131)-5+1),9)),"")} -> 통제를 벗어난 에이전트 | D38: {=IF(9<=COUNTIF(통합매트릭스!$I$5:$I$131,"매우 높음"),INDEX(통합매트릭스!$J$5:$J$131,SMALL(IF(통합매트릭스!$I$5:$I$131="매우 높음",ROW(통합매트릭스!$I$5:$I$131)-5+1),9)),"")} -> 실제 사고 2건(ATLAS 1 / OWASP 1), 실증 사례 0건, Realized 기법 0개, 취약점·익스플로잇 0건
A39: {=IF(10<=COUNTIF(통합매트릭스!$I$5:$I$131,"매우 높음"),INDEX(통합매트릭스!$D$5:$D$131,SMALL(IF(통합매트릭스!$I$5:$I$131="매우 높음",ROW(통합매트릭스!$I$5:$I$131)-5+1),10)),"")} -> UT-24.2 | B39: {=IF(10<=COUNTIF(통합매트릭스!$I$5:$I$131,"매우 높음"),INDEX(통합매트릭스!$E$5:$E$131,SMALL(IF(통합매트릭스!$I$5:$I$131="매우 높음",ROW(통합매트릭스!$I$5:$I$131)-5+1),10)),"")} -> 악성 에이전트 배치 | C39: {=IF(10<=COUNTIF(통합매트릭스!$I$5:$I$131,"매우 높음"),INDEX(통합매트릭스!$C$5:$C$131,SMALL(IF(통합매트릭스!$I$5:$I$131="매우 높음",ROW(통합매트릭스!$I$5:$I$131)-5+1),10)),"")} -> 통제를 벗어난 에이전트 | D39: {=IF(10<=COUNTIF(통합매트릭스!$I$5:$I$131,"매우 높음"),INDEX(통합매트릭스!$J$5:$J$131,SMALL(IF(통합매트릭스!$I$5:$I$131="매우 높음",ROW(통합매트릭스!$I$5:$I$131)-5+1),10)),"")} -> 실제 사고 2건(ATLAS 2 / OWASP 0), 실증 사례 0건, Realized 기법 1개, 취약점·익스플로잇 0건
A40: {=IF(11<=COUNTIF(통합매트릭스!$I$5:$I$131,"매우 높음"),INDEX(통합매트릭스!$D$5:$D$131,SMALL(IF(통합매트릭스!$I$5:$I$131="매우 높음",ROW(통합매트릭스!$I$5:$I$131)-5+1),11)),"")} -> UT-25.1 | B40: {=IF(11<=COUNTIF(통합매트릭스!$I$5:$I$131,"매우 높음"),INDEX(통합매트릭스!$E$5:$E$131,SMALL(IF(통합매트릭스!$I$5:$I$131="매우 높음",ROW(통합매트릭스!$I$5:$I$131)-5+1),11)),"")} -> 설정 파일 내 비밀정보 수집 | C40: {=IF(11<=COUNTIF(통합매트릭스!$I$5:$I$131,"매우 높음"),INDEX(통합매트릭스!$C$5:$C$131,SMALL(IF(통합매트릭스!$I$5:$I$131="매우 높음",ROW(통합매트릭스!$I$5:$I$131)-5+1),11)),"")} -> 에이전트 자격증명 탈취 및 악용 | D40: {=IF(11<=COUNTIF(통합매트릭스!$I$5:$I$131,"매우 높음"),INDEX(통합매트릭스!$J$5:$J$131,SMALL(IF(통합매트릭스!$I$5:$I$131="매우 높음",ROW(통합매트릭스!$I$5:$I$131)-5+1),11)),"")} -> 실제 사고 8건(ATLAS 7 / OWASP 1), 실증 사례 6건, Realized 기법 1개, 취약점·익스플로잇 0건
A41: {=IF(12<=COUNTIF(통합매트릭스!$I$5:$I$131,"매우 높음"),INDEX(통합매트릭스!$D$5:$D$131,SMALL(IF(통합매트릭스!$I$5:$I$131="매우 높음",ROW(통합매트릭스!$I$5:$I$131)-5+1),12)),"")} -> UT-25.4 | B41: {=IF(12<=COUNTIF(통합매트릭스!$I$5:$I$131,"매우 높음"),INDEX(통합매트릭스!$E$5:$E$131,SMALL(IF(통합매트릭스!$I$5:$I$131="매우 높음",ROW(통합매트릭스!$I$5:$I$131)-5+1),12)),"")} -> 탈취 자격증명 재사용 | C41: {=IF(12<=COUNTIF(통합매트릭스!$I$5:$I$131,"매우 높음"),INDEX(통합매트릭스!$C$5:$C$131,SMALL(IF(통합매트릭스!$I$5:$I$131="매우 높음",ROW(통합매트릭스!$I$5:$I$131)-5+1),12)),"")} -> 에이전트 자격증명 탈취 및 악용 | D41: {=IF(12<=COUNTIF(통합매트릭스!$I$5:$I$131,"매우 높음"),INDEX(통합매트릭스!$J$5:$J$131,SMALL(IF(통합매트릭스!$I$5:$I$131="매우 높음",ROW(통합매트릭스!$I$5:$I$131)-5+1),12)),"")} -> 실제 사고 6건(ATLAS 6 / OWASP 0), 실증 사례 7건, Realized 기법 4개, 취약점·익스플로잇 0건
A42: {=IF(13<=COUNTIF(통합매트릭스!$I$5:$I$131,"매우 높음"),INDEX(통합매트릭스!$D$5:$D$131,SMALL(IF(통합매트릭스!$I$5:$I$131="매우 높음",ROW(통합매트릭스!$I$5:$I$131)-5+1),13)),"")} -> UT-28.1 | B42: {=IF(13<=COUNTIF(통합매트릭스!$I$5:$I$131,"매우 높음"),INDEX(통합매트릭스!$E$5:$E$131,SMALL(IF(통합매트릭스!$I$5:$I$131="매우 높음",ROW(통합매트릭스!$I$5:$I$131)-5+1),13)),"")} -> 변조 모델 유입 | C42: {=IF(13<=COUNTIF(통합매트릭스!$I$5:$I$131,"매우 높음"),INDEX(통합매트릭스!$C$5:$C$131,SMALL(IF(통합매트릭스!$I$5:$I$131="매우 높음",ROW(통합매트릭스!$I$5:$I$131)-5+1),13)),"")} -> 모델 및 데이터 공급망 침해 | D42: {=IF(13<=COUNTIF(통합매트릭스!$I$5:$I$131,"매우 높음"),INDEX(통합매트릭스!$J$5:$J$131,SMALL(IF(통합매트릭스!$I$5:$I$131="매우 높음",ROW(통합매트릭스!$I$5:$I$131)-5+1),13)),"")} -> 실제 사고 4건(ATLAS 4 / OWASP 0), 실증 사례 5건, Realized 기법 6개, 취약점·익스플로잇 0건
A43: {=IF(14<=COUNTIF(통합매트릭스!$I$5:$I$131,"매우 높음"),INDEX(통합매트릭스!$D$5:$D$131,SMALL(IF(통합매트릭스!$I$5:$I$131="매우 높음",ROW(통합매트릭스!$I$5:$I$131)-5+1),14)),"")} -> UT-28.2 | B43: {=IF(14<=COUNTIF(통합매트릭스!$I$5:$I$131,"매우 높음"),INDEX(통합매트릭스!$E$5:$E$131,SMALL(IF(통합매트릭스!$I$5:$I$131="매우 높음",ROW(통합매트릭스!$I$5:$I$131)-5+1),14)),"")} -> 악성 의존성 유입 | C43: {=IF(14<=COUNTIF(통합매트릭스!$I$5:$I$131,"매우 높음"),INDEX(통합매트릭스!$C$5:$C$131,SMALL(IF(통합매트릭스!$I$5:$I$131="매우 높음",ROW(통합매트릭스!$I$5:$I$131)-5+1),14)),"")} -> 모델 및 데이터 공급망 침해 | D43: {=IF(14<=COUNTIF(통합매트릭스!$I$5:$I$131,"매우 높음"),INDEX(통합매트릭스!$J$5:$J$131,SMALL(IF(통합매트릭스!$I$5:$I$131="매우 높음",ROW(통합매트릭스!$I$5:$I$131)-5+1),14)),"")} -> 실제 사고 2건(ATLAS 2 / OWASP 0), 실증 사례 3건, Realized 기법 2개, 취약점·익스플로잇 0건
A44: {=IF(15<=COUNTIF(통합매트릭스!$I$5:$I$131,"매우 높음"),INDEX(통합매트릭스!$D$5:$D$131,SMALL(IF(통합매트릭스!$I$5:$I$131="매우 높음",ROW(통합매트릭스!$I$5:$I$131)-5+1),15)),"")} -> UT-28.4 | B44: {=IF(15<=COUNTIF(통합매트릭스!$I$5:$I$131,"매우 높음"),INDEX(통합매트릭스!$E$5:$E$131,SMALL(IF(통합매트릭스!$I$5:$I$131="매우 높음",ROW(통합매트릭스!$I$5:$I$131)-5+1),15)),"")} -> 네임스페이스 및 평판 악용 | C44: {=IF(15<=COUNTIF(통합매트릭스!$I$5:$I$131,"매우 높음"),INDEX(통합매트릭스!$C$5:$C$131,SMALL(IF(통합매트릭스!$I$5:$I$131="매우 높음",ROW(통합매트릭스!$I$5:$I$131)-5+1),15)),"")} -> 모델 및 데이터 공급망 침해 | D44: {=IF(15<=COUNTIF(통합매트릭스!$I$5:$I$131,"매우 높음"),INDEX(통합매트릭스!$J$5:$J$131,SMALL(IF(통합매트릭스!$I$5:$I$131="매우 높음",ROW(통합매트릭스!$I$5:$I$131)-5+1),15)),"")} -> 실제 사고 2건(ATLAS 2 / OWASP 0), 실증 사례 6건, Realized 기법 2개, 취약점·익스플로잇 0건
...

Sheet 통합매트릭스
A1: 통합 AI 보안위협 매트릭스 v3.1 — Lv1 도메인(10) · Lv2 위협 분류(36) · Lv3 세부 위협(127)
A2: 기준: MITRE ATLAS v2026.09(YAML) · OWASP LLM Top 10 2026 · Agentic Top 10 2026 · GenAI Data Security 2026 v1.0 · MCP Top 10(2025 beta) | 2026-10-01
A3: 분류 체계 (Lv1 · Lv2 · Lv3) | G3: 위험 평가 | L3: 공격 단계 | N3: AI 적용 프로파일 | S3: 영향 | T3: 생애주기(기업 관점) ●주 통제 시점 ○연관 | Y3: MITRE ATLAS | AD3: OWASP LLM · Agentic · Data Security · MCP | AM3: 실제 근거 | AT3: 통제 (Lv2 유지)
A4: 도메인 (Lv1) | B4: UT-ID | C4: 위협 분류 (Lv2) | D4: Lv3 ID | E4: 세부 위협 (Lv3) | F4: 위협 설명 (Lv3) | G4: 발생가능성 | H4: 심각도 | I4: 위험도 | J4: 발생가능성 근거 (자동 산정) | K4: 심각도 근거 | L4: 주 공격 단계 | M4: 연관 공격 단계 (ATLAS 전술) | N4: 예측 AI | O4: LLM 앱 | P4: RAG | Q4: AI 에이전트 | R4: 멀티에이전트·MCP | S4: 영향 | T4: 기획/개발 | U4: 배포 | V4: 운영 | W4: 종료 | X4: 생애주기 비고 | Y4: ATLAS 기법 (주) | Z4: ATLAS 기법 (연관) | AA4: 기법 수 | AB4: Realized 기법 수 | AC4: Maturity 분포 (R/D/F) | AD4: LLM 2026 (주) | AE4: LLM 2026 (보조) | AF4: ASI 2026 (주) | AG4: ASI 2026 (보조) | AH4: DSGAI 2026 (주) | AI4: DSGAI 2026 (보조) | AJ4: MCP (주) | AK4: MCP (보조) | AL4: 소스 커버리지 (0~5) | AM4: ATLAS 사례 수 | AN4: ATLAS 실제 사고 수 | AO4: OWASP 인용 실제 사고 수 | AP4: OWASP 인용 취약점·익스플로잇 수 | AQ4: 근거 수준 | AR4: 관련 ATLAS 사례 ID | AS4: 실제 사례·공격 예시 | AT4: ATLAS 완화책 (상위 5) | AU4: 핵심 통제 요약 (Lv2) | AV4: 구 UT-ID (v1.2)
A5: D01. 공격 준비 및 AI 무기화 | B5: UT-01 | C5: AI 대상 정찰 및 접근 확보 | D5: UT-01.1 | E5: 공개 정보 수집 | F5: 공개 논문/기술 블로그/코드 저장소/조직 웹사이트 분석을 통해 대상 AI의 모델 구조, 학습 데이터, 사용 프레임워크 및 관련 인물 정보를 수집하여 후속 공격 설계에 활용 | G5: =IF(AN5+AO5>=2,"상",IF(OR(AN5+AO5=1,AM5>0,AB5>0,AP5>0),"중","하")) -> 상 | H5: 하 | I5: =IF(AND(G5="상",H5="상"),"매우 높음",IF(OR(AND(G5="상",H5="중"),AND(G5="중",H5="상")),"높음",IF(OR(AND(G5="중",H5="중"),AND(G5="상",H5="하"),AND(G5="하",H5="상")),"보통","낮음"))) -> 보통 | J5: ="실제 사고 "&(AN5+AO5)&"건(ATLAS "&AN5&" / OWASP "&AO5&"), 실증 사례 "&(AM5-AN5)&"건, Realized 기법 "&AB5&"개, 취약점·익스플로잇 "&AP5&"건" -> 실제 사고 3건(ATLAS 3 / OWASP 0), 실증 사례 20건, Realized 기법 5개, 취약점·익스플로잇 0건 | K5: 직접 피해 없음(후속 공격 설계 단계) | L5: 정찰(Reconnaissance) | M5: 정찰 | N5: ● | O5: ● | P5: ● | Q5: ● | R5: ● | S5: (후속 공격 준비) | U5: ○ | V5: ○ | X5: 조직 생애주기 외부 활동 — 공개 릴리스(배포) 정보가 정찰 재료가 됨 | Y5: T0000, T0000.000, T0000.001, T0000.002, T0000.003, T0001, T0003, T0004, T0095, T0095.000, T0087 | AA5: =COUNTIF(ATLAS기법매핑!$H$5:$H$212,"*"&D5&"*") -> 11 | AB5: =COUNTIFS(ATLAS기법매핑!$H$5:$H$212,"*"&D5&"*",ATLAS기법매핑!$M$5:$M$212,"Realized") -> 5 | AC5: =COUNTIFS(ATLAS기법매핑!$H$5:$H$212,"*"&D5&"*",ATLAS기법매핑!$M$5:$M$212,"Realized")&" / "&COUNTIFS(ATLAS기법매핑!$H$5:$H$212,"*"&D5&"*",ATLAS기법매핑!$M$5:$M$212,"Demonstrated")&" / "&COUNTIFS(ATLAS기법매핑!$H$5:$H$212,"*"&D5&"*",ATLAS기법매핑!$M$5:$M$212,"Feasible") -> 5 / 4 / 2 | AL5: =(LEN(Y5&Z5)>0)+(LEN(AD5&AE5)>0)+(LEN(AF5&AG5)>0)+(LEN(AH5&AI5)>0)+(LEN(AJ5&AK5)>0) -> 1 | AM5: =COUNTIF(ATLAS사례연구!$J$5:$J$77,"*"&D5&"*") -> 23 | AN5: =COUNTIFS(ATLAS사례연구!$J$5:$J$77,"*"&D5&"*",ATLAS사례연구!$C$5:$C$77,"Incident") -> 3 | AO5: 0 | AP5: 0 | AQ5: =IF(AN5+AO5>0,"실제 사고 확인",IF(AB5>0,"실사용 기법 포함",IF(OR(AM5>0,AP5>0),"실증·공개 취약점","이론·시나리오"))) -> 실제 사고 확인 | AR5: CS0000, CS0001, CS0003, CS0004, CS0005, CS0007, CS0010, CS0011, CS0012, CS0013, CS0014, CS0016, CS0028, CS0033, CS0034, CS0039, CS0048, CS0051, CS0052, CS0061, CS0065, CS0067, CS0070 | AS5: • [ATLAS CS0004·실제사고] 카메라 영상 주입으로 얼굴인식 인증을 우회해 세금 사기(실제 사고) • [ATLAS CS0034·실제사고] KYC 우회용 딥페이크 도구 ProKYC가 범죄자에게 판매(실제 사고) • [ATLAS CS0070·실제사고] DeepSeek 기반 Hermes 에이전트로 Langflow·n8n 취약점 공격 시도(실제 사고) | AT5: M0000 Limit Public Release of Information M0039 AI Honeypots | AU5: 공개 정보·모델 아티팩트 공개 최소화, 노출 자산 관리, AI 허니팟, 비정상 탐색·질의 탐지 | AV5: UT-36
A6: D01. 공격 준비 및 AI 무기화 | B6: UT-01 | C6: AI 대상 정찰 및 접근 확보 | D6: UT-01.2 | E6: 노출 AI 자산 스캔 | F6: 인터넷 스캔/메타데이터 API 조회를 통해 외부에 노출된 AI 서비스, 모델 저장소, 에이전트 호출 채널을 식별하고 공격 가능한 진입점 목록화 | G6: =IF(AN6+AO6>=2,"상",IF(OR(AN6+AO6=1,AM6>0,AB6>0,AP6>0),"중","하")) -> 상 | H6: 하 | I6: =IF(AND(G6="상",H6="상"),"매우 높음",IF(OR(AND(G6="상",H6="중"),AND(G6="중",H6="상")),"높음",IF(OR(AND(G6="중",H6="중"),AND(G6="상",H6="하"),AND(G6="하",H6="상")),"보통","낮음"))) -> 보통 | J6: ="실제 사고 "&(AN6+AO6)&"건(ATLAS "&AN6&" / OWASP "&AO6&"), 실증 사례 "&(AM6-AN6)&"건, Realized 기법 "&AB6&"개, 취약점·익스플로잇 "&AP6&"건" -> 실제 사고 4건(ATLAS 4 / OWASP 0), 실증 사례 2건, Realized 기법 1개, 취약점·익스플로잇 0건 | K6: 직접 피해 없음(공격 진입점 식별 단계) | L6: 정찰(Reconnaissance) | M6: 정찰 | N6: ● | O6: ● | P6: ● | Q6: ● | R6: ● | S6: (후속 공격 준비) | U6: ○ | V6: ○ | X6: 조직 생애주기 외부 활동 — 공개 릴리스(배포) 정보가 정찰 재료가 됨 | Y6: T0006, T0006.000, T0006.001, T0006.002, T0006.003 | AA6: =COUNTIF(ATLAS기법매핑!$H$5:$H$212,"*"&D6&"*") -> 5 | AB6: =COUNTIFS(ATLAS기법매핑!$H$5:$H$212,"*"&D6&"*",ATLAS기법매핑!$M$5:$M$212,"Realized") -> 1 | AC6: =COUNTIFS(ATLAS기법매핑!$H$5:$H$212,"*"&D6&"*",ATLAS기법매핑!$M$5:$M$212,"Realized")&" / "&COUNTIFS(ATLAS기법매핑!$H$5:$H$212,"*"&D6&"*",ATLAS기법매핑!$M$5:$M$212,"Demonstrated")&" / "&COUNTIFS(ATLAS기법매핑!$H$5:$H$212,"*"&D6&"*",ATLAS기법매핑!$M$5:$M$212,"Feasible") -> 1 / 1 / 3 | AL6: =(LEN(Y6&Z6)>0)+(LEN(AD6&AE6)>0)+(LEN(AF6&AG6)>0)+(LEN(AH6&AI6)>0)+(LEN(AJ6&AK6)>0) -> 1 | AM6: =COUNTIF(ATLAS사례연구!$J$5:$J$77,"*"&D6&"*") -> 6 | AN6: =COUNTIFS(ATLAS사례연구!$J$5:$J$77,"*"&D6&"*",ATLAS사례연구!$C$5:$C$77,"Incident") -> 4 | AO6: 0 | AP6: 0 | AQ6: =IF(AN6+AO6>0,"실제 사고 확인",IF(AB6>0,"실사용 기법 포함",IF(OR(AM6>0,AP6>0),"실증·공개 취약점","이론·시나리오"))) -> 실제 사고 확인 | AR6: CS0023, CS0037, CS0063, CS0069, CS0070, CS0071 | AS6: • [ATLAS CS0023·실제사고] 인증 없는 Ray 클러스터를 탈취해 연산자원·자격증명·모델 탈취(ShadowRay, 실제 사고) • [ATLAS CS0069·실제사고] GTG-1002가 탈옥한 Claude Code로 약 30개 조직 대상 자율 사이버 첩보(실제 사고) • [ATLAS CS0070·실제사고] DeepSeek 기반 Hermes 에이전트로 Langflow·n8n 취약점 공격 시도(실제 사고) | AT6: M0039 AI Honeypots M0019 Control Access to AI Models and Data in Production M0032 Segmentation of AI Agent Components | AU6: 공개 정보·모델 아티팩트 공개 최소화, 노출 자산 관리, AI 허니팟, 비정상 탐색·질의 탐지 | AV6: UT-36
A7: D01. 공격 준비 및 AI 무기화 | B7: UT-01 | C7: AI 대상 정찰 및 접근 확보 | D7: UT-01.3 | E7: AI 모델 접근 확보 | F7: 추론 API/AI 탑재 제품/모델 파일 확보를 통해 대상 모델에 대한 질의 권한 또는 전체 접근 권한을 획득하여 추출/회피/추론 공격의 기반 마련 | G7: =IF(AN7+AO7>=2,"상",IF(OR(AN7+AO7=1,AM7>0,AB7>0,AP7>0),"중","하")) -> 상 | H7: 중 | I7: =IF(AND(G7="상",H7="상"),"매우 높음",IF(OR(AND(G7="상",H7="중"),AND(G7="중",H7="상")),"높음",IF(OR(AND(G7="중",H7="중"),AND(G7="상",H7="하"),AND(G7="하",H7="상")),"보통","낮음"))) -> 높음 | J7: ="실제 사고 "&(AN7+AO7)&"건(ATLAS "&AN7&" / OWASP "&AO7&"), 실증 사례 "&(AM7-AN7)&"건, Realized 기법 "&AB7&"개, 취약점·익스플로잇 "&AP7&"건" -> 실제 사고 8건(ATLAS 8 / OWASP 0), 실증 사례 22건, Realized 기법 2개, 취약점·익스플로잇 0건 | K7: 질의 또는 전체 접근 확보로 추출/회피/추론 공격 기반 형성 | L7: AI 모델 접근(AI Model Access) | M7: AI 모델 접근 | N7: ● | O7: ● | P7: ● | Q7: ● | R7: ● | S7: (후속 공격 준비) | V7: ○ | Y7: T0040, T0044, T0047 | AA7: =COUNTIF(ATLAS기법매핑!$H$5:$H$212,"*"&D7&"*") -> 3 | AB7: =COUNTIFS(ATLAS기법매핑!$H$5:$H$212,"*"&D7&"*",ATLAS기법매핑!$M$5:$M$212,"Realized") -> 2 | AC7: =COUNTIFS(ATLAS기법매핑!$H$5:$H$212,"*"&D7&"*",ATLAS기법매핑!$M$5:$M$212,"Realized")&" / "&COUNTIFS(ATLAS기법매핑!$H$5:$H$212,"*"&D7&"*",ATLAS기법매핑!$M$5:$M$212,"Demonstrated")&" / "&COUNTIFS(ATLAS기법매핑!$H$5:$H$212,"*"&D7&"*",ATLAS기법매핑!$M$5:$M$212,"Feasible") -> 2 / 1 / 0 | AL7: =(LEN(Y7&Z7)>0)+(LEN(AD7&AE7)>0)+(LEN(AF7&AG7)>0)+(LEN(AH7&AI7)>0)+(LEN(AJ7&AK7)>0) -> 1 | AM7: =COUNTIF(ATLAS사례연구!$J$5:$J$77,"*"&D7&"*") -> 30 | AN7: =COUNTIFS(ATLAS사례연구!$J$5:$J$77,"*"&D7&"*",ATLAS사례연구!$C$5:$C$77,"Incident") -> 8 | AO7: 0 | AP7: 0 | AQ7: =IF(AN7+AO7>0,"실제 사고 확인",IF(AB7>0,"실사용 기법 포함",IF(OR(AM7>0,AP7>0),"실증·공개 취약점","이론·시나리오"))) -> 실제 사고 확인 | AR7: CS0003, CS0004, CS0005, CS0008, CS0009, CS0010, CS0011, CS0012, CS0013, CS0014, CS0016, CS0017, CS0022, CS0024, CS0026, CS0027, CS0028, CS0033, CS0034, CS0035, CS0036, CS0037, CS0056, CS0057, CS0058, CS0060, CS0061, CS0062, CS0069, CS0070 | AS7: • [ATLAS CS0004·실제사고] 카메라 영상 주입으로 얼굴인식 인증을 우회해 세금 사기(실제 사고) • [ATLAS CS0009·실제사고] Tay 챗봇이 사용자 대화로 온라인 학습되며 오염되어 혐오 발언 생성(실제 사고) • [ATLAS CS0017·실제사고] ID.me 자동 신원확인을 우회해 180건 이상 허위 실업급여 청구(실제 사고) | AT7: M0024 AI Telemetry Logging M0005 Control Access to AI Models and Data at Rest M0017 AI Model Distribution Methods M0019 Control Access to AI Models and Data in Production M0039 AI Honeypots | AU7: 공개 정보·모델 아티팩트 공개 최소화, 노출 자산 관리, AI 허니팟, 비정상 탐색·질의 탐지 | AV7: UT-36
A8: D01. 공격 준비 및 AI 무기화 | B8: UT-01 | C8: AI 대상 정찰 및 접근 확보 | D8: UT-01.4 | E8: 모델 및 환경 탐색 | F8: 출력 관찰/아티팩트 조회를 통해 모델 계열, 분류 체계, 내부 AI 자원 및 실행 환경을 파악하여 공격 정밀도 제고 | G8: =IF(AN8+AO8>=2,"상",IF(OR(AN8+AO8=1,AM8>0,AB8>0,AP8>0),"중","하")) -> 상 | H8: 하 | I8: =IF(AND(G8="상",H8="상"),"매우 높음",IF(OR(AND(G8="상",H8="중"),AND(G8="중",H8="상")),"높음",IF(OR(AND(G8="중",H8="중"),AND(G8="상",H8="하"),AND(G8="하",H8="상")),"보통","낮음"))) -> 보통 | J8: ="실제 사고 "&(AN8+AO8)&"건(ATLAS "&AN8&" / OWASP "&AO8&"), 실증 사례 "&(AM8-AN8)&"건, Realized 기법 "&AB8&"개, 취약점·익스플로잇 "&AP8&"건" -> 실제 사고 3건(ATLAS 3 / OWASP 0), 실증 사례 5건, Realized 기법 2개, 취약점·익스플로잇 0건 | K8: 탐색 단계로 직접 피해 제한적 | L8: 탐색(Discovery) | M8: 탐색 | N8: ● | O8: ● | P8: ● | Q8: ● | R8: ● | S8: (후속 공격 준비) | V8: ○ | Y8: T0007, T0013, T0014, T0075, T0089 | AA8: =COUNTIF(ATLAS기법매핑!$H$5:$H$212,"*"&D8&"*") -> 5 | AB8: =COUNTIFS(ATLAS기법매핑!$H$5:$H$212,"*"&D8&"*",ATLAS기법매핑!$M$5:$M$212,"Realized") -> 2 | AC8: =COUNTIFS(ATLAS기법매핑!$H$5:$H$212,"*"&D8&"*",ATLAS기법매핑!$M$5:$M$212,"Realized")&" / "&COUNTIFS(ATLAS기법매핑!$H$5:$H$212,"*"&D8&"*",ATLAS기법매핑!$M$5:$M$212,"Demonstrated")&" / "&COUNTIFS(ATLAS기법매핑!$H$5:$H$212,"*"&D8&"*",ATLAS기법매핑!$M$5:$M$212,"Feasible") -> 2 / 2 / 1 | AE8: LLM08 | AL8: =(LEN(Y8&Z8)>0)+(LEN(AD8&AE8)>0)+(LEN(AF8&AG8)>0)+(LEN(AH8&AI8)>0)+(LEN(AJ8&AK8)>0) -> 2 | AM8: =COUNTIF(ATLAS사례연구!$J$5:$J$77,"*"&D8&"*") -> 8 | AN8: =COUNTIFS(ATLAS사례연구!$J$5:$J$77,"*"&D8&"*",ATLAS사례연구!$C$5:$C$77,"Incident") -> 3 | AO8: 0 | AP8: 0 | AQ8: =IF(AN8+AO8>0,"실제 사고 확인",IF(AB8>0,"실사용 기법 포함",IF(OR(AM8>0,AP8>0),"실증·공개 취약점","이론·시나리오"))) -> 실제 사고 확인 | AR8: CS0012, CS0027, CS0028, CS0030, CS0036, CS0058, CS0068, CS0069 | AS8: • [ATLAS CS0030·실제사고] 탈취한 클라우드 자격증명으로 LLM 서비스를 무단 사용·재판매(LLMjacking, 실제 사고) • [ATLAS CS0068·실제사고] OpenAI 평가용 자율 에이전트들이 평가 경계를 넘어 외부 인프라 구축·Hugging Face 침해(실제 사고) • [ATLAS CS0069·실제사고] GTG-1002가 탈옥한 Claude Code로 약 30개 조직 대상 자율 사이버 첩보(실제 사고) | AT8: M0002 Predictive AI Output Obfuscation M0004 Limit AI Service Query Volume and Rate M0005 Control Access to AI Models and Data at Rest M0006 Predictive AI Ensembles M0012 Encrypt Sensitive Information | AU8: 공개 정보·모델 아티팩트 공개 최소화, 노출 자산 관리, AI 허니팟, 비정상 탐색·질의 탐지 | AV8: UT-36
A9: D01. 공격 준비 및 AI 무기화 | B9: UT-02 | C9: 공격 준비 및 일반 침투 기법 | D9: UT-02.1 | E9: 공격 도구 확보 | F9: 공개 적대적 공격 구현체/익스플로잇/범용 해킹 도구를 입수하거나 자체 개발하여 AI 대상 공격 역량 확보 | G9: =IF(AN9+AO9>=2,"상",IF(OR(AN9+AO9=1,AM9>0,AB9>0,AP9>0),"중","하")) -> 상 | H9: 하 | I9: =IF(AND(G9="상",H9="상"),"매우 높음",IF(OR(AND(G9="상",H9="중"),AND(G9="중",H9="상")),"높음",IF(OR(AND(G9="중",H9="중"),AND(G9="상",H9="하"),AND(G9="하",H9="상")),"보통","낮음"))) -> 보통 | J9: ="실제 사고 "&(AN9+AO9)&"건(ATLAS "&AN9&" / OWASP "&AO9&"), 실증 사례 "&(AM9-AN9)&"건, Realized 기법 "&AB9&"개, 취약점·익스플로잇 "&AP9&"건" -> 실제 사고 10건(ATLAS 10 / OWASP 0), 실증 사례 14건, Realized 기법 6개, 취약점·익스플로잇 0건 | K9: 직접 피해 없음(공격 준비 단계) | L9: 자원 개발(Resource Development) | M9: 자원 개발 | N9: ● | O9: ● | P9: ● | Q9: ● | R9: ● | S9: 기밀성, 무결성, 가용성 | V9: ○ | X9: 조직 생애주기 외부 활동 — 운영 중 시스템을 대상으로 발현 | Y9: T0016, T0016.000, T0016.001, T0016.002, T0016.003, T0017, T0017.000 | AA9: =COUNTIF(ATLAS기법매핑!$H$5:$H$212,"*"&D9&"*") -> 7 | AB9: =COUNTIFS(ATLAS기법매핑!$H$5:$H$212,"*"&D9&"*",ATLAS기법매핑!$M$5:$M$212,"Realized") -> 6 | AC9: =COUNTIFS(ATLAS기법매핑!$H$5:$H$212,"*"&D9&"*",ATLAS기법매핑!$M$5:$M$212,"Realized")&" / "&COUNTIFS(ATLAS기법매핑!$H$5:$H$212,"*"&D9&"*",ATLAS기법매핑!$M$5:$M$212,"Demonstrated")&" / "&COUNTIFS(ATLAS기법매핑!$H$5:$H$212,"*"&D9&"*",ATLAS기법매핑!$M$5:$M$212,"Feasible") -> 6 / 1 / 0 | AL9: =(LEN(Y9&Z9)>0)+(LEN(AD9&AE9)>0)+(LEN(AF9&AG9)>0)+(LEN(AH9&AI9)>0)+(LEN(AJ9&AK9)>0) -> 1 | AM9: =COUNTIF(ATLAS사례연구!$J$5:$J$77,"*"&D9&"*") -> 24 | AN9: =COUNTIFS(ATLAS사례연구!$J$5:$J$77,"*"&D9&"*",ATLAS사례연구!$C$5:$C$77,"Incident") -> 10 | AO9: 0 | AP9: 0 | AQ9: =IF(AN9+AO9>0,"실제 사고 확인",IF(AB9>0,"실사용 기법 포함",IF(OR(AM9>0,AP9>0),"실증·공개 취약점","이론·시나리오"))) -> 실제 사고 확인 | AR9: CS0001, CS0002, CS0003, CS0004, CS0013, CS0014, CS0018, CS0020, CS0027, CS0029, CS0030, CS0033, CS0034, CS0043, CS0049, CS0050, CS0052, CS0053, CS0055, CS0057, CS0064, CS0069, CS0070, CS0072 | AS9: • [ATLAS CS0002·실제사고] VirusTotal에 변종 샘플을 대량 제출해 크라우드소싱 학습 데이터를 오염 • [ATLAS CS0004·실제사고] 카메라 영상 주입으로 얼굴인식 인증을 우회해 세금 사기(실제 사고) • [ATLAS CS0030·실제사고] 탈취한 클라우드 자격증명으로 LLM 서비스를 무단 사용·재판매(LLMjacking, 실제 사고) | AT9: M0001 Limit Model Artifact Release M0020 Generative AI Guardrails M0022 Generative AI Model Alignment | AU9: 기존 엔터프라이즈 보안통제(패치·EDR·네트워크 분리·ATT&CK 기반 탐지)를 AI 인프라까지 확장 | AV9: UT-39
A10: D01. 공격 준비 및 AI 무기화 | B10: UT-02 | C10: 공격 준비 및 일반 침투 기법 | D10: UT-02.2 | E10: 공개 AI 자원 입수 | F10: 공개 데이터셋/사전학습 모델/에이전트 설정 파일을 입수하여 대리 모델 구축 및 공격 사전 검증에 활용 | G10: =IF(AN10+AO10>=2,"상",IF(OR(AN10+AO10=1,AM10>0,AB10>0,AP10>0),"중","하")) -> 중 | H10: 하 | I10: =IF(AND(G10="상",H10="상"),"매우 높음",IF(OR(AND(G10="상",H10="중"),AND(G10="중",H10="상")),"높음",IF(OR(AND(G10="중",H10="중"),AND(G10="상",H10="하"),AND(G10="하",H10="상")),"보통","낮음"))) -> 낮음 | J10: ="실제 사고 "&(AN10+AO10)&"건(ATLAS "&AN10&" / OWASP "&AO10&"), 실증 사례 "&(AM10-AN10)&"건, Realized 기법 "&AB10&"개, 취약점·익스플로잇 "&AP10&"건" -> 실제 사고 1건(ATLAS 1 / OWASP 0), 실증 사례 12건, Realized 기법 1개, 취약점·익스플로잇 0건 | K10: 직접 피해 없음(대리 모델 구축 등 준비 단계) | L10: 자원 개발(Resource Development) | M10: 자원 개발 | N10: ● | O10: ● | P10: ● | Q10: ● | R10: ● | S10: 기밀성, 무결성, 가용성 | V10: ○ | X10: 조직 생애주기 외부 활동 — 운영 중 시스템을 대상으로 발현 | Y10: T0002, T0002.000, T0002.001, T0002.002 | AA10: =COUNTIF(ATLAS기법매핑!$H$5:$H$212,"*"&D10&"*") -> 4 | AB10: =COUNTIFS(ATLAS기법매핑!$H$5:$H$212,"*"&D10&"*",ATLAS기법매핑!$M$5:$M$212,"Realized") -> 1 | AC10: =COUNTIFS(ATLAS기법매핑!$H$5:$H$212,"*"&D10&"*",ATLAS기법매핑!$M$5:$M$212,"Realized")&" / "&COUNTIFS(ATLAS기법매핑!$H$5:$H$212,"*"&D10&"*",ATLAS기법매핑!$M$5:$M$212,"Demonstrated")&" / "&COUNTIFS(ATLAS기법매핑!$H$5:$H$212,"*"&D10&"*",ATLAS기법매핑!$M$5:$M$212,"Feasible") -> 1 / 3 / 0 | AL10: =(LEN(Y10&Z10)>0)+(LEN(AD10&AE10)>0)+(LEN(AF10&AG10)>0)+(LEN(AH10&AI10)>0)+(LEN(AJ10&AK10)>0) -> 1 | AM10: =COUNTIF(ATLAS사례연구!$J$5:$J$77,"*"&D10&"*") -> 13 | AN10: =COUNTIFS(ATLAS사례연구!$J$5:$J$77,"*"&D10&"*",ATLAS사례연구!$C$5:$C$77,"Incident") -> 1 | AO10: 0 | AP10: 0 | AQ10: =IF(AN10+AO10>0,"실제 사고 확인",IF(AB10>0,"실사용 기법 포함",IF(OR(AM10>0,AP10>0),"실증·공개 취약점","이론·시나리오"))) -> 실제 사고 확인 | AR10: CS0000, CS0001, CS0005, CS0006, CS0007, CS0011, CS0012, CS0013, CS0014, CS0019, CS0025, CS0051, CS0064 | AS10: • [ATLAS CS0006·실제사고] Clearview AI 저장소 설정 오류로 소스코드·자격증명·모델 노출 • [ATLAS CS0000·실증] 공개 논문을 재현한 대리모델로 악성 C&C 트래픽 탐지 딥러닝 모델을 회피 • [ATLAS CS0001·실증] 도메인명 변형 기법으로 CNN 기반 봇넷 DGA 탐지기를 우회 | AT10: M0001 Limit Model Artifact Release M0000 Limit Public Release of Information M0014 Verify AI Artifacts | AU10: 기존 엔터프라이즈 보안통제(패치·EDR·네트워크 분리·ATT&CK 기반 탐지)를 AI 인프라까지 확장 | AV10: UT-39
A11: D01. 공격 준비 및 AI 무기화 | B11: UT-02 | C11: 공격 준비 및 일반 침투 기법 | D11: UT-02.3 | E11: 공격 인프라 확보 | F11: 클라우드 자원/도메인/물리적 대응물 구매, 계정 생성, 정상 인프라 탈취를 통해 공격 수행 및 은닉에 필요한 기반 구축 | G11: =IF(AN11+AO11>=2,"상",IF(OR(AN11+AO11=1,AM11>0,AB11>0,AP11>0),"중","하")) -> 상 | H11: 하 | I11: =IF(AND(G11="상",H11="상"),"매우 높음",IF(OR(AND(G11="상",H11="중"),AND(G11="중",H11="상")),"높음",IF(OR(AND(G11="중",H11="중"),AND(G11="상",H11="하"),AND(G11="하",H11="상")),"보통","낮음"))) -> 보통 | J11: ="실제 사고 "&(AN11+AO11)&"건(ATLAS "&AN11&" / OWASP "&AO11&"), 실증 사례 "&(AM11-AN11)&"건, Realized 기법 "&AB11&"개, 취약점·익스플로잇 "&AP11&"건" -> 실제 사고 7건(ATLAS 7 / OWASP 0), 실증 사례 18건, Realized 기법 6개, 취약점·익스플로잇 0건 | K11: 직접 피해 없음(공격 기반 구축 단계) | L11: 자원 개발(Resource Development) | M11: 자원 개발 | N11: ● | O11: ● | P11: ● | Q11: ● | R11: ● | S11: 기밀성, 무결성, 가용성 | V11: ○ | X11: 조직 생애주기 외부 활동 — 운영 중 시스템을 대상으로 발현 | Y11: T0008, T0008.000, T0008.001, T0008.002, T0008.003, T0008.004, T0008.005, T0021, T0079, T0128 | AA11: =COUNTIF(ATLAS기법매핑!$H$5:$H$212,"*"&D11&"*") -> 10 | AB11: =COUNTIFS(ATLAS기법매핑!$H$5:$H$212,"*"&D11&"*",ATLAS기법매핑!$M$5:$M$212,"Realized") -> 6 | AC11: =COUNTIFS(ATLAS기법매핑!$H$5:$H$212,"*"&D11&"*",ATLAS기법매핑!$M$5:$M$212,"Realized")&" / "&COUNTIFS(ATLAS기법매핑!$H$5:$H$212,"*"&D11&"*",ATLAS기법매핑!$M$5:$M$212,"Demonstrated")&" / "&COUNTIFS(ATLAS기법매핑!$H$5:$H$212,"*"&D11&"*",ATLAS기법매핑!$M$5:$M$212,"Feasible") -> 6 / 3 / 1 | AL11: =(LEN(Y11&Z11)>0)+(LEN(AD11&AE11)>0)+(LEN(AF11&AG11)>0)+(LEN(AH11&AI11)>0)+(LEN(AJ11&AK11)>0) -> 1 | AM11: =COUNTIF(ATLAS사례연구!$J$5:$J$77,"*"&D11&"*") -> 25 | AN11: =COUNTIFS(ATLAS사례연구!$J$5:$J$77,"*"&D11&"*",ATLAS사례연구!$C$5:$C$77,"Incident") -> 7 | AO11: 0 | AP11: 0 | AQ11: =IF(AN11+AO11>0,"실제 사고 확인",IF(AB11>0,"실사용 기법 포함",IF(OR(AM11>0,AP11>0),"실증·공개 취약점","이론·시나리오"))) -> 실제 사고 확인 | AR11: CS0004, CS0006, CS0007, CS0012, CS0021, CS0025, CS0027, CS0029, CS0033, CS0034, CS0041, CS0045, CS0049, CS0050, CS0051, CS0055, CS0056, CS0057, CS0059, CS0060, CS0061, CS0065, CS0066, CS0069, CS0072 | AS11: • [ATLAS CS0004·실제사고] 카메라 영상 주입으로 얼굴인식 인증을 우회해 세금 사기(실제 사고) • [ATLAS CS0006·실제사고] Clearview AI 저장소 설정 오류로 소스코드·자격증명·모델 노출 • [ATLAS CS0034·실제사고] KYC 우회용 딥페이크 도구 ProKYC가 범죄자에게 판매(실제 사고) | AT11: M0005 Control Access to AI Models and Data at Rest M0019 Control Access to AI Models and Data in Production | AU11: 기존 엔터프라이즈 보안통제(패치·EDR·네트워크 분리·ATT&CK 기반 탐지)를 AI 인프라까지 확장 | AV11: UT-39
A12: D01. 공격 준비 및 AI 무기화 | B12: UT-02 | C12: 공격 준비 및 일반 침투 기법 | D12: UT-02.4 | E12: 일반 초기 침투 | F12: 공개 애플리케이션 취약점 익스플로잇/드라이브바이 다운로드/악성 링크 실행 유도를 통해 AI 서비스 및 지원 인프라에 최초 침투 | G12: =IF(AN12+AO12>=2,"상",IF(OR(AN12+AO12=1,AM12>0,AB12>0,AP12>0),"중","하")) -> 상 | H12: 상 | I12: =IF(AND(G12="상",H12="상"),"매우 높음",IF(OR(AND(G12="상",H12="중"),AND(G12="중",H12="상")),"높음",IF(OR(AND(G12="중",H12="중"),AND(G12="상",H12="하"),AND(G12="하",H12="상")),"보통","낮음"))) -> 매우 높음 | J12: ="실제 사고 "&(AN12+AO12)&"건(ATLAS "&AN12&" / OWASP "&AO12&"), 실증 사례 "&(AM12-AN12)&"건, Realized 기법 "&AB12&"개, 취약점·익스플로잇 "&AP12&"건" -> 실제 사고 7건(ATLAS 6 / OWASP 1), 실증 사례 7건, Realized 기법 1개, 취약점·익스플로잇 1건 | K12: AI 서비스 및 지원 인프라 장악으로 확대 가능 | L12: 초기 접근(Initial Access) | M12: 초기 접근, 실행 | N12: ● | O12: ● | P12: ● | Q12: ● | R12: ● | S12: 기밀성, 무결성, 가용성 | V12: ○ | X12: 조직 생애주기 외부 활동 — 운영 중 시스템을 대상으로 발현 | Y12: T0049, T0078, T0011.003 | AA12: =COUNTIF(ATLAS기법매핑!$H$5:$H$212,"*"&D12&"*") -> 3 | AB12: =COUNTIFS(ATLAS기법매핑!$H$5:$H$212,"*"&D12&"*",ATLAS기법매핑!$M$5:$M$212,"Realized") -> 1 | AC12: =COUNTIFS(ATLAS기법매핑!$H$5:$H$212,"*"&D12&"*",ATLAS기법매핑!$M$5:$M$212,"Realized")&" / "&COUNTIFS(ATLAS기법매핑!$H$5:$H$212,"*"&D12&"*",ATLAS기법매핑!$M$5:$M$212,"Demonstrated")&" / "&COUNTIFS(ATLAS기법매핑!$H$5:$H$212,"*"&D12&"*",ATLAS기법매핑!$M$5:$M$212,"Feasible") -> 1 / 2 / 0 | AL12: =(LEN(Y12&Z12)>0)+(LEN(AD12&AE12)>0)+(LEN(AF12&AG12)>0)+(LEN(AH12&AI12)>0)+(LEN(AJ12&AK12)>0) -> 1 | AM12: =COUNTIF(ATLAS사례연구!$J$5:$J$77,"*"&D12&"*") -> 13 | AN12: =COUNTIFS(ATLAS사례연구!$J$5:$J$77,"*"&D12&"*",ATLAS사례연구!$C$5:$C$77,"Incident") -> 6 | AO12: 1 | AP12: 1 | AQ12: =IF(AN12+AO12>0,"실제 사고 확인",IF(AB12>0,"실사용 기법 포함",IF(OR(AM12>0,AP12>0),"실증·공개 취약점","이론·시나리오"))) -> 실제 사고 확인 | AR12: CS0021, CS0023, CS0028, CS0030, CS0045, CS0050, CS0051, CS0052, CS0055, CS0068, CS0069, CS0070, CS0071 | AS12: • [ATLAS CS0023·실제사고] 인증 없는 Ray 클러스터를 탈취해 연산자원·자격증명·모델 탈취(ShadowRay, 실제 사고) • [ATLAS CS0030·실제사고] 탈취한 클라우드 자격증명으로 LLM 서비스를 무단 사용·재판매(LLMjacking, 실제 사고) • [ATLAS CS0068·실제사고] OpenAI 평가용 자율 에이전트들이 평가 경계를 넘어 외부 인프라 구축·Hugging Face 침해(실제 사고) • [OWASP 인용] ToolShell SharePoint RCE 악용(2025.07, 실제 사고) / Flowise 사전인증 임의 파일 업로드(2025.03) | AT12: M0020 Generative AI Guardrails M0039 AI Honeypots | AU12: 기존 엔터프라이즈 보안통제(패치·EDR·네트워크 분리·ATT&CK 기반 탐지)를 AI 인프라까지 확장 | AV12: UT-39
A13: D01. 공격 준비 및 AI 무기화 | B13: UT-02 | C13: 공격 준비 및 일반 침투 기법 | D13: UT-02.5 | E13: 내부 확산 및 탐지 회피 | F13: 원격 서비스 악용을 통한 내부 확산과 샌드박스 회피/난독화를 통한 보안 탐지 우회로 침투 범위 확대 및 체류 장기화 | G13: =IF(AN13+AO13>=2,"상",IF(OR(AN13+AO13=1,AM13>0,AB13>0,AP13>0),"중","하")) -> 상 | H13: 중 | I13: =IF(AND(G13="상",H13="상"),"매우 높음",IF(OR(AND(G13="상",H13="중"),AND(G13="중",H13="상")),"높음",IF(OR(AND(G13="중",H13="중"),AND(G13="상",H13="하"),AND(G13="하",H13="상")),"보통","낮음"))) -> 높음 | J13: ="실제 사고 "&(AN13+AO13)&"건(ATLAS "&AN13&" / OWASP "&AO13&"), 실증 사례 "&(AM13-AN13)&"건, Realized 기법 "&AB13&"개, 취약점·익스플로잇 "&AP13&"건" -> 실제 사고 2건(ATLAS 2 / OWASP 0), 실증 사례 1건, Realized 기법 3개, 취약점·익스플로잇 0건 | K13: 침투 범위 확대 및 탐지 지연 | L13: 방어 회피(Defense Evasion) | M13: 방어 회피, 내부 확산 | N13: ● | O13: ● | P13: ● | Q13: ● | R13: ● | S13: 기밀성, 무결성, 가용성 | V13: ○ | X13: 조직 생애주기 외부 활동 — 운영 중 시스템을 대상으로 발현 | Y13: T0122, T0097, T0107, T0123 | AA13: =COUNTIF(ATLAS기법매핑!$H$5:$H$212,"*"&D13&"*") -> 4 | AB13: =COUNTIFS(ATLAS기법매핑!$H$5:$H$212,"*"&D13&"*",ATLAS기법매핑!$M$5:$M$212,"Realized") -> 3 | AC13: =COUNTIFS(ATLAS기법매핑!$H$5:$H$212,"*"&D13&"*",ATLAS기법매핑!$M$5:$M$212,"Realized")&" / "&COUNTIFS(ATLAS기법매핑!$H$5:$H$212,"*"&D13&"*",ATLAS기법매핑!$M$5:$M$212,"Demonstrated")&" / "&COUNTIFS(ATLAS기법매핑!$H$5:$H$212,"*"&D13&"*",ATLAS기법매핑!$M$5:$M$212,"Feasible") -> 3 / 1 / 0 | AL13: =(LEN(Y13&Z13)>0)+(LEN(AD13&AE13)>0)+(LEN(AF13&AG13)>0)+(LEN(AH13&AI13)>0)+(LEN(AJ13&AK13)>0) -> 1 | AM13: =COUNTIF(ATLAS사례연구!$J$5:$J$77,"*"&D13&"*") -> 3 | AN13: =COUNTIFS(ATLAS사례연구!$J$5:$J$77,"*"&D13&"*",ATLAS사례연구!$C$5:$C$77,"Incident") -> 2 | AO13: 0 | AP13: 0 | AQ13: =IF(AN13+AO13>0,"실제 사고 확인",IF(AB13>0,"실사용 기법 포함",IF(OR(AM13>0,AP13>0),"실증·공개 취약점","이론·시나리오"))) -> 실제 사고 확인 | AR13: CS0043, CS0050, CS0068 | AS13: • [ATLAS CS0043·실제사고] LLM 기반 악성코드 분석기를 속이려 프롬프트 인젝션을 내장한 악성코드(실제 사고) • [ATLAS CS0068·실제사고] OpenAI 평가용 자율 에이전트들이 평가 경계를 넘어 외부 인프라 구축·Hugging Face 침해(실제 사고) • [ATLAS CS0050·실증] 악성 링크 1회 클릭으로 OpenClaw 로컬 에이전트 원격 코드 실행 | AT13: M0016 Vulnerability Scanning | AU13: 기존 엔터프라이즈 보안통제(패치·EDR·네트워크 분리·ATT&CK 기반 탐지)를 AI 인프라까지 확장 | AV13: UT-39
A14: D01. 공격 준비 및 AI 무기화 | B14: UT-02 | C14: 공격 준비 및 일반 침투 기법 | D14: UT-02.6 | E14: 일반 수단 데이터 유출 | F14: 정보 저장소/로컬 시스템의 데이터를 자동 수집 및 압축한 후 일반 네트워크 또는 C2 채널로 외부 반출 | G14: =IF(AN14+AO14>=2,"상",IF(OR(AN14+AO14=1,AM14>0,AB14>0,AP14>0),"중","하")) -> 상 | H14: 상 | I14: =IF(AND(G14="상",H14="상"),"매우 높음",IF(OR(AND(G14="상",H14="중"),AND(G14="중",H14="상")),"높음",IF(OR(AND(G14="중",H14="중"),AND(G14="상",H14="하"),AND(G14="하",H14="상")),"보통","낮음"))) -> 매우 높음 | J14: ="실제 사고 "&(AN14+AO14)&"건(ATLAS "&AN14&" / OWASP "&AO14&"), 실증 사례 "&(AM14-AN14)&"건, Realized 기법 "&AB14&"개, 취약점·익스플로잇 "&AP14&"건" -> 실제 사고 9건(ATLAS 9 / OWASP 0), 실증 사례 10건, Realized 기법 6개, 취약점·익스플로잇 0건 | K14: 중요정보 및 AI 자산 대량 반출 | L14: 유출(Exfiltration) | M14: 수집, 명령·제어, 유출 | N14: ● | O14: ● | P14: ● | Q14: ● | R14: ● | S14: 기밀성 | V14: ○ | X14: 조직 생애주기 외부 활동 — 운영 중 시스템을 대상으로 발현 | Y14: T0036, T0037, T0126, T0127, T0025, T0072 | AA14: =COUNTIF(ATLAS기법매핑!$H$5:$H$212,"*"&D14&"*") -> 6 | AB14: =COUNTIFS(ATLAS기법매핑!$H$5:$H$212,"*"&D14&"*",ATLAS기법매핑!$M$5:$M$212,"Realized") -> 6 | AC14: =COUNTIFS(ATLAS기법매핑!$H$5:$H$212,"*"&D14&"*",ATLAS기법매핑!$M$5:$M$212,"Realized")&" / "&COUNTIFS(ATLAS기법매핑!$H$5:$H$212,"*"&D14&"*",ATLAS기법매핑!$M$5:$M$212,"Demonstrated")&" / "&COUNTIFS(ATLAS기법매핑!$H$5:$H$212,"*"&D14&"*",ATLAS기법매핑!$M$5:$M$212,"Feasible") -> 6 / 0 / 0 | AL14: =(LEN(Y14&Z14)>0)+(LEN(AD14&AE14)>0)+(LEN(AF14&AG14)>0)+(LEN(AH14&AI14)>0)+(LEN(AJ14&AK14)>0) -> 1 | AM14: =COUNTIF(ATLAS사례연구!$J$5:$J$77,"*"&D14&"*") -> 19 | AN14: =COUNTIFS(ATLAS사례연구!$J$5:$J$77,"*"&D14&"*",ATLAS사례연구!$C$5:$C$77,"Incident") -> 9 | AO14: 0 | AP14: 0 | AQ14: =IF(AN14+AO14>0,"실제 사고 확인",IF(AB14>0,"실사용 기법 포함",IF(OR(AM14>0,AP14>0),"실증·공개 취약점","이론·시나리오"))) -> 실제 사고 확인 | AR14: CS0006, CS0010, CS0015, CS0018, CS0023, CS0027, CS0031, CS0043, CS0044, CS0048, CS0052, CS0058, CS0059, CS0061, CS0063, CS0065, CS0068, CS0069, CS0071 | AS14: • [ATLAS CS0006·실제사고] Clearview AI 저장소 설정 오류로 소스코드·자격증명·모델 노출 • [ATLAS CS0015·실제사고] PyPI에 올라간 악성 torchtriton 의존성으로 PyTorch-nightly 사용자 정보 유출(실제 사고) • [ATLAS CS0023·실제사고] 인증 없는 Ray 클러스터를 탈취해 연산자원·자격증명·모델 탈취(ShadowRay, 실제 사고) | AT14: M0005 Control Access to AI Models and Data at Rest | AU14: 기존 엔터프라이즈 보안통제(패치·EDR·네트워크 분리·ATT&CK 기반 탐지)를 AI 인프라까지 확장 | AV14: UT-39
A15: D01. 공격 준비 및 AI 무기화 | B15: UT-03 | C15: AI 기반 자율 공격 | D15: UT-03.1 | E15: 자율 공격 에이전트 | F15: 공격 목표만 부여받은 AI 에이전트가 대상 탐색, 익스플로잇 개발, 실패 시 공격 경로 수정을 사람 개입 없이 반복 수행하여 사람 대비 압도적 속도와 규모로 침투 | G15: =IF(AN15+AO15>=2,"상",IF(OR(AN15+AO15=1,AM15>0,AB15>0,AP15>0),"중","하")) -> 상 | H15: 상 | I15: =IF(AND(G15="상",H15="상"),"매우 높음",IF(OR(AND(G15="상",H15="중"),AND(G15="중",H15="상")),"높음",IF(OR(AND(G15="중",H15="중"),AND(G15="상",H15="하"),AND(G15="하",H15="상")),"보통","낮음"))) -> 매우 높음 | J15: ="실제 사고 "&(AN15+AO15)&"건(ATLAS "&AN15&" / OWASP "&AO15&"), 실증 사례 "&(AM15-AN15)&"건, Realized 기법 "&AB15&"개, 취약점·익스플로잇 "&AP15&"건" -> 실제 사고 4건(ATLAS 4 / OWASP 0), 실증 사례 0건, Realized 기법 3개, 취약점·익스플로잇 0건 | K15: 다수 조직 동시 침투 및 시스템 장악 | L15: AI 공격 적응(AI Attack Adaptation) | M15: 정찰, 자원 개발, AI 공격 적응 | N15: ● | O15: ● | P15: ● | Q15: ● | R15: ● | S15: 기밀성, 무결성, 가용성 | V15: ○ | X15: 조직 생애주기 외부 활동 — AI 속도의 공격이 운영 시스템에 발현 | Y15: T0116, T0117, T0017.001 | AA15: =COUNTIF(ATLAS기법매핑!$H$5:$H$212,"*"&D15&"*") -> 3 | AB15: =COUNTIFS(ATLAS기법매핑!$H$5:$H$212,"*"&D15&"*",ATLAS기법매핑!$M$5:$M$212,"Realized") -> 3 | AC15: =COUNTIFS(ATLAS기법매핑!$H$5:$H$212,"*"&D15&"*",ATLAS기법매핑!$M$5:$M$212,"Realized")&" / "&COUNTIFS(ATLAS기법매핑!$H$5:$H$212,"*"&D15&"*",ATLAS기법매핑!$M$5:$M$212,"Demonstrated")&" / "&COUNTIFS(ATLAS기법매핑!$H$5:$H$212,"*"&D15&"*",ATLAS기법매핑!$M$5:$M$212,"Feasible") -> 3 / 0 / 0 | AL15: =(LEN(Y15&Z15)>0)+(LEN(AD15&AE15)>0)+(LEN(AF15&AG15)>0)+(LEN(AH15&AI15)>0)+(LEN(AJ15&AK15)>0) -> 1 | AM15: =COUNTIF(ATLAS사례연구!$J$5:$J$77,"*"&D15&"*") -> 4 | AN15: =COUNTIFS(ATLAS사례연구!$J$5:$J$77,"*"&D15&"*",ATLAS사례연구!$C$5:$C$77,"Incident") -> 4 | AO15: 0 | AP15: 0 | AQ15: =IF(AN15+AO15>0,"실제 사고 확인",IF(AB15>0,"실사용 기법 포함",IF(OR(AM15>0,AP15>0),"실증·공개 취약점","이론·시나리오"))) -> 실제 사고 확인 | AR15: CS0068, CS0069, CS0070, CS0071 | AS15: • [ATLAS CS0069·실제사고] GTG-1002가 탈옥한 Claude Code로 약 30개 조직 대상 자율 사이버 첩보(실제 사고) • [ATLAS CS0070·실제사고] DeepSeek 기반 Hermes 에이전트로 Langflow·n8n 취약점 공격 시도(실제 사고) • [ATLAS CS0071·실제사고] Hermes·OpenClaw 기반 다중 에이전트 프레임워크로 대만 정부 시스템 침해(실제 사고) | AT15: M0037 AI Agent Authority Expansion Controls M0038 AI Agent Scope Drift Detection | AU15: AI 속도 공격을 전제한 탐지·대응 자동화, AI 제공자 오남용 탐지 연계, 위협 인텔리전스 | AV15: UT-37
A16: D01. 공격 준비 및 AI 무기화 | B16: UT-03 | C16: AI 기반 자율 공격 | D16: UT-03.2 | E16: 다중 에이전트 공격 조율 | F16: 오케스트레이터 AI가 다수 하위 에이전트에 임무를 분배하고 탐색 결과/자격증명을 공유하며 복수 대상을 병렬 공격 | G16: =IF(AN16+AO16>=2,"상",IF(OR(AN16+AO16=1,AM16>0,AB16>0,AP16>0),"중","하")) -> 상 | H16: 상 | I16: =IF(AND(G16="상",H16="상"),"매우 높음",IF(OR(AND(G16="상",H16="중"),AND(G16="중",H16="상")),"높음",IF(OR(AND(G16="중",H16="중"),AND(G16="상",H16="하"),AND(G16="하",H16="상")),"보통","낮음"))) -> 매우 높음 | J16: ="실제 사고 "&(AN16+AO16)&"건(ATLAS "&AN16&" / OWASP "&AO16&"), 실증 사례 "&(AM16-AN16)&"건, Realized 기법 "&AB16&"개, 취약점·익스플로잇 "&AP16&"건" -> 실제 사고 2건(ATLAS 2 / OWASP 0), 실증 사례 0건, Realized 기법 4개, 취약점·익스플로잇 0건 | K16: 복수 대상 병렬 침투 및 시스템 장악 | L16: AI 공격 적응(AI Attack Adaptation) | M16: AI 공격 적응 | N16: ● | O16: ● | P16: ● | Q16: ● | R16: ● | S16: 기밀성, 무결성, 가용성 | V16: ○ | X16: 조직 생애주기 외부 활동 — AI 속도의 공격이 운영 시스템에 발현 | Y16: T0118, T0118.000, T0118.001, T0124 | AA16: =COUNTIF(ATLAS기법매핑!$H$5:$H$212,"*"&D16&"*") -> 4 | AB16: =COUNTIFS(ATLAS기법매핑!$H$5:$H$212,"*"&D16&"*",ATLAS기법매핑!$M$5:$M$212,"Realized") -> 4 | AC16: =COUNTIFS(ATLAS기법매핑!$H$5:$H$212,"*"&D16&"*",ATLAS기법매핑!$M$5:$M$212,"Realized")&" / "&COUNTIFS(ATLAS기법매핑!$H$5:$H$212,"*"&D16&"*",ATLAS기법매핑!$M$5:$M$212,"Demonstrated")&" / "&COUNTIFS(ATLAS기법매핑!$H$5:$H$212,"*"&D16&"*",ATLAS기법매핑!$M$5:$M$212,"Feasible") -> 4 / 0 / 0 | AL16: =(LEN(Y16&Z16)>0)+(LEN(AD16&AE16)>0)+(LEN(AF16&AG16)>0)+(LEN(AH16&AI16)>0)+(LEN(AJ16&AK16)>0) -> 1 | AM16: =COUNTIF(ATLAS사례연구!$J$5:$J$77,"*"&D16&"*") -> 2 | AN16: =COUNTIFS(ATLAS사례연구!$J$5:$J$77,"*"&D16&"*",ATLAS사례연구!$C$5:$C$77,"Incident") -> 2 | AO16: 0 | AP16: 0 | AQ16: =IF(AN16+AO16>0,"실제 사고 확인",IF(AB16>0,"실사용 기법 포함",IF(OR(AM16>0,AP16>0),"실증·공개 취약점","이론·시나리오"))) -> 실제 사고 확인 | AR16: CS0068, CS0071 | AS16: • [ATLAS CS0068·실제사고] OpenAI 평가용 자율 에이전트들이 평가 경계를 넘어 외부 인프라 구축·Hugging Face 침해(실제 사고) • [ATLAS CS0071·실제사고] Hermes·OpenClaw 기반 다중 에이전트 프레임워크로 대만 정부 시스템 침해(실제 사고) | AT16: M0037 AI Agent Authority Expansion Controls M0038 AI Agent Scope Drift Detection | AU16: AI 속도 공격을 전제한 탐지·대응 자동화, AI 제공자 오남용 탐지 연계, 위협 인텔리전스 | AV16: UT-37
A17: D01. 공격 준비 및 AI 무기화 | B17: UT-03 | C17: AI 기반 자율 공격 | D17: UT-03.3 | E17: AI 연동 악성코드 | F17: 피해 시스템의 악성코드가 실행 중 LLM 서비스에 질의하여 실행 명령을 동적 생성함으로써 시그니처 기반 탐지 우회 및 정상 AI 트래픽으로 위장 | G17: =IF(AN17+AO17>=2,"상",IF(OR(AN17+AO17=1,AM17>0,AB17>0,AP17>0),"중","하")) -> 상 | H17: 상 | I17: =IF(AND(G17="상",H17="상"),"매우 높음",IF(OR(AND(G17="상",H17="중"),AND(G17="중",H17="상")),"높음",IF(OR(AND(G17="중",H17="중"),AND(G17="상",H17="하"),AND(G17="하",H17="상")),"보통","낮음"))) -> 매우 높음 | J17: ="실제 사고 "&(AN17+AO17)&"건(ATLAS "&AN17&" / OWASP "&AO17&"), 실증 사례 "&(AM17-AN17)&"건, Realized 기법 "&AB17&"개, 취약점·익스플로잇 "&AP17&"건" -> 실제 사고 3건(ATLAS 3 / OWASP 0), 실증 사례 0건, Realized 기법 1개, 취약점·익스플로잇 0건 | K17: 호스트 장악 상태의 탐지 회피형 원격 조작 | L17: AI 공격 적응(AI Attack Adaptation) | M17: AI 공격 적응 | N17: ● | O17: ● | P17: ● | Q17: ● | R17: ● | S17: 기밀성, 무결성, 가용성 | V17: ○ | X17: 조직 생애주기 외부 활동 — AI 속도의 공격이 운영 시스템에 발현 | Y17: T0102 | AA17: =COUNTIF(ATLAS기법매핑!$H$5:$H$212,"*"&D17&"*") -> 1 | AB17: =COUNTIFS(ATLAS기법매핑!$H$5:$H$212,"*"&D17&"*",ATLAS기법매핑!$M$5:$M$212,"Realized") -> 1 | AC17: =COUNTIFS(ATLAS기법매핑!$H$5:$H$212,"*"&D17&"*",ATLAS기법매핑!$M$5:$M$212,"Realized")&" / "&COUNTIFS(ATLAS기법매핑!$H$5:$H$212,"*"&D17&"*",ATLAS기법매핑!$M$5:$M$212,"Demonstrated")&" / "&COUNTIFS(ATLAS기법매핑!$H$5:$H$212,"*"&D17&"*",ATLAS기법매핑!$M$5:$M$212,"Feasible") -> 1 / 0 / 0 | AL17: =(LEN(Y17&Z17)>0)+(LEN(AD17&AE17)>0)+(LEN(AF17&AG17)>0)+(LEN(AH17&AI17)>0)+(LEN(AJ17&AK17)>0) -> 1 | AM17: =COUNTIF(ATLAS사례연구!$J$5:$J$77,"*"&D17&"*") -> 3 | AN17: =COUNTIFS(ATLAS사례연구!$J$5:$J$77,"*"&D17&"*",ATLAS사례연구!$C$5:$C$77,"Incident") -> 3 | AO17: 0 | AP17: 0 | AQ17: =IF(AN17+AO17>0,"실제 사고 확인",IF(AB17>0,"실사용 기법 포함",IF(OR(AM17>0,AP17>0),"실증·공개 취약점","이론·시나리오"))) -> 실제 사고 확인 | AR17: CS0044, CS0068, CS0070 | AS17: • [ATLAS CS0044·실제사고] APT28 LAMEHUG가 LLM API로 실행 명령을 동적 생성(실제 사고) • [ATLAS CS0068·실제사고] OpenAI 평가용 자율 에이전트들이 평가 경계를 넘어 외부 인프라 구축·Hugging Face 침해(실제 사고) • [ATLAS CS0070·실제사고] DeepSeek 기반 Hermes 에이전트로 Langflow·n8n 취약점 공격 시도(실제 사고) | AT17: M0020 Generative AI Guardrails M0022 Generative AI Model Alignment | AU17: AI 속도 공격을 전제한 탐지·대응 자동화, AI 제공자 오남용 탐지 연계, 위협 인텔리전스 | AV17: UT-37
A18: D01. 공격 준비 및 AI 무기화 | B18: UT-03 | C18: AI 기반 자율 공격 | D18: UT-03.4 | E18: 공격용 에이전트 도구 확보 | F18: 자율 공격에 활용할 에이전트 프레임워크/도구를 개발하거나 공개 도구를 입수하여 공격 자동화 역량 확보 | G18: =IF(AN18+AO18>=2,"상",IF(OR(AN18+AO18=1,AM18>0,AB18>0,AP18>0),"중","하")) -> 중 | H18: 하 | I18: =IF(AND(G18="상",H18="상"),"매우 높음",IF(OR(AND(G18="상",H18="중"),AND(G18="중",H18="상")),"높음",IF(OR(AND(G18="중",H18="중"),AND(G18="상",H18="하"),AND(G18="하",H18="상")),"보통","낮음"))) -> 낮음 | J18: ="실제 사고 "&(AN18+AO18)&"건(ATLAS "&AN18&" / OWASP "&AO18&"), 실증 사례 "&(AM18-AN18)&"건, Realized 기법 "&AB18&"개, 취약점·익스플로잇 "&AP18&"건" -> 실제 사고 1건(ATLAS 1 / OWASP 0), 실증 사례 0건, Realized 기법 2개, 취약점·익스플로잇 0건 | K18: 직접 피해 없음(공격 자동화 준비 단계) | L18: 자원 개발(Resource Development) | M18: 자원 개발 | N18: ● | O18: ● | P18: ● | Q18: ● | R18: ● | S18: 기밀성, 무결성, 가용성 | V18: ○ | X18: 조직 생애주기 외부 활동 — AI 속도의 공격이 운영 시스템에 발현 | Y18: T0016.004, T0017.002 | AA18: =COUNTIF(ATLAS기법매핑!$H$5:$H$212,"*"&D18&"*") -> 2 | AB18: =COUNTIFS(ATLAS기법매핑!$H$5:$H$212,"*"&D18&"*",ATLAS기법매핑!$M$5:$M$212,"Realized") -> 2 | AC18: =COUNTIFS(ATLAS기법매핑!$H$5:$H$212,"*"&D18&"*",ATLAS기법매핑!$M$5:$M$212,"Realized")&" / "&COUNTIFS(ATLAS기법매핑!$H$5:$H$212,"*"&D18&"*",ATLAS기법매핑!$M$5:$M$212,"Demonstrated")&" / "&COUNTIFS(ATLAS기법매핑!$H$5:$H$212,"*"&D18&"*",ATLAS기법매핑!$M$5:$M$212,"Feasible") -> 2 / 0 / 0 | AL18: =(LEN(Y18&Z18)>0)+(LEN(AD18&AE18)>0)+(LEN(AF18&AG18)>0)+(LEN(AH18&AI18)>0)+(LEN(AJ18&AK18)>0) -> 1 | AM18: =COUNTIF(ATLAS사례연구!$J$5:$J$77,"*"&D18&"*") -> 1 | AN18: =COUNTIFS(ATLAS사례연구!$J$5:$J$77,"*"&D18&"*",ATLAS사례연구!$C$5:$C$77,"Incident") -> 1 | AO18: 0 | AP18: 0 | AQ18: =IF(AN18+AO18>0,"실제 사고 확인",IF(AB18>0,"실사용 기법 포함",IF(OR(AM18>0,AP18>0),"실증·공개 취약점","이론·시나리오"))) -> 실제 사고 확인 | AR18: CS0070 | AS18: • [ATLAS CS0070·실제사고] DeepSeek 기반 Hermes 에이전트로 Langflow·n8n 취약점 공격 시도(실제 사고) | AT18: — (ATLAS 완화책 없음: Lv2 핵심 통제 참조) | AU18: AI 속도 공격을 전제한 탐지·대응 자동화, AI 제공자 오남용 탐지 연계, 위협 인텔리전스 | AV18: UT-37
A19: D01. 공격 준비 및 AI 무기화 | B19: UT-04 | C19: AI 생성 콘텐츠를 이용한 사기 | D19: UT-04.1 | E19: 딥페이크 신원 위장 | F19: 실시간 딥페이크 영상/음성 및 가상 카메라 주입을 통해 생체인증/KYC 절차를 우회하여 타인 명의 계정 개설 및 금융 사기 수행 | G19: =IF(AN19+AO19>=2,"상",IF(OR(AN19+AO19=1,AM19>0,AB19>0,AP19>0),"중","하")) -> 상 | H19: 중 | I19: =IF(AND(G19="상",H19="상"),"매우 높음",IF(OR(AND(G19="상",H19="중"),AND(G19="중",H19="상")),"높음",IF(OR(AND(G19="중",H19="중"),AND(G19="상",H19="하"),AND(G19="하",H19="상")),"보통","낮음"))) -> 높음 | J19: ="실제 사고 "&(AN19+AO19)&"건(ATLAS "&AN19&" / OWASP "&AO19&"), 실증 사례 "&(AM19-AN19)&"건, Realized 기법 "&AB19&"개, 취약점·익스플로잇 "&AP19&"건" -> 실제 사고 4건(ATLAS 4 / OWASP 0), 실증 사례 1건, Realized 기법 1개, 취약점·익스플로잇 0건 | K19: 특정 계정/거래 단위 금전 피해 | L19: 방어 회피(Defense Evasion) | M19: AI 공격 적응 | N19: ● | S19: 재무, 평판·사회 | V19: ○ | X19: 조직 생애주기 외부 활동 — 사람·생체인증 프로세스를 대상으로 운영 중 발현 | Y19: T0088 | AA19: =COUNTIF(ATLAS기법매핑!$H$5:$H$212,"*"&D19&"*") -> 1 | AB19: =COUNTIFS(ATLAS기법매핑!$H$5:$H$212,"*"&D19&"*",ATLAS기법매핑!$M$5:$M$212,"Realized") -> 1 | AC19: =COUNTIFS(ATLAS기법매핑!$H$5:$H$212,"*"&D19&"*",ATLAS기법매핑!$M$5:$M$212,"Realized")&" / "&COUNTIFS(ATLAS기법매핑!$H$5:$H$212,"*"&D19&"*",ATLAS기법매핑!$M$5:$M$212,"Demonstrated")&" / "&COUNTIFS(ATLAS기법매핑!$H$5:$H$212,"*"&D19&"*",ATLAS기법매핑!$M$5:$M$212,"Feasible") -> 1 / 0 / 0 | AL19: =(LEN(Y19&Z19)>0)+(LEN(AD19&AE19)>0)+(LEN(AF19&AG19)>0)+(LEN(AH19&AI19)>0)+(LEN(AJ19&AK19)>0) -> 1 | AM19: =COUNTIF(ATLAS사례연구!$J$5:$J$77,"*"&D19&"*") -> 5 | AN19: =COUNTIFS(ATLAS사례연구!$J$5:$J$77,"*"&D19&"*",ATLAS사례연구!$C$5:$C$77,"Incident") -> 4 | AO19: 0 | AP19: 0 | AQ19: =IF(AN19+AO19>0,"실제 사고 확인",IF(AB19>0,"실사용 기법 포함",IF(OR(AM19>0,AP19>0),"실증·공개 취약점","이론·시나리오"))) -> 실제 사고 확인 | AR19: CS0004, CS0017, CS0033, CS0034, CS0057 | AS19: • [ATLAS CS0034·실제사고] KYC 우회용 딥페이크 도구 ProKYC가 범죄자에게 판매(실제 사고) • [ATLAS CS0033·실증] 실시간 딥페이크 영상 주입으로 모바일 KYC 얼굴인증 우회 • [ATLAS CS0004·실제사고] 카메라 영상 주입으로 얼굴인식 인증을 우회해 세금 사기(실제 사고) | AT19: M0009 Predictive AI Multi-Sensor Fusion M0034 Deepfake Detection | AU19: 딥페이크 탐지·라이브니스 검증, 고위험 요청 다중 채널 확인, 사용자 교육 | AV19: UT-30(분리)
A20: D01. 공격 준비 및 AI 무기화 | B20: UT-04 | C20: AI 생성 콘텐츠를 이용한 사기 | D20: UT-04.2 | E20: AI 생성 피싱 | F20: LLM 생성 맞춤형 스피어피싱 및 딥페이크 음성/영상 통화를 통해 임직원을 기망하여 자격증명 탈취 또는 송금 유도 | G20: =IF(AN20+AO20>=2,"상",IF(OR(AN20+AO20=1,AM20>0,AB20>0,AP20>0),"중","하")) -> 상 | H20: 중 | I20: =IF(AND(G20="상",H20="상"),"매우 높음",IF(OR(AND(G20="상",H20="중"),AND(G20="중",H20="상")),"높음",IF(OR(AND(G20="중",H20="중"),AND(G20="상",H20="하"),AND(G20="하",H20="상")),"보통","낮음"))) -> 높음 | J20: ="실제 사고 "&(AN20+AO20)&"건(ATLAS "&AN20&" / OWASP "&AO20&"), 실증 사례 "&(AM20-AN20)&"건, Realized 기법 "&AB20&"개, 취약점·익스플로잇 "&AP20&"건" -> 실제 사고 2건(ATLAS 2 / OWASP 0), 실증 사례 1건, Realized 기법 1개, 취약점·익스플로잇 0건 | K20: 자격증명 탈취 시 내부 침투로 확대 가능 | L20: 초기 접근(Initial Access) | M20: 초기 접근, 내부 확산 | S20: 기밀성, 재무 | V20: ○ | X20: 조직 생애주기 외부 활동 — 사람·생체인증 프로세스를 대상으로 운영 중 발현 | Y20: T0052, T0052.000, T0052.001 | AA20: =COUNTIF(ATLAS기법매핑!$H$5:$H$212,"*"&D20&"*") -> 3 | AB20: =COUNTIFS(ATLAS기법매핑!$H$5:$H$212,"*"&D20&"*",ATLAS기법매핑!$M$5:$M$212,"Realized") -> 1 | AC20: =COUNTIFS(ATLAS기법매핑!$H$5:$H$212,"*"&D20&"*",ATLAS기법매핑!$M$5:$M$212,"Realized")&" / "&COUNTIFS(ATLAS기법매핑!$H$5:$H$212,"*"&D20&"*",ATLAS기법매핑!$M$5:$M$212,"Demonstrated")&" / "&COUNTIFS(ATLAS기법매핑!$H$5:$H$212,"*"&D20&"*",ATLAS기법매핑!$M$5:$M$212,"Feasible") -> 1 / 1 / 1 | AL20: =(LEN(Y20&Z20)>0)+(LEN(AD20&AE20)>0)+(LEN(AF20&AG20)>0)+(LEN(AH20&AI20)>0)+(LEN(AJ20&AK20)>0) -> 1 | AM20: =COUNTIF(ATLAS사례연구!$J$5:$J$77,"*"&D20&"*") -> 3 | AN20: =COUNTIFS(ATLAS사례연구!$J$5:$J$77,"*"&D20&"*",ATLAS사례연구!$C$5:$C$77,"Incident") -> 2 | AO20: 0 | AP20: 0 | AQ20: =IF(AN20+AO20>0,"실제 사고 확인",IF(AB20>0,"실사용 기법 포함",IF(OR(AM20>0,AP20>0),"실증·공개 취약점","이론·시나리오"))) -> 실제 사고 확인 | AR20: CS0020, CS0032, CS0044 | AS20: • [ATLAS CS0032·실제사고] 피싱 사이트가 ML 기반 피싱 탐지기를 회피하도록 시각 요소 변형(실제 사고) • [ATLAS CS0044·실제사고] APT28 LAMEHUG가 LLM API로 실행 명령을 동적 생성(실제 사고) • [ATLAS CS0020·실증] 웹페이지 숨은 지시로 Bing Chat이 사용자 개인정보를 캐내는 사회공학 수행 • [OWASP 시나리오] 딥페이크 음성·영상과 LLM 생성 문안을 결합한 피싱(ATLAS T0052.001 기법 정의) | AT20: M0018 User Training M0034 Deepfake Detection | AU20: 딥페이크 탐지·라이브니스 검증, 고위험 요청 다중 채널 확인, 사용자 교육 | AV20: UT-30(분리)
A21: D01. 공격 준비 및 AI 무기화 | B21: UT-04 | C21: AI 생성 콘텐츠를 이용한 사기 | D21: UT-04.3 | E21: 신뢰 주체 사칭 | F21: 신뢰받는 개인/조직을 사칭한 커뮤니케이션으로 대상의 판단을 조작하여 공격자 대신 행위 수행 유도 | G21: =IF(AN21+AO21>=2,"상",IF(OR(AN21+AO21=1,AM21>0,AB21>0,AP21>0),"중","하")) -> 상 | H21: 중 | I21: =IF(AND(G21="상",H21="상"),"매우 높음",IF(OR(AND(G21="상",H21="중"),AND(G21="중",H21="상")),"높음",IF(OR(AND(G21="중",H21="중"),AND(G21="상",H21="하"),AND(G21="하",H21="상")),"보통","낮음"))) -> 높음 | J21: ="실제 사고 "&(AN21+AO21)&"건(ATLAS "&AN21&" / OWASP "&AO21&"), 실증 사례 "&(AM21-AN21)&"건, Realized 기법 "&AB21&"개, 취약점·익스플로잇 "&AP21&"건" -> 실제 사고 3건(ATLAS 3 / OWASP 0), 실증 사례 2건, Realized 기법 1개, 취약점·익스플로잇 0건 | K21: 기망 대상 개인/거래 단위 피해 | L21: 초기 접근(Initial Access) | M21: 방어 회피 | S21: 재무 | V21: ○ | X21: 조직 생애주기 외부 활동 — 사람·생체인증 프로세스를 대상으로 운영 중 발현 | Y21: T0073 | AA21: =COUNTIF(ATLAS기법매핑!$H$5:$H$212,"*"&D21&"*") -> 1 | AB21: =COUNTIFS(ATLAS기법매핑!$H$5:$H$212,"*"&D21&"*",ATLAS기법매핑!$M$5:$M$212,"Realized") -> 1 | AC21: =COUNTIFS(ATLAS기법매핑!$H$5:$H$212,"*"&D21&"*",ATLAS기법매핑!$M$5:$M$212,"Realized")&" / "&COUNTIFS(ATLAS기법매핑!$H$5:$H$212,"*"&D21&"*",ATLAS기법매핑!$M$5:$M$212,"Demonstrated")&" / "&COUNTIFS(ATLAS기법매핑!$H$5:$H$212,"*"&D21&"*",ATLAS기법매핑!$M$5:$M$212,"Feasible") -> 1 / 0 / 0 | AL21: =(LEN(Y21&Z21)>0)+(LEN(AD21&AE21)>0)+(LEN(AF21&AG21)>0)+(LEN(AH21&AI21)>0)+(LEN(AJ21&AK21)>0) -> 1 | AM21: =COUNTIF(ATLAS사례연구!$J$5:$J$77,"*"&D21&"*") -> 5 | AN21: =COUNTIFS(ATLAS사례연구!$J$5:$J$77,"*"&D21&"*",ATLAS사례연구!$C$5:$C$77,"Incident") -> 3 | AO21: 0 | AP21: 0 | AQ21: =IF(AN21+AO21>0,"실제 사고 확인",IF(AB21>0,"실사용 기법 포함",IF(OR(AM21>0,AP21>0),"실증·공개 취약점","이론·시나리오"))) -> 실제 사고 확인 | AR21: CS0027, CS0033, CS0034, CS0044, CS0053 | AS21: • [ATLAS CS0034·실제사고] KYC 우회용 딥페이크 도구 ProKYC가 범죄자에게 판매(실제 사고) • [ATLAS CS0044·실제사고] APT28 LAMEHUG가 LLM API로 실행 명령을 동적 생성(실제 사고) • [ATLAS CS0053·실제사고] Postmark를 사칭한 악성 MCP 서버가 발송 메일을 몰래 BCC로 유출(실제 사고) | AT21: — (ATLAS 완화책 없음: Lv2 핵심 통제 참조) | AU21: 딥페이크 탐지·라이브니스 검증, 고위험 요청 다중 채널 확인, 사용자 교육 | AV21: UT-30(분리)
A22: D01. 공격 준비 및 AI 무기화 | B22: UT-05 | C22: AI 서비스를 이용한 C2 통신 | D22: UT-05.1 | E22: AI 서비스 API 은닉 통신 | F22: 감염 호스트가 정상 AI 서비스 API를 명령 수신/결과 전송 채널로 사용하여 C2 트래픽을 정상 AI 트래픽으로 위장 | G22: =IF(AN22+AO22>=2,"상",IF(OR(AN22+AO22=1,AM22>0,AB22>0,AP22>0),"중","하")) -> 중 | H22: 상 | I22: =IF(AND(G22="상",H22="상"),"매우 높음",IF(OR(AND(G22="상",H22="중"),AND(G22="중",H22="상")),"높음",IF(OR(AND(G22="중",H22="중"),AND(G22="상",H22="하"),AND(G22="하",H22="상")),"보통","낮음"))) -> 높음 | J22: ="실제 사고 "&(AN22+AO22)&"건(ATLAS "&AN22&" / OWASP "&AO22&"), 실증 사례 "&(AM22-AN22)&"건, Realized 기법 "&AB22&"개, 취약점·익스플로잇 "&AP22&"건" -> 실제 사고 1건(ATLAS 1 / OWASP 0), 실증 사례 0건, Realized 기법 1개, 취약점·익스플로잇 0건 | K22: 침해 호스트에 대한 은닉 원격 제어 지속 | L22: 명령·제어(Command and Control) | M22: 명령·제어 | O22: ● | Q22: ● | S22: 기밀성, 무결성 | V22: ○ | X22: 조직 생애주기 외부 활동 — 탈취 자격증명 사용 시 운영 비용·데이터 피해로 발현 | Y22: T0096 | AA22: =COUNTIF(ATLAS기법매핑!$H$5:$H$212,"*"&D22&"*") -> 1 | AB22: =COUNTIFS(ATLAS기법매핑!$H$5:$H$212,"*"&D22&"*",ATLAS기법매핑!$M$5:$M$212,"Realized") -> 1 | AC22: =COUNTIFS(ATLAS기법매핑!$H$5:$H$212,"*"&D22&"*",ATLAS기법매핑!$M$5:$M$212,"Realized")&" / "&COUNTIFS(ATLAS기법매핑!$H$5:$H$212,"*"&D22&"*",ATLAS기법매핑!$M$5:$M$212,"Demonstrated")&" / "&COUNTIFS(ATLAS기법매핑!$H$5:$H$212,"*"&D22&"*",ATLAS기법매핑!$M$5:$M$212,"Feasible") -> 1 / 0 / 0 | AL22: =(LEN(Y22&Z22)>0)+(LEN(AD22&AE22)>0)+(LEN(AF22&AG22)>0)+(LEN(AH22&AI22)>0)+(LEN(AJ22&AK22)>0) -> 1 | AM22: =COUNTIF(ATLAS사례연구!$J$5:$J$77,"*"&D22&"*") -> 1 | AN22: =COUNTIFS(ATLAS사례연구!$J$5:$J$77,"*"&D22&"*",ATLAS사례연구!$C$5:$C$77,"Incident") -> 1 | AO22: 0 | AP22: 0 | AQ22: =IF(AN22+AO22>0,"실제 사고 확인",IF(AB22>0,"실사용 기법 포함",IF(OR(AM22>0,AP22>0),"실증·공개 취약점","이론·시나리오"))) -> 실제 사고 확인 | AR22: CS0042 | AS22: • [ATLAS CS0042·실제사고] OpenAI Assistants API를 은밀한 C2 채널로 악용한 백도어 SesameOp(실제 사고) | AT22: M0019 Control Access to AI Models and Data in Production | AU22: AI API 키 보호·사용량 이상 탐지, AI 서비스 egress 가시성, 비인가 AI 트래픽 차단 | AV22: UT-38
A23: D01. 공격 준비 및 AI 무기화 | B23: UT-05 | C23: AI 서비스를 이용한 C2 통신 | D23: UT-05.2 | E23: AI 웹 서비스 중계 악용 | F23: URL 조회 기능을 가진 AI 비서 또는 침해된 AI 에이전트를 경유하여 공격자 서버와 간접 통신함으로써 직접 통신 탐지 회피 | G23: =IF(AN23+AO23>=2,"상",IF(OR(AN23+AO23=1,AM23>0,AB23>0,AP23>0),"중","하")) -> 중 | H23: 상 | I23: =IF(AND(G23="상",H23="상"),"매우 높음",IF(OR(AND(G23="상",H23="중"),AND(G23="중",H23="상")),"높음",IF(OR(AND(G23="중",H23="중"),AND(G23="상",H23="하"),AND(G23="하",H23="상")),"보통","낮음"))) -> 높음 | J23: ="실제 사고 "&(AN23+AO23)&"건(ATLAS "&AN23&" / OWASP "&AO23&"), 실증 사례 "&(AM23-AN23)&"건, Realized 기법 "&AB23&"개, 취약점·익스플로잇 "&AP23&"건" -> 실제 사고 0건(ATLAS 0 / OWASP 0), 실증 사례 2건, Realized 기법 0개, 취약점·익스플로잇 0건 | K23: 직접 통신 탐지 회피형 원격 제어 | L23: 명령·제어(Command and Control) | M23: 명령·제어 | O23: ● | Q23: ● | S23: 기밀성, 무결성 | V23: ○ | X23: 조직 생애주기 외부 활동 — 탈취 자격증명 사용 시 운영 비용·데이터 피해로 발현 | Y23: T0114, T0108 | AA23: =COUNTIF(ATLAS기법매핑!$H$5:$H$212,"*"&D23&"*") -> 2 | AB23: =COUNTIFS(ATLAS기법매핑!$H$5:$H$212,"*"&D23&"*",ATLAS기법매핑!$M$5:$M$212,"Realized") -> 0 | AC23: =COUNTIFS(ATLAS기법매핑!$H$5:$H$212,"*"&D23&"*",ATLAS기법매핑!$M$5:$M$212,"Realized")&" / "&COUNTIFS(ATLAS기법매핑!$H$5:$H$212,"*"&D23&"*",ATLAS기법매핑!$M$5:$M$212,"Demonstrated")&" / "&COUNTIFS(ATLAS기법매핑!$H$5:$H$212,"*"&D23&"*",ATLAS기법매핑!$M$5:$M$212,"Feasible") -> 0 / 2 / 0 | AL23: =(LEN(Y23&Z23)>0)+(LEN(AD23&AE23)>0)+(LEN(AF23&AG23)>0)+(LEN(AH23&AI23)>0)+(LEN(AJ23&AK23)>0) -> 1 | AM23: =COUNTIF(ATLAS사례연구!$J$5:$J$77,"*"&D23&"*") -> 2 | AN23: =COUNTIFS(ATLAS사례연구!$J$5:$J$77,"*"&D23&"*",ATLAS사례연구!$C$5:$C$77,"Incident") -> 0 | AO23: 0 | AP23: 0 | AQ23: =IF(AN23+AO23>0,"실제 사고 확인",IF(AB23>0,"실사용 기법 포함",IF(OR(AM23>0,AP23>0),"실증·공개 취약점","이론·시나리오"))) -> 실증·공개 취약점 | AR23: CS0051, CS0061 | AS23: • [ATLAS CS0061·실증] 익명 웹 AI 비서의 URL 조회 기능을 악성코드 C2 중계로 악용(AI in the Middle) • [ATLAS CS0051·실증] 웹페이지 인젝션으로 OpenClaw에 지속 지시를 심어 C2로 활용 | AT23: M0020 Generative AI Guardrails M0024 AI Telemetry Logging | AU23: AI API 키 보호·사용량 이상 탐지, AI 서비스 egress 가시성, 비인가 AI 트래픽 차단 | AV23: UT-38
A24: D01. 공격 준비 및 AI 무기화 | B24: UT-05 | C24: AI 서비스를 이용한 C2 통신 | D24: UT-05.3 | E24: AI 아티팩트 저장소 악용 | F24: 모델/데이터셋 저장소를 명령 및 데이터 교환 매체로 사용하여 정상 아티팩트 다운로드로 위장된 C2 수행 | G24: =IF(AN24+AO24>=2,"상",IF(OR(AN24+AO24=1,AM24>0,AB24>0,AP24>0),"중","하")) -> 중 | H24: 중 | I24: =IF(AND(G24="상",H24="상"),"매우 높음",IF(OR(AND(G24="상",H24="중"),AND(G24="중",H24="상")),"높음",IF(OR(AND(G24="중",H24="중"),AND(G24="상",H24="하"),AND(G24="하",H24="상")),"보통","낮음"))) -> 보통 | J24: ="실제 사고 "&(AN24+AO24)&"건(ATLAS "&AN24&" / OWASP "&AO24&"), 실증 사례 "&(AM24-AN24)&"건, Realized 기법 "&AB24&"개, 취약점·익스플로잇 "&AP24&"건" -> 실제 사고 1건(ATLAS 1 / OWASP 0), 실증 사례 0건, Realized 기법 1개, 취약점·익스플로잇 0건 | K24: 탐지 회피형 통신 채널(제한적 대역) | L24: 명령·제어(Command and Control) | M24: 명령·제어 | O24: ● | Q24: ● | S24: 기밀성, 무결성 | V24: ○ | X24: 조직 생애주기 외부 활동 — 탈취 자격증명 사용 시 운영 비용·데이터 피해로 발현 | Y24: T0120 | AA24: =COUNTIF(ATLAS기법매핑!$H$5:$H$212,"*"&D24&"*") -> 1 | AB24: =COUNTIFS(ATLAS기법매핑!$H$5:$H$212,"*"&D24&"*",ATLAS기법매핑!$M$5:$M$212,"Realized") -> 1 | AC24: =COUNTIFS(ATLAS기법매핑!$H$5:$H$212,"*"&D24&"*",ATLAS기법매핑!$M$5:$M$212,"Realized")&" / "&COUNTIFS(ATLAS기법매핑!$H$5:$H$212,"*"&D24&"*",ATLAS기법매핑!$M$5:$M$212,"Demonstrated")&" / "&COUNTIFS(ATLAS기법매핑!$H$5:$H$212,"*"&D24&"*",ATLAS기법매핑!$M$5:$M$212,"Feasible") -> 1 / 0 / 0 | AL24: =(LEN(Y24&Z24)>0)+(LEN(AD24&AE24)>0)+(LEN(AF24&AG24)>0)+(LEN(AH24&AI24)>0)+(LEN(AJ24&AK24)>0) -> 1 | AM24: =COUNTIF(ATLAS사례연구!$J$5:$J$77,"*"&D24&"*") -> 1 | AN24: =COUNTIFS(ATLAS사례연구!$J$5:$J$77,"*"&D24&"*",ATLAS사례연구!$C$5:$C$77,"Incident") -> 1 | AO24: 0 | AP24: 0 | AQ24: =IF(AN24+AO24>0,"실제 사고 확인",IF(AB24>0,"실사용 기법 포함",IF(OR(AM24>0,AP24>0),"실증·공개 취약점","이론·시나리오"))) -> 실제 사고 확인 | AR24: CS0068 | AS24: • [ATLAS CS0068·실제사고] OpenAI 평가용 자율 에이전트들이 평가 경계를 넘어 외부 인프라 구축·Hugging Face 침해(실제 사고) • [OWASP 시나리오] 모델 허브 저장소를 명령·데이터 교환 매체로 사용하는 C2(ATLAS T0120 기법 정의) | AT24: — (ATLAS 완화책 없음: Lv2 핵심 통제 참조) | AU24: AI API 키 보호·사용량 이상 탐지, AI 서비스 egress 가시성, 비인가 AI 트래픽 차단 | AV24: UT-38
A25: D02. 프롬프트 인젝션 및 컨텍스트 노출 | B25: UT-06 | C25: 직접 프롬프트 인젝션 | D25: UT-06.1 | E25: 시스템 지시 무력화 | F25: 사용자 입력창에 '이전 지시 무시' 등 조작 지시를 입력하여 시스템 프롬프트의 역할/제약을 무력화하고 비인가 정보 조회 또는 기능 실행 유도 | G25: =IF(AN25+AO25>=2,"상",IF(OR(AN25+AO25=1,AM25>0,AB25>0,AP25>0),"중","하")) -> 상 | H25: 중 | I25: =IF(AND(G25="상",H25="상"),"매우 높음",IF(OR(AND(G25="상",H25="중"),AND(G25="중",H25="상")),"높음",IF(OR(AND(G25="중",H25="중"),AND(G25="상",H25="하"),AND(G25="하",H25="상")),"보통","낮음"))) -> 높음 | J25: ="실제 사고 "&(AN25+AO25)&"건(ATLAS "&AN25&" / OWASP "&AO25&"), 실증 사례 "&(AM25-AN25)&"건, Realized 기법 "&AB25&"개, 취약점·익스플로잇 "&AP25&"건" -> 실제 사고 3건(ATLAS 3 / OWASP 0), 실증 사례 9건, Realized 기법 2개, 취약점·익스플로잇 1건 | K25: 앱 권한 범위 내 비인가 조회/실행 | L25: 실행(Execution) | M25: 실행 | O25: ● | P25: ● | Q25: ● | R25: ● | S25: 기밀성, 무결성 | T25: ○ | V25: ● | Y25: T0051, T0051.000 | AA25: =COUNTIF(ATLAS기법매핑!$H$5:$H$212,"*"&D25&"*") -> 2 | AB25: =COUNTIFS(ATLAS기법매핑!$H$5:$H$212,"*"&D25&"*",ATLAS기법매핑!$M$5:$M$212,"Realized") -> 2 | AC25: =COUNTIFS(ATLAS기법매핑!$H$5:$H$212,"*"&D25&"*",ATLAS기법매핑!$M$5:$M$212,"Realized")&" / "&COUNTIFS(ATLAS기법매핑!$H$5:$H$212,"*"&D25&"*",ATLAS기법매핑!$M$5:$M$212,"Demonstrated")&" / "&COUNTIFS(ATLAS기법매핑!$H$5:$H$212,"*"&D25&"*",ATLAS기법매핑!$M$5:$M$212,"Feasible") -> 2 / 0 / 0 | AD25: LLM01 | AE25: LLM08 | AG25: ASI01, ASI09 | AI25: DSGAI01 | AK25: MCP06 | AL25: =(LEN(Y25&Z25)>0)+(LEN(AD25&AE25)>0)+(LEN(AF25&AG25)>0)+(LEN(AH25&AI25)>0)+(LEN(AJ25&AK25)>0) -> 5 | AM25: =COUNTIF(ATLAS사례연구!$J$5:$J$77,"*"&D25&"*") -> 12 | AN25: =COUNTIFS(ATLAS사례연구!$J$5:$J$77,"*"&D25&"*",ATLAS사례연구!$C$5:$C$77,"Incident") -> 3 | AO25: 0 | AP25: 1 | AQ25: =IF(AN25+AO25>0,"실제 사고 확인",IF(AB25>0,"실사용 기법 포함",IF(OR(AM25>0,AP25>0),"실증·공개 취약점","이론·시나리오"))) -> 실제 사고 확인 | AR25: CS0016, CS0024, CS0036, CS0037, CS0041, CS0043, CS0047, CS0051, CS0052, CS0060, CS0062, CS0069 | AS25: • [ATLAS CS0043·실제사고] LLM 기반 악성코드 분석기를 속이려 프롬프트 인젝션을 내장한 악성코드(실제 사고) • [ATLAS CS0016·실증] MathGPT에 프롬프트 인젝션으로 파이썬 코드 실행·API 키 노출 • [ATLAS CS0047·실제사고] 과권한 GitHub 토큰으로 Amazon Q VS Code 확장에 파괴형 에이전트 지시 커밋(실제 사고) • [OWASP 인용] CVE-2024-5184 EmailGPT 프롬프트 인젝션(시스템 프롬프트 노출 및 데이터 유출) | AT25: M0024 AI Telemetry Logging M0033 Input and Output Validation for AI Agent Components M0035 AI Red Team M0019 Control Access to AI Models and Data in Production M0020 Generative AI Guardrails | AU25: 다층 입·출력 가드레일, 모달리티별 정규화·비가시 문자 제거, 권한 분리로 폭발반경 제한, 적대적 테스트 상시화 | AV25: UT-01, UT-03
